Workbook

Sheet ZAMBI
A2: NAMA PRODUK | B2: KODE BAHAN | C2: NAMA BAHAN | D2: HARGA KULAK | E2: ISI | F2: SATUAN | G2: HARGA KULAK SATUAN | H2: MODAL SATUAN | I2: KEB. | J2: JUMLAH MODAL
A3: ZAMBI 10 CM SOSIZ+AYAM | B3: 1 | C3: SAOS SPAGHETI GRAM | D3: =VLOOKUP(TBLZAMBISOSYAM[NAMA BAHAN],[2]!TBLREKAPBAHAN[[NAMA BAHAN]:[MODAL SATUAN]],2,FALSE) -> 12000 | E3: =VLOOKUP(TBLZAMBISOSYAM[NAMA BAHAN],[2]!TBLREKAPBAHAN[[NAMA BAHAN]:[MODAL SATUAN]],3,FALSE) -> 250 | G3: =VLOOKUP(TBLZAMBISOSYAM[NAMA BAHAN],[2]!TBLREKAPBAHAN[[NAMA BAHAN]:[MODAL SATUAN]],4,FALSE) -> 48 | H3: =VLOOKUP(TBLZAMBISOSYAM[NAMA BAHAN],[2]!TBLREKAPBAHAN[[NAMA BAHAN]:[MODAL SATUAN]],4,FALSE) -> 48 | I3: 20 | J3: =H3*I3 -> 960
B4: 2 | C4: SAOS BBQ GRAM | D4: =VLOOKUP(TBLZAMBISOSYAM[NAMA BAHAN],[2]!TBLREKAPBAHAN[[NAMA BAHAN]:[MODAL SATUAN]],2,FALSE) -> 12000 | E4: =VLOOKUP(TBLZAMBISOSYAM[NAMA BAHAN],[2]!TBLREKAPBAHAN[[NAMA BAHAN]:[MODAL SATUAN]],3,FALSE) -> 250 | G4: =VLOOKUP(TBLZAMBISOSYAM[NAMA BAHAN],[2]!TBLREKAPBAHAN[[NAMA BAHAN]:[MODAL SATUAN]],4,FALSE) -> 48 | H4: =VLOOKUP(TBLZAMBISOSYAM[NAMA BAHAN],[2]!TBLREKAPBAHAN[[NAMA BAHAN]:[MODAL SATUAN]],4,FALSE) -> 48 | I4: 10 | J4: =H4*I4 -> 480
B5: 3 | C5: DAGING SAPI | D5: =VLOOKUP(TBLZAMBISOSYAM[NAMA BAHAN],[2]!TBLREKAPBAHAN[[NAMA BAHAN]:[MODAL SATUAN]],2,FALSE) -> 85000 | E5: =VLOOKUP(TBLZAMBISOSYAM[NAMA BAHAN],[2]!TBLREKAPBAHAN[[NAMA BAHAN]:[MODAL SATUAN]],3,FALSE) -> 1000 | G5: =VLOOKUP(TBLZAMBISOSYAM[NAMA BAHAN],[2]!TBLREKAPBAHAN[[NAMA BAHAN]:[MODAL SATUAN]],4,FALSE) -> 85 | H5: =VLOOKUP(TBLZAMBISOSYAM[NAMA BAHAN],[2]!TBLREKAPBAHAN[[NAMA BAHAN]:[MODAL SATUAN]],4,FALSE) -> 85 | I5: 0 | J5: =H5*I5 -> 0
B6: 4 | C6: SOSIZ BATANG | D6: =VLOOKUP(TBLZAMBISOSYAM[NAMA BAHAN],[2]!TBLREKAPBAHAN[[NAMA BAHAN]:[MODAL SATUAN]],2,FALSE) -> 35000 | E6: =VLOOKUP(TBLZAMBISOSYAM[NAMA BAHAN],[2]!TBLREKAPBAHAN[[NAMA BAHAN]:[MODAL SATUAN]],3,FALSE) -> 38 | G6: =VLOOKUP(TBLZAMBISOSYAM[NAMA BAHAN],[2]!TBLREKAPBAHAN[[NAMA BAHAN]:[MODAL SATUAN]],4,FALSE) -> 921.05263 | H6: =VLOOKUP(TBLZAMBISOSYAM[NAMA BAHAN],[2]!TBLREKAPBAHAN[[NAMA BAHAN]:[MODAL SATUAN]],4,FALSE) -> 921.05263 | I6: 1 | J6: =H6*I6 -> 921.05263
B7: 5 | C7: AYAM SUWIR | D7: =VLOOKUP(TBLZAMBISOSYAM[NAMA BAHAN],[2]!TBLREKAPBAHAN[[NAMA BAHAN]:[MODAL SATUAN]],2,FALSE) -> 45000 | E7: =VLOOKUP(TBLZAMBISOSYAM[NAMA BAHAN],[2]!TBLREKAPBAHAN[[NAMA BAHAN]:[MODAL SATUAN]],3,FALSE) -> 400 | G7: =VLOOKUP(TBLZAMBISOSYAM[NAMA BAHAN],[2]!TBLREKAPBAHAN[[NAMA BAHAN]:[MODAL SATUAN]],4,FALSE) -> 112.5 | H7: =VLOOKUP(TBLZAMBISOSYAM[NAMA BAHAN],[2]!TBLREKAPBAHAN[[NAMA BAHAN]:[MODAL SATUAN]],4,FALSE) -> 112.5 | I7: 10 | J7: =H7*I7 -> 1125
B8: 6 | C8: SAOS SAMBAL SACHET | D8: =VLOOKUP(TBLZAMBISOSYAM[NAMA BAHAN],[2]!TBLREKAPBAHAN[[NAMA BAHAN]:[MODAL SATUAN]],2,FALSE) -> 8000 | E8: =VLOOKUP(TBLZAMBISOSYAM[NAMA BAHAN],[2]!TBLREKAPBAHAN[[NAMA BAHAN]:[MODAL SATUAN]],3,FALSE) -> 24 | G8: =VLOOKUP(TBLZAMBISOSYAM[NAMA BAHAN],[2]!TBLREKAPBAHAN[[NAMA BAHAN]:[MODAL SATUAN]],4,FALSE) -> 333.33333 | H8: =VLOOKUP(TBLZAMBISOSYAM[NAMA BAHAN],[2]!TBLREKAPBAHAN[[NAMA BAHAN]:[MODAL SATUAN]],4,FALSE) -> 333.33333 | I8: 1 | J8: =H8*I8 -> 333.33333
B9: 7 | C9: MENTEGA | D9: =VLOOKUP(TBLZAMBISOSYAM[NAMA BAHAN],[2]!TBLREKAPBAHAN[[NAMA BAHAN]:[MODAL SATUAN]],2,FALSE) -> 35000 | E9: =VLOOKUP(TBLZAMBISOSYAM[NAMA BAHAN],[2]!TBLREKAPBAHAN[[NAMA BAHAN]:[MODAL SATUAN]],3,FALSE) -> 1000 | G9: =VLOOKUP(TBLZAMBISOSYAM[NAMA BAHAN],[2]!TBLREKAPBAHAN[[NAMA BAHAN]:[MODAL SATUAN]],4,FALSE) -> 35 | H9: =VLOOKUP(TBLZAMBISOSYAM[NAMA BAHAN],[2]!TBLREKAPBAHAN[[NAMA BAHAN]:[MODAL SATUAN]],4,FALSE) -> 35 | I9: 7.5 | J9: =H9*I9 -> 262.5
B10: 8 | C10: GULA PASIR | D10: =VLOOKUP(TBLZAMBISOSYAM[NAMA BAHAN],[2]!TBLREKAPBAHAN[[NAMA BAHAN]:[MODAL SATUAN]],2,FALSE) -> 18000 | E10: =VLOOKUP(TBLZAMBISOSYAM[NAMA BAHAN],[2]!TBLREKAPBAHAN[[NAMA BAHAN]:[MODAL SATUAN]],3,FALSE) -> 1000 | G10: =VLOOKUP(TBLZAMBISOSYAM[NAMA BAHAN],[2]!TBLREKAPBAHAN[[NAMA BAHAN]:[MODAL SATUAN]],4,FALSE) -> 18 | H10: =VLOOKUP(TBLZAMBISOSYAM[NAMA BAHAN],[2]!TBLREKAPBAHAN[[NAMA BAHAN]:[MODAL SATUAN]],4,FALSE) -> 18 | I10: 4.5 | J10: =H10*I10 -> 81
B11: 9 | C11: GARAM HALUS | D11: =VLOOKUP(TBLZAMBISOSYAM[NAMA BAHAN],[2]!TBLREKAPBAHAN[[NAMA BAHAN]:[MODAL SATUAN]],2,FALSE) -> 4000 | E11: =VLOOKUP(TBLZAMBISOSYAM[NAMA BAHAN],[2]!TBLREKAPBAHAN[[NAMA BAHAN]:[MODAL SATUAN]],3,FALSE) -> 250 | G11: =VLOOKUP(TBLZAMBISOSYAM[NAMA BAHAN],[2]!TBLREKAPBAHAN[[NAMA BAHAN]:[MODAL SATUAN]],4,FALSE) -> 16 | H11: =VLOOKUP(TBLZAMBISOSYAM[NAMA BAHAN],[2]!TBLREKAPBAHAN[[NAMA BAHAN]:[MODAL SATUAN]],4,FALSE) -> 16 | I11: 0.5 | J11: =H11*I11 -> 8
B12: 10 | C12: VERMIPAN | D12: =VLOOKUP(TBLZAMBISOSYAM[NAMA BAHAN],[2]!TBLREKAPBAHAN[[NAMA BAHAN]:[MODAL SATUAN]],2,FALSE) -> 7000 | E12: =VLOOKUP(TBLZAMBISOSYAM[NAMA BAHAN],[2]!TBLREKAPBAHAN[[NAMA BAHAN]:[MODAL SATUAN]],3,FALSE) -> 11 | G12: =VLOOKUP(TBLZAMBISOSYAM[NAMA BAHAN],[2]!TBLREKAPBAHAN[[NAMA BAHAN]:[MODAL SATUAN]],4,FALSE) -> 636.36364 | H12: =VLOOKUP(TBLZAMBISOSYAM[NAMA BAHAN],[2]!TBLREKAPBAHAN[[NAMA BAHAN]:[MODAL SATUAN]],4,FALSE) -> 636.36364 | I12: 0.5 | J12: =H12*I12 -> 318.18182
B13: 11 | C13: SUSU BUBUK | D13: =VLOOKUP(TBLZAMBISOSYAM[NAMA BAHAN],[2]!TBLREKAPBAHAN[[NAMA BAHAN]:[MODAL SATUAN]],2,FALSE) -> 18000 | E13: =VLOOKUP(TBLZAMBISOSYAM[NAMA BAHAN],[2]!TBLREKAPBAHAN[[NAMA BAHAN]:[MODAL SATUAN]],3,FALSE) -> 250 | G13: =VLOOKUP(TBLZAMBISOSYAM[NAMA BAHAN],[2]!TBLREKAPBAHAN[[NAMA BAHAN]:[MODAL SATUAN]],4,FALSE) -> 72 | H13: =VLOOKUP(TBLZAMBISOSYAM[NAMA BAHAN],[2]!TBLREKAPBAHAN[[NAMA BAHAN]:[MODAL SATUAN]],4,FALSE) -> 72 | I13: 5 | J13: =H13*I13 -> 360
B14: 12 | C14: TEPUNG SEGITIGA BIRU | D14: =VLOOKUP(TBLZAMBISOSYAM[NAMA BAHAN],[2]!TBLREKAPBAHAN[[NAMA BAHAN]:[MODAL SATUAN]],2,FALSE) -> 14000 | E14: =VLOOKUP(TBLZAMBISOSYAM[NAMA BAHAN],[2]!TBLREKAPBAHAN[[NAMA BAHAN]:[MODAL SATUAN]],3,FALSE) -> 1000 | G14: =VLOOKUP(TBLZAMBISOSYAM[NAMA BAHAN],[2]!TBLREKAPBAHAN[[NAMA BAHAN]:[MODAL SATUAN]],4,FALSE) -> 14 | H14: =VLOOKUP(TBLZAMBISOSYAM[NAMA BAHAN],[2]!TBLREKAPBAHAN[[NAMA BAHAN]:[MODAL SATUAN]],4,FALSE) -> 14 | I14: 10 | J14: =H14*I14 -> 140
B15: 13 | C15: TEPUNG CAKRA KEMBAR | D15: =VLOOKUP(TBLZAMBISOSYAM[NAMA BAHAN],[2]!TBLREKAPBAHAN[[NAMA BAHAN]:[MODAL SATUAN]],2,FALSE) -> 14000 | E15: =VLOOKUP(TBLZAMBISOSYAM[NAMA BAHAN],[2]!TBLREKAPBAHAN[[NAMA BAHAN]:[MODAL SATUAN]],3,FALSE) -> 1000 | G15: =VLOOKUP(TBLZAMBISOSYAM[NAMA BAHAN],[2]!TBLREKAPBAHAN[[NAMA BAHAN]:[MODAL SATUAN]],4,FALSE) -> 14 | H15: =VLOOKUP(TBLZAMBISOSYAM[NAMA BAHAN],[2]!TBLREKAPBAHAN[[NAMA BAHAN]:[MODAL SATUAN]],4,FALSE) -> 14 | I15: 20 | J15: =H15*I15 -> 280
... B22: 20 | C22: PLASTIK KLIP SEDANG 13 CM | D22: =VLOOKUP(TBLZAMBISOSYAM[NAMA BAHAN],[2]!TBLREKAPBAHAN[[NAMA BAHAN]:[MODAL SATUAN]],2,FALSE) -> 6000 | E22: =VLOOKUP(TBLZAMBISOSYAM[NAMA BAHAN],[2]!TBLREKAPBAHAN[[NAMA BAHAN]:[MODAL SATUAN]],3,FALSE) -> 100 | G22: =VLOOKUP(TBLZAMBISOSYAM[NAMA BAHAN],[2]!TBLREKAPBAHAN[[NAMA BAHAN]:[MODAL SATUAN]],4,FALSE) -> 60 | H22: =VLOOKUP(TBLZAMBISOSYAM[NAMA BAHAN],[2]!TBLREKAPBAHAN[[NAMA BAHAN]:[MODAL SATUAN]],4,FALSE) -> 60 | I22: 1 | J22: =H22*I22 -> 60
C23: MODAL | J23: =SUM(J3:J22) -> 5951.9406
A28: NAMA PRODUK | B28: KODE BAHAN | C28: NAMA BAHAN | D28: HARGA KULAK | E28: ISI | F28: SATUAN | G28: HARGA KULAK SATUAN | H28: MODAL SATUAN | I28: KEB. | J28: JUMLAH MODAL
A29: ZAMBI 10 CM DAGING SAPI | B29: 1 | C29: SAOS SPAGHETI GRAM | D29: =VLOOKUP(TBLZAMBIDAGINGSAPI[NAMA BAHAN],[2]!TBLREKAPBAHAN[[NAMA BAHAN]:[MODAL SATUAN]],2,FALSE) -> 12000 | E29: =VLOOKUP(TBLZAMBIDAGINGSAPI[NAMA BAHAN],[2]!TBLREKAPBAHAN[[NAMA BAHAN]:[MODAL SATUAN]],3,FALSE) -> 250 | G29: =VLOOKUP(TBLZAMBIDAGINGSAPI[NAMA BAHAN],[2]!TBLREKAPBAHAN[[NAMA BAHAN]:[MODAL SATUAN]],4,FALSE) -> 48 | H29: =VLOOKUP(TBLZAMBIDAGINGSAPI[NAMA BAHAN],[2]!TBLREKAPBAHAN[[NAMA BAHAN]:[MODAL SATUAN]],4,FALSE) -> 48 | I29: 20 | J29: =H29*I29 -> 960
B30: 2 | C30: SAOS BBQ GRAM | D30: =VLOOKUP(TBLZAMBIDAGINGSAPI[NAMA BAHAN],[2]!TBLREKAPBAHAN[[NAMA BAHAN]:[MODAL SATUAN]],2,FALSE) -> 12000 | E30: =VLOOKUP(TBLZAMBIDAGINGSAPI[NAMA BAHAN],[2]!TBLREKAPBAHAN[[NAMA BAHAN]:[MODAL SATUAN]],3,FALSE) -> 250 | G30: =VLOOKUP(TBLZAMBIDAGINGSAPI[NAMA BAHAN],[2]!TBLREKAPBAHAN[[NAMA BAHAN]:[MODAL SATUAN]],4,FALSE) -> 48 | H30: =VLOOKUP(TBLZAMBIDAGINGSAPI[NAMA BAHAN],[2]!TBLREKAPBAHAN[[NAMA BAHAN]:[MODAL SATUAN]],4,FALSE) -> 48 | I30: 10 | J30: =H30*I30 -> 480
B31: 3 | C31: DAGING SAPI | D31: =VLOOKUP(TBLZAMBIDAGINGSAPI[NAMA BAHAN],[2]!TBLREKAPBAHAN[[NAMA BAHAN]:[MODAL SATUAN]],2,FALSE) -> 85000 | E31: =VLOOKUP(TBLZAMBIDAGINGSAPI[NAMA BAHAN],[2]!TBLREKAPBAHAN[[NAMA BAHAN]:[MODAL SATUAN]],3,FALSE) -> 1000 | G31: =VLOOKUP(TBLZAMBIDAGINGSAPI[NAMA BAHAN],[2]!TBLREKAPBAHAN[[NAMA BAHAN]:[MODAL SATUAN]],4,FALSE) -> 85 | H31: =VLOOKUP(TBLZAMBIDAGINGSAPI[NAMA BAHAN],[2]!TBLREKAPBAHAN[[NAMA BAHAN]:[MODAL SATUAN]],4,FALSE) -> 85 | I31: 20 | J31: =H31*I31 -> 1700
B32: 4 | C32: SOSIZ BATANG | D32: =VLOOKUP(TBLZAMBIDAGINGSAPI[NAMA BAHAN],[2]!TBLREKAPBAHAN[[NAMA BAHAN]:[MODAL SATUAN]],2,FALSE) -> 35000 | E32: =VLOOKUP(TBLZAMBIDAGINGSAPI[NAMA BAHAN],[2]!TBLREKAPBAHAN[[NAMA BAHAN]:[MODAL SATUAN]],3,FALSE) -> 38 | G32: =VLOOKUP(TBLZAMBIDAGINGSAPI[NAMA BAHAN],[2]!TBLREKAPBAHAN[[NAMA BAHAN]:[MODAL SATUAN]],4,FALSE) -> 921.05263 | H32: =VLOOKUP(TBLZAMBIDAGINGSAPI[NAMA BAHAN],[2]!TBLREKAPBAHAN[[NAMA BAHAN]:[MODAL SATUAN]],4,FALSE) -> 921.05263 | I32: 0 | J32: =H32*I32 -> 0
B33: 5 | C33: AYAM SUWIR | D33: =VLOOKUP(TBLZAMBIDAGINGSAPI[NAMA BAHAN],[2]!TBLREKAPBAHAN[[NAMA BAHAN]:[MODAL SATUAN]],2,FALSE) -> 45000 | E33: =VLOOKUP(TBLZAMBIDAGINGSAPI[NAMA BAHAN],[2]!TBLREKAPBAHAN[[NAMA BAHAN]:[MODAL SATUAN]],3,FALSE) -> 400 | G33: =VLOOKUP(TBLZAMBIDAGINGSAPI[NAMA BAHAN],[2]!TBLREKAPBAHAN[[NAMA BAHAN]:[MODAL SATUAN]],4,FALSE) -> 112.5 | H33: =VLOOKUP(TBLZAMBIDAGINGSAPI[NAMA BAHAN],[2]!TBLREKAPBAHAN[[NAMA BAHAN]:[MODAL SATUAN]],4,FALSE) -> 112.5 | I33: 0 | J33: =H33*I33 -> 0
B34: 6 | C34: SAOS SAMBAL SACHET | D34: =VLOOKUP(TBLZAMBIDAGINGSAPI[NAMA BAHAN],[2]!TBLREKAPBAHAN[[NAMA BAHAN]:[MODAL SATUAN]],2,FALSE) -> 8000 | E34: =VLOOKUP(TBLZAMBIDAGINGSAPI[NAMA BAHAN],[2]!TBLREKAPBAHAN[[NAMA BAHAN]:[MODAL SATUAN]],3,FALSE) -> 24 | G34: =VLOOKUP(TBLZAMBIDAGINGSAPI[NAMA BAHAN],[2]!TBLREKAPBAHAN[[NAMA BAHAN]:[MODAL SATUAN]],4,FALSE) -> 333.33333 | H34: =VLOOKUP(TBLZAMBIDAGINGSAPI[NAMA BAHAN],[2]!TBLREKAPBAHAN[[NAMA BAHAN]:[MODAL SATUAN]],4,FALSE) -> 333.33333 | I34: 1 | J34: =H34*I34 -> 333.33333
B35: 7 | C35: MENTEGA | D35: =VLOOKUP(TBLZAMBIDAGINGSAPI[NAMA BAHAN],[2]!TBLREKAPBAHAN[[NAMA BAHAN]:[MODAL SATUAN]],2,FALSE) -> 35000 | E35: =VLOOKUP(TBLZAMBIDAGINGSAPI[NAMA BAHAN],[2]!TBLREKAPBAHAN[[NAMA BAHAN]:[MODAL SATUAN]],3,FALSE) -> 1000 | G35: =VLOOKUP(TBLZAMBIDAGINGSAPI[NAMA BAHAN],[2]!TBLREKAPBAHAN[[NAMA BAHAN]:[MODAL SATUAN]],4,FALSE) -> 35 | H35: =VLOOKUP(TBLZAMBIDAGINGSAPI[NAMA BAHAN],[2]!TBLREKAPBAHAN[[NAMA BAHAN]:[MODAL SATUAN]],4,FALSE) -> 35 | I35: 7.5 | J35: =H35*I35 -> 262.5
B36: 8 | C36: GULA PASIR | D36: =VLOOKUP(TBLZAMBIDAGINGSAPI[NAMA BAHAN],[2]!TBLREKAPBAHAN[[NAMA BAHAN]:[MODAL SATUAN]],2,FALSE) -> 18000 | E36: =VLOOKUP(TBLZAMBIDAGINGSAPI[NAMA BAHAN],[2]!TBLREKAPBAHAN[[NAMA BAHAN]:[MODAL SATUAN]],3,FALSE) -> 1000 | G36: =VLOOKUP(TBLZAMBIDAGINGSAPI[NAMA BAHAN],[2]!TBLREKAPBAHAN[[NAMA BAHAN]:[MODAL SATUAN]],4,FALSE) -> 18 | H36: =VLOOKUP(TBLZAMBIDAGINGSAPI[NAMA BAHAN],[2]!TBLREKAPBAHAN[[NAMA BAHAN]:[MODAL SATUAN]],4,FALSE) -> 18 | I36: 4.5 | J36: =H36*I36 -> 81
B37: 9 | C37: GARAM HALUS | D37: =VLOOKUP(TBLZAMBIDAGINGSAPI[NAMA BAHAN],[2]!TBLREKAPBAHAN[[NAMA BAHAN]:[MODAL SATUAN]],2,FALSE) -> 4000 | E37: =VLOOKUP(TBLZAMBIDAGINGSAPI[NAMA BAHAN],[2]!TBLREKAPBAHAN[[NAMA BAHAN]:[MODAL SATUAN]],3,FALSE) -> 250 | G37: =VLOOKUP(TBLZAMBIDAGINGSAPI[NAMA BAHAN],[2]!TBLREKAPBAHAN[[NAMA BAHAN]:[MODAL SATUAN]],4,FALSE) -> 16 | H37: =VLOOKUP(TBLZAMBIDAGINGSAPI[NAMA BAHAN],[2]!TBLREKAPBAHAN[[NAMA BAHAN]:[MODAL SATUAN]],4,FALSE) -> 16 | I37: 0.5 | J37: =H37*I37 -> 8
B38: 10 | C38: VERMIPAN | D38: =VLOOKUP(TBLZAMBIDAGINGSAPI[NAMA BAHAN],[2]!TBLREKAPBAHAN[[NAMA BAHAN]:[MODAL SATUAN]],2,FALSE) -> 7000 | E38: =VLOOKUP(TBLZAMBIDAGINGSAPI[NAMA BAHAN],[2]!TBLREKAPBAHAN[[NAMA BAHAN]:[MODAL SATUAN]],3,FALSE) -> 11 | G38: =VLOOKUP(TBLZAMBIDAGINGSAPI[NAMA BAHAN],[2]!TBLREKAPBAHAN[[NAMA BAHAN]:[MODAL SATUAN]],4,FALSE) -> 636.36364 | H38: =VLOOKUP(TBLZAMBIDAGINGSAPI[NAMA BAHAN],[2]!TBLREKAPBAHAN[[NAMA BAHAN]:[MODAL SATUAN]],4,FALSE) -> 636.36364 | I38: 0.5 | J38: =H38*I38 -> 318.18182
B39: 11 | C39: SUSU BUBUK | D39: =VLOOKUP(TBLZAMBIDAGINGSAPI[NAMA BAHAN],[2]!TBLREKAPBAHAN[[NAMA BAHAN]:[MODAL SATUAN]],2,FALSE) -> 18000 | E39: =VLOOKUP(TBLZAMBIDAGINGSAPI[NAMA BAHAN],[2]!TBLREKAPBAHAN[[NAMA BAHAN]:[MODAL SATUAN]],3,FALSE) -> 250 | G39: =VLOOKUP(TBLZAMBIDAGINGSAPI[NAMA BAHAN],[2]!TBLREKAPBAHAN[[NAMA BAHAN]:[MODAL SATUAN]],4,FALSE) -> 72 | H39: =VLOOKUP(TBLZAMBIDAGINGSAPI[NAMA BAHAN],[2]!TBLREKAPBAHAN[[NAMA BAHAN]:[MODAL SATUAN]],4,FALSE) -> 72 | I39: 5 | J39: =H39*I39 -> 360
B40: 12 | C40: TEPUNG SEGITIGA BIRU | D40: =VLOOKUP(TBLZAMBIDAGINGSAPI[NAMA BAHAN],[2]!TBLREKAPBAHAN[[NAMA BAHAN]:[MODAL SATUAN]],2,FALSE) -> 14000 | E40: =VLOOKUP(TBLZAMBIDAGINGSAPI[NAMA BAHAN],[2]!TBLREKAPBAHAN[[NAMA BAHAN]:[MODAL SATUAN]],3,FALSE) -> 1000 | G40: =VLOOKUP(TBLZAMBIDAGINGSAPI[NAMA BAHAN],[2]!TBLREKAPBAHAN[[NAMA BAHAN]:[MODAL SATUAN]],4,FALSE) -> 14 | H40: =VLOOKUP(TBLZAMBIDAGINGSAPI[NAMA BAHAN],[2]!TBLREKAPBAHAN[[NAMA BAHAN]:[MODAL SATUAN]],4,FALSE) -> 14 | I40: 10 | J40: =H40*I40 -> 140
B41: 13 | C41: TEPUNG CAKRA KEMBAR | D41: =VLOOKUP(TBLZAMBIDAGINGSAPI[NAMA BAHAN],[2]!TBLREKAPBAHAN[[NAMA BAHAN]:[MODAL SATUAN]],2,FALSE) -> 14000 | E41: =VLOOKUP(TBLZAMBIDAGINGSAPI[NAMA BAHAN],[2]!TBLREKAPBAHAN[[NAMA BAHAN]:[MODAL SATUAN]],3,FALSE) -> 1000 | G41: =VLOOKUP(TBLZAMBIDAGINGSAPI[NAMA BAHAN],[2]!TBLREKAPBAHAN[[NAMA BAHAN]:[MODAL SATUAN]],4,FALSE) -> 14 | H41: =VLOOKUP(TBLZAMBIDAGINGSAPI[NAMA BAHAN],[2]!TBLREKAPBAHAN[[NAMA BAHAN]:[MODAL SATUAN]],4,FALSE) -> 14 | I41: 20 | J41: =H41*I41 -> 280
... B48: 20 | C48: PLASTIK KLIP SEDANG 13 CM | D48: =VLOOKUP(TBLZAMBIDAGINGSAPI[NAMA BAHAN],[2]!TBLREKAPBAHAN[[NAMA BAHAN]:[MODAL SATUAN]],2,FALSE) -> 6000 | E48: =VLOOKUP(TBLZAMBIDAGINGSAPI[NAMA BAHAN],[2]!TBLREKAPBAHAN[[NAMA BAHAN]:[MODAL SATUAN]],3,FALSE) -> 100 | G48: =VLOOKUP(TBLZAMBIDAGINGSAPI[NAMA BAHAN],[2]!TBLREKAPBAHAN[[NAMA BAHAN]:[MODAL SATUAN]],4,FALSE) -> 60 | H48: =VLOOKUP(TBLZAMBIDAGINGSAPI[NAMA BAHAN],[2]!TBLREKAPBAHAN[[NAMA BAHAN]:[MODAL SATUAN]],4,FALSE) -> 60 | I48: 1 | J48: =H48*I48 -> 60
C49: MODAL | J49: =SUM(J29:J48) -> 5605.888

Sheet BURGER
A1: NAMA PRODUK | B1: KODE BAHAN | C1: NAMA BAHAN | D1: HARGA KULAK | E1: ISI | F1: SATUAN | G1: HARGA KULAK SATUAN | H1: MODAL SATUAN | I1: KEB. | J1: JUMLAH MODAL | L1: NAMA PRODUK | M1: KODE BAHAN | N1: NAMA BAHAN | O1: HARGA KULAK | P1: ISI | Q1: SATUAN | R1: HARGA KULAK SATUAN | S1: MODAL SATUAN | T1: SINGLE | U1: JUMLAH MODAL | V1: DOUBLE | W1: JUMLAH MODAL2 | Z1: NAMA PRODUK | AA1: KODE BAHAN | AB1: NAMA BAHAN | AC1: HARGA KULAK | AD1: ISI | AE1: SATUAN | AF1: HARGA KULAK SATUAN | AG1: MODAL SATUAN | AH1: KEB. | AI1: JUMLAH MODAL | AK1: NAMA PRODUK | AL1: KODE BAHAN | AM1: NAMA BAHAN | AN1: HARGA KULAK | AO1: ISI | AP1: SATUAN | AQ1: HARGA KULAK SATUAN | AR1: MODAL SATUAN | AS1: KEB. | AT1: JUMLAH MODAL
A2: BURGER MEDIUM NUGGET AYAM | B2: 1 | C2: SAOS TOMAT GRAM | D2: =VLOOKUP(TBLBURGERNUGGETAYAM[NAMA BAHAN],[2]!TBLREKAPBAHAN[[NAMA BAHAN]:[MODAL SATUAN]],2,FALSE) -> 20000 | E2: =VLOOKUP(TBLBURGERNUGGETAYAM[NAMA BAHAN],[2]!TBLREKAPBAHAN[[NAMA BAHAN]:[MODAL SATUAN]],3,FALSE) -> 1000 | F2: GRAM | G2: =VLOOKUP(TBLBURGERNUGGETAYAM[NAMA BAHAN],[2]!TBLREKAPBAHAN[[NAMA BAHAN]:[MODAL SATUAN]],4,FALSE) -> 20 | H2: =VLOOKUP(TBLBURGERNUGGETAYAM[NAMA BAHAN],[2]!TBLREKAPBAHAN[[NAMA BAHAN]:[MODAL SATUAN]],4,FALSE) -> 20 | I2: 15 | J2: =H2*I2 -> 300 | L2: BURGER MEDIUM DAGING SAPI | M2: 1 | N2: SAOS TOMAT GRAM | O2: =VLOOKUP(TBLBURGERDAGINGSAPI[NAMA BAHAN],[2]!TBLREKAPBAHAN[[NAMA BAHAN]:[MODAL SATUAN]],2,FALSE) -> 20000 | P2: =VLOOKUP(TBLBURGERDAGINGSAPI[NAMA BAHAN],[2]!TBLREKAPBAHAN[[NAMA BAHAN]:[MODAL SATUAN]],3,FALSE) -> 1000 | Q2: GRAM | R2: =VLOOKUP(TBLBURGERDAGINGSAPI[NAMA BAHAN],[2]!TBLREKAPBAHAN[[NAMA BAHAN]:[MODAL SATUAN]],4,FALSE) -> 20 | S2: =VLOOKUP(TBLBURGERDAGINGSAPI[NAMA BAHAN],[2]!TBLREKAPBAHAN[[NAMA BAHAN]:[MODAL SATUAN]],4,FALSE) -> 20 | T2: 15 | U2: =S2*T2 -> 300 | V2: 15 | W2: =TBLBURGERDAGINGSAPI[[#This Row],[MODAL SATUAN]]*TBLBURGERDAGINGSAPI[[#This Row],[DOUBLE]] -> 300 | Z2: BURGER MEDIUM DAGING SAPI TANPA SAYUR | AA2: 1 | AB2: SAOS TOMAT GRAM | AC2: =VLOOKUP(TBLBURGERDAGINGSAPITANPASAYUR[NAMA BAHAN],[2]!TBLREKAPBAHAN[[NAMA BAHAN]:[MODAL SATUAN]],2,FALSE) -> 20000 | AD2: =VLOOKUP(TBLBURGERDAGINGSAPITANPASAYUR[NAMA BAHAN],[2]!TBLREKAPBAHAN[[NAMA BAHAN]:[MODAL SATUAN]],3,FALSE) -> 1000 | AE2: GRAM | AF2: =VLOOKUP(TBLBURGERDAGINGSAPITANPASAYUR[NAMA BAHAN],[2]!TBLREKAPBAHAN[[NAMA BAHAN]:[MODAL SATUAN]],4,FALSE) -> 20 | AG2: =VLOOKUP(TBLBURGERDAGINGSAPITANPASAYUR[NAMA BAHAN],[2]!TBLREKAPBAHAN[[NAMA BAHAN]:[MODAL SATUAN]],4,FALSE) -> 20 | AH2: 15 | AI2: =AG2*AH2 -> 300 | AK2: BURGER MEDIUM NUGGET AYAM TANPA SAYUR | AL2: 1 | AM2: SAOS TOMAT GRAM | AN2: =VLOOKUP(TBLBURGERNUGGETAYAMTANPASAYUR[NAMA BAHAN],[2]!TBLREKAPBAHAN[[NAMA BAHAN]:[MODAL SATUAN]],2,FALSE) -> 20000 | AO2: =VLOOKUP(TBLBURGERNUGGETAYAMTANPASAYUR[NAMA BAHAN],[2]!TBLREKAPBAHAN[[NAMA BAHAN]:[MODAL SATUAN]],3,FALSE) -> 1000 | AP2: GRAM | AQ2: =VLOOKUP(TBLBURGERNUGGETAYAMTANPASAYUR[NAMA BAHAN],[2]!TBLREKAPBAHAN[[NAMA BAHAN]:[MODAL SATUAN]],4,FALSE) -> 20 | AR2: =VLOOKUP(TBLBURGERNUGGETAYAMTANPASAYUR[NAMA BAHAN],[2]!TBLREKAPBAHAN[[NAMA BAHAN]:[MODAL SATUAN]],4,FALSE) -> 20 | AS2: 15 | AT2: =AR2*AS2 -> 300
B3: 2 | C3: SAOS BBQ GRAM | D3: =VLOOKUP(TBLBURGERNUGGETAYAM[NAMA BAHAN],[2]!TBLREKAPBAHAN[[NAMA BAHAN]:[MODAL SATUAN]],2,FALSE) -> 12000 | E3: =VLOOKUP(TBLBURGERNUGGETAYAM[NAMA BAHAN],[2]!TBLREKAPBAHAN[[NAMA BAHAN]:[MODAL SATUAN]],3,FALSE) -> 250 | F3: GRAM | G3: =VLOOKUP(TBLBURGERNUGGETAYAM[NAMA BAHAN],[2]!TBLREKAPBAHAN[[NAMA BAHAN]:[MODAL SATUAN]],4,FALSE) -> 48 | H3: =VLOOKUP(TBLBURGERNUGGETAYAM[NAMA BAHAN],[2]!TBLREKAPBAHAN[[NAMA BAHAN]:[MODAL SATUAN]],4,FALSE) -> 48 | I3: 15 | J3: =H3*I3 -> 720 | M3: 2 | N3: SAOS BBQ GRAM | O3: =VLOOKUP(TBLBURGERDAGINGSAPI[NAMA BAHAN],[2]!TBLREKAPBAHAN[[NAMA BAHAN]:[MODAL SATUAN]],2,FALSE) -> 12000 | P3: =VLOOKUP(TBLBURGERDAGINGSAPI[NAMA BAHAN],[2]!TBLREKAPBAHAN[[NAMA BAHAN]:[MODAL SATUAN]],3,FALSE) -> 250 | Q3: GRAM | R3: =VLOOKUP(TBLBURGERDAGINGSAPI[NAMA BAHAN],[2]!TBLREKAPBAHAN[[NAMA BAHAN]:[MODAL SATUAN]],4,FALSE) -> 48 | S3: =VLOOKUP(TBLBURGERDAGINGSAPI[NAMA BAHAN],[2]!TBLREKAPBAHAN[[NAMA BAHAN]:[MODAL SATUAN]],4,FALSE) -> 48 | T3: 15 | U3: =S3*T3 -> 720 | V3: 15 | W3: =TBLBURGERDAGINGSAPI[[#This Row],[MODAL SATUAN]]*TBLBURGERDAGINGSAPI[[#This Row],[DOUBLE]] -> 720 | AA3: 2 | AB3: SAOS BBQ GRAM | AC3: =VLOOKUP(TBLBURGERDAGINGSAPITANPASAYUR[NAMA BAHAN],[2]!TBLREKAPBAHAN[[NAMA BAHAN]:[MODAL SATUAN]],2,FALSE) -> 12000 | AD3: =VLOOKUP(TBLBURGERDAGINGSAPITANPASAYUR[NAMA BAHAN],[2]!TBLREKAPBAHAN[[NAMA BAHAN]:[MODAL SATUAN]],3,FALSE) -> 250 | AE3: GRAM | AF3: =VLOOKUP(TBLBURGERDAGINGSAPITANPASAYUR[NAMA BAHAN],[2]!TBLREKAPBAHAN[[NAMA BAHAN]:[MODAL SATUAN]],4,FALSE) -> 48 | AG3: =VLOOKUP(TBLBURGERDAGINGSAPITANPASAYUR[NAMA BAHAN],[2]!TBLREKAPBAHAN[[NAMA BAHAN]:[MODAL SATUAN]],4,FALSE) -> 48 | AH3: 15 | AI3: =AG3*AH3 -> 720 | AL3: 2 | AM3: SAOS BBQ GRAM | AN3: =VLOOKUP(TBLBURGERNUGGETAYAMTANPASAYUR[NAMA BAHAN],[2]!TBLREKAPBAHAN[[NAMA BAHAN]:[MODAL SATUAN]],2,FALSE) -> 12000 | AO3: =VLOOKUP(TBLBURGERNUGGETAYAMTANPASAYUR[NAMA BAHAN],[2]!TBLREKAPBAHAN[[NAMA BAHAN]:[MODAL SATUAN]],3,FALSE) -> 250 | AP3: GRAM | AQ3: =VLOOKUP(TBLBURGERNUGGETAYAMTANPASAYUR[NAMA BAHAN],[2]!TBLREKAPBAHAN[[NAMA BAHAN]:[MODAL SATUAN]],4,FALSE) -> 48 | AR3: =VLOOKUP(TBLBURGERNUGGETAYAMTANPASAYUR[NAMA BAHAN],[2]!TBLREKAPBAHAN[[NAMA BAHAN]:[MODAL SATUAN]],4,FALSE) -> 48 | AS3: 15 | AT3: =AR3*AS3 -> 720
B4: 3 | C4: MAYONAIS GRAM | D4: =VLOOKUP(TBLBURGERNUGGETAYAM[NAMA BAHAN],[2]!TBLREKAPBAHAN[[NAMA BAHAN]:[MODAL SATUAN]],2,FALSE) -> 50000 | E4: =VLOOKUP(TBLBURGERNUGGETAYAM[NAMA BAHAN],[2]!TBLREKAPBAHAN[[NAMA BAHAN]:[MODAL SATUAN]],3,FALSE) -> 1000 | F4: GRAM | G4: =VLOOKUP(TBLBURGERNUGGETAYAM[NAMA BAHAN],[2]!TBLREKAPBAHAN[[NAMA BAHAN]:[MODAL SATUAN]],4,FALSE) -> 50 | H4: =VLOOKUP(TBLBURGERNUGGETAYAM[NAMA BAHAN],[2]!TBLREKAPBAHAN[[NAMA BAHAN]:[MODAL SATUAN]],4,FALSE) -> 50 | I4: 15 | J4: =H4*I4 -> 750 | M4: 3 | N4: MAYONAIS GRAM | O4: =VLOOKUP(TBLBURGERDAGINGSAPI[NAMA BAHAN],[2]!TBLREKAPBAHAN[[NAMA BAHAN]:[MODAL SATUAN]],2,FALSE) -> 50000 | P4: =VLOOKUP(TBLBURGERDAGINGSAPI[NAMA BAHAN],[2]!TBLREKAPBAHAN[[NAMA BAHAN]:[MODAL SATUAN]],3,FALSE) -> 1000 | Q4: GRAM | R4: =VLOOKUP(TBLBURGERDAGINGSAPI[NAMA BAHAN],[2]!TBLREKAPBAHAN[[NAMA BAHAN]:[MODAL SATUAN]],4,FALSE) -> 50 | S4: =VLOOKUP(TBLBURGERDAGINGSAPI[NAMA BAHAN],[2]!TBLREKAPBAHAN[[NAMA BAHAN]:[MODAL SATUAN]],4,FALSE) -> 50 | T4: 15 | U4: =S4*T4 -> 750 | V4: 15 | W4: =TBLBURGERDAGINGSAPI[[#This Row],[MODAL SATUAN]]*TBLBURGERDAGINGSAPI[[#This Row],[DOUBLE]] -> 750 | AA4: 3 | AB4: MAYONAIS GRAM | AC4: =VLOOKUP(TBLBURGERDAGINGSAPITANPASAYUR[NAMA BAHAN],[2]!TBLREKAPBAHAN[[NAMA BAHAN]:[MODAL SATUAN]],2,FALSE) -> 50000 | AD4: =VLOOKUP(TBLBURGERDAGINGSAPITANPASAYUR[NAMA BAHAN],[2]!TBLREKAPBAHAN[[NAMA BAHAN]:[MODAL SATUAN]],3,FALSE) -> 1000 | AE4: GRAM | AF4: =VLOOKUP(TBLBURGERDAGINGSAPITANPASAYUR[NAMA BAHAN],[2]!TBLREKAPBAHAN[[NAMA BAHAN]:[MODAL SATUAN]],4,FALSE) -> 50 | AG4: =VLOOKUP(TBLBURGERDAGINGSAPITANPASAYUR[NAMA BAHAN],[2]!TBLREKAPBAHAN[[NAMA BAHAN]:[MODAL SATUAN]],4,FALSE) -> 50 | AH4: 15 | AI4: =AG4*AH4 -> 750 | AL4: 3 | AM4: MAYONAIS GRAM | AN4: =VLOOKUP(TBLBURGERNUGGETAYAMTANPASAYUR[NAMA BAHAN],[2]!TBLREKAPBAHAN[[NAMA BAHAN]:[MODAL SATUAN]],2,FALSE) -> 50000 | AO4: =VLOOKUP(TBLBURGERNUGGETAYAMTANPASAYUR[NAMA BAHAN],[2]!TBLREKAPBAHAN[[NAMA BAHAN]:[MODAL SATUAN]],3,FALSE) -> 1000 | AP4: GRAM | AQ4: =VLOOKUP(TBLBURGERNUGGETAYAMTANPASAYUR[NAMA BAHAN],[2]!TBLREKAPBAHAN[[NAMA BAHAN]:[MODAL SATUAN]],4,FALSE) -> 50 | AR4: =VLOOKUP(TBLBURGERNUGGETAYAMTANPASAYUR[NAMA BAHAN],[2]!TBLREKAPBAHAN[[NAMA BAHAN]:[MODAL SATUAN]],4,FALSE) -> 50 | AS4: 15 | AT4: =AR4*AS4 -> 750
B5: 4 | C5: SAOS SAMBAL SACHET | D5: =VLOOKUP(TBLBURGERNUGGETAYAM[NAMA BAHAN],[2]!TBLREKAPBAHAN[[NAMA BAHAN]:[MODAL SATUAN]],2,FALSE) -> 8000 | E5: =VLOOKUP(TBLBURGERNUGGETAYAM[NAMA BAHAN],[2]!TBLREKAPBAHAN[[NAMA BAHAN]:[MODAL SATUAN]],3,FALSE) -> 24 | F5: SACHET | G5: =VLOOKUP(TBLBURGERNUGGETAYAM[NAMA BAHAN],[2]!TBLREKAPBAHAN[[NAMA BAHAN]:[MODAL SATUAN]],4,FALSE) -> 333.33333 | H5: =VLOOKUP(TBLBURGERNUGGETAYAM[NAMA BAHAN],[2]!TBLREKAPBAHAN[[NAMA BAHAN]:[MODAL SATUAN]],4,FALSE) -> 333.33333 | I5: 1 | J5: =H5*I5 -> 333.33333 | M5: 4 | N5: SAOS SAMBAL SACHET | O5: =VLOOKUP(TBLBURGERDAGINGSAPI[NAMA BAHAN],[2]!TBLREKAPBAHAN[[NAMA BAHAN]:[MODAL SATUAN]],2,FALSE) -> 8000 | P5: =VLOOKUP(TBLBURGERDAGINGSAPI[NAMA BAHAN],[2]!TBLREKAPBAHAN[[NAMA BAHAN]:[MODAL SATUAN]],3,FALSE) -> 24 | Q5: SACHET | R5: =VLOOKUP(TBLBURGERDAGINGSAPI[NAMA BAHAN],[2]!TBLREKAPBAHAN[[NAMA BAHAN]:[MODAL SATUAN]],4,FALSE) -> 333.33333 | S5: =VLOOKUP(TBLBURGERDAGINGSAPI[NAMA BAHAN],[2]!TBLREKAPBAHAN[[NAMA BAHAN]:[MODAL SATUAN]],4,FALSE) -> 333.33333 | T5: 1 | U5: =S5*T5 -> 333.33333 | V5: 1 | W5: =TBLBURGERDAGINGSAPI[[#This Row],[MODAL SATUAN]]*TBLBURGERDAGINGSAPI[[#This Row],[DOUBLE]] -> 333.33333 | AA5: 4 | AB5: SAOS SAMBAL SACHET | AC5: =VLOOKUP(TBLBURGERDAGINGSAPITANPASAYUR[NAMA BAHAN],[2]!TBLREKAPBAHAN[[NAMA BAHAN]:[MODAL SATUAN]],2,FALSE) -> 8000 | AD5: =VLOOKUP(TBLBURGERDAGINGSAPITANPASAYUR[NAMA BAHAN],[2]!TBLREKAPBAHAN[[NAMA BAHAN]:[MODAL SATUAN]],3,FALSE) -> 24 | AE5: SACHET | AF5: =VLOOKUP(TBLBURGERDAGINGSAPITANPASAYUR[NAMA BAHAN],[2]!TBLREKAPBAHAN[[NAMA BAHAN]:[MODAL SATUAN]],4,FALSE) -> 333.33333 | AG5: =VLOOKUP(TBLBURGERDAGINGSAPITANPASAYUR[NAMA BAHAN],[2]!TBLREKAPBAHAN[[NAMA BAHAN]:[MODAL SATUAN]],4,FALSE) -> 333.33333 | AH5: 1 | AI5: =AG5*AH5 -> 333.33333 | AL5: 4 | AM5: SAOS SAMBAL SACHET | AN5: =VLOOKUP(TBLBURGERNUGGETAYAMTANPASAYUR[NAMA BAHAN],[2]!TBLREKAPBAHAN[[NAMA BAHAN]:[MODAL SATUAN]],2,FALSE) -> 8000 | AO5: =VLOOKUP(TBLBURGERNUGGETAYAMTANPASAYUR[NAMA BAHAN],[2]!TBLREKAPBAHAN[[NAMA BAHAN]:[MODAL SATUAN]],3,FALSE) -> 24 | AP5: SACHET | AQ5: =VLOOKUP(TBLBURGERNUGGETAYAMTANPASAYUR[NAMA BAHAN],[2]!TBLREKAPBAHAN[[NAMA BAHAN]:[MODAL SATUAN]],4,FALSE) -> 333.33333 | AR5: =VLOOKUP(TBLBURGERNUGGETAYAMTANPASAYUR[NAMA BAHAN],[2]!TBLREKAPBAHAN[[NAMA BAHAN]:[MODAL SATUAN]],4,FALSE) -> 333.33333 | AS5: 1 | AT5: =AR5*AS5 -> 333.33333
B6: 5 | C6: KEJU SLICE MEDIUM SACHET | D6: =VLOOKUP(TBLBURGERNUGGETAYAM[NAMA BAHAN],[2]!TBLREKAPBAHAN[[NAMA BAHAN]:[MODAL SATUAN]],2,FALSE) -> 16000 | E6: =VLOOKUP(TBLBURGERNUGGETAYAM[NAMA BAHAN],[2]!TBLREKAPBAHAN[[NAMA BAHAN]:[MODAL SATUAN]],3,FALSE) -> 12 | F6: LEMBAR | G6: =VLOOKUP(TBLBURGERNUGGETAYAM[NAMA BAHAN],[2]!TBLREKAPBAHAN[[NAMA BAHAN]:[MODAL SATUAN]],4,FALSE) -> 1333.3333 | H6: =VLOOKUP(TBLBURGERNUGGETAYAM[NAMA BAHAN],[2]!TBLREKAPBAHAN[[NAMA BAHAN]:[MODAL SATUAN]],4,FALSE) -> 1333.3333 | I6: 1 | J6: =H6*I6 -> 1333.3333 | M6: 5 | N6: KEJU SLICE MEDIUM SACHET | O6: =VLOOKUP(TBLBURGERDAGINGSAPI[NAMA BAHAN],[2]!TBLREKAPBAHAN[[NAMA BAHAN]:[MODAL SATUAN]],2,FALSE) -> 16000 | P6: =VLOOKUP(TBLBURGERDAGINGSAPI[NAMA BAHAN],[2]!TBLREKAPBAHAN[[NAMA BAHAN]:[MODAL SATUAN]],3,FALSE) -> 12 | Q6: LEMBAR | R6: =VLOOKUP(TBLBURGERDAGINGSAPI[NAMA BAHAN],[2]!TBLREKAPBAHAN[[NAMA BAHAN]:[MODAL SATUAN]],4,FALSE) -> 1333.3333 | S6: =VLOOKUP(TBLBURGERDAGINGSAPI[NAMA BAHAN],[2]!TBLREKAPBAHAN[[NAMA BAHAN]:[MODAL SATUAN]],4,FALSE) -> 1333.3333 | T6: 1 | U6: =S6*T6 -> 1333.3333 | V6: 1 | W6: =TBLBURGERDAGINGSAPI[[#This Row],[MODAL SATUAN]]*TBLBURGERDAGINGSAPI[[#This Row],[DOUBLE]] -> 1333.3333 | AA6: 5 | AB6: KEJU SLICE MEDIUM SACHET | AC6: =VLOOKUP(TBLBURGERDAGINGSAPITANPASAYUR[NAMA BAHAN],[2]!TBLREKAPBAHAN[[NAMA BAHAN]:[MODAL SATUAN]],2,FALSE) -> 16000 | AD6: =VLOOKUP(TBLBURGERDAGINGSAPITANPASAYUR[NAMA BAHAN],[2]!TBLREKAPBAHAN[[NAMA BAHAN]:[MODAL SATUAN]],3,FALSE) -> 12 | AE6: LEMBAR | AF6: =VLOOKUP(TBLBURGERDAGINGSAPITANPASAYUR[NAMA BAHAN],[2]!TBLREKAPBAHAN[[NAMA BAHAN]:[MODAL SATUAN]],4,FALSE) -> 1333.3333 | AG6: =VLOOKUP(TBLBURGERDAGINGSAPITANPASAYUR[NAMA BAHAN],[2]!TBLREKAPBAHAN[[NAMA BAHAN]:[MODAL SATUAN]],4,FALSE) -> 1333.3333 | AH6: 1 | AI6: =AG6*AH6 -> 1333.3333 | AL6: 5 | AM6: KEJU SLICE MEDIUM SACHET | AN6: =VLOOKUP(TBLBURGERNUGGETAYAMTANPASAYUR[NAMA BAHAN],[2]!TBLREKAPBAHAN[[NAMA BAHAN]:[MODAL SATUAN]],2,FALSE) -> 16000 | AO6: =VLOOKUP(TBLBURGERNUGGETAYAMTANPASAYUR[NAMA BAHAN],[2]!TBLREKAPBAHAN[[NAMA BAHAN]:[MODAL SATUAN]],3,FALSE) -> 12 | AP6: LEMBAR | AQ6: =VLOOKUP(TBLBURGERNUGGETAYAMTANPASAYUR[NAMA BAHAN],[2]!TBLREKAPBAHAN[[NAMA BAHAN]:[MODAL SATUAN]],4,FALSE) -> 1333.3333 | AR6: =VLOOKUP(TBLBURGERNUGGETAYAMTANPASAYUR[NAMA BAHAN],[2]!TBLREKAPBAHAN[[NAMA BAHAN]:[MODAL SATUAN]],4,FALSE) -> 1333.3333 | AS6: 2 | AT6: =AR6*AS6 -> 2666.6667
B7: 6 | C7: DAGING SAPI | D7: =VLOOKUP(TBLBURGERNUGGETAYAM[NAMA BAHAN],[2]!TBLREKAPBAHAN[[NAMA BAHAN]:[MODAL SATUAN]],2,FALSE) -> 85000 | E7: =VLOOKUP(TBLBURGERNUGGETAYAM[NAMA BAHAN],[2]!TBLREKAPBAHAN[[NAMA BAHAN]:[MODAL SATUAN]],3,FALSE) -> 1000 | F7: GRAM | G7: =VLOOKUP(TBLBURGERNUGGETAYAM[NAMA BAHAN],[2]!TBLREKAPBAHAN[[NAMA BAHAN]:[MODAL SATUAN]],4,FALSE) -> 85 | H7: =VLOOKUP(TBLBURGERNUGGETAYAM[NAMA BAHAN],[2]!TBLREKAPBAHAN[[NAMA BAHAN]:[MODAL SATUAN]],4,FALSE) -> 85 | I7: 0 | J7: =H7*I7 -> 0 | M7: 6 | N7: DAGING SAPI | O7: =VLOOKUP(TBLBURGERDAGINGSAPI[NAMA BAHAN],[2]!TBLREKAPBAHAN[[NAMA BAHAN]:[MODAL SATUAN]],2,FALSE) -> 85000 | P7: =VLOOKUP(TBLBURGERDAGINGSAPI[NAMA BAHAN],[2]!TBLREKAPBAHAN[[NAMA BAHAN]:[MODAL SATUAN]],3,FALSE) -> 1000 | Q7: GRAM | R7: =VLOOKUP(TBLBURGERDAGINGSAPI[NAMA BAHAN],[2]!TBLREKAPBAHAN[[NAMA BAHAN]:[MODAL SATUAN]],4,FALSE) -> 85 | S7: =VLOOKUP(TBLBURGERDAGINGSAPI[NAMA BAHAN],[2]!TBLREKAPBAHAN[[NAMA BAHAN]:[MODAL SATUAN]],4,FALSE) -> 85 | T7: 45 | U7: =S7*T7 -> 3825 | V7: 90 | W7: =TBLBURGERDAGINGSAPI[[#This Row],[MODAL SATUAN]]*TBLBURGERDAGINGSAPI[[#This Row],[DOUBLE]] -> 7650 | AA7: 6 | AB7: DAGING SAPI | AC7: =VLOOKUP(TBLBURGERDAGINGSAPITANPASAYUR[NAMA BAHAN],[2]!TBLREKAPBAHAN[[NAMA BAHAN]:[MODAL SATUAN]],2,FALSE) -> 85000 | AD7: =VLOOKUP(TBLBURGERDAGINGSAPITANPASAYUR[NAMA BAHAN],[2]!TBLREKAPBAHAN[[NAMA BAHAN]:[MODAL SATUAN]],3,FALSE) -> 1000 | AE7: GRAM | AF7: =VLOOKUP(TBLBURGERDAGINGSAPITANPASAYUR[NAMA BAHAN],[2]!TBLREKAPBAHAN[[NAMA BAHAN]:[MODAL SATUAN]],4,FALSE) -> 85 | AG7: =VLOOKUP(TBLBURGERDAGINGSAPITANPASAYUR[NAMA BAHAN],[2]!TBLREKAPBAHAN[[NAMA BAHAN]:[MODAL SATUAN]],4,FALSE) -> 85 | AH7: 45 | AI7: =AG7*AH7 -> 3825 | AL7: 6 | AM7: DAGING SAPI | AN7: =VLOOKUP(TBLBURGERNUGGETAYAMTANPASAYUR[NAMA BAHAN],[2]!TBLREKAPBAHAN[[NAMA BAHAN]:[MODAL SATUAN]],2,FALSE) -> 85000 | AO7: =VLOOKUP(TBLBURGERNUGGETAYAMTANPASAYUR[NAMA BAHAN],[2]!TBLREKAPBAHAN[[NAMA BAHAN]:[MODAL SATUAN]],3,FALSE) -> 1000 | AP7: GRAM | AQ7: =VLOOKUP(TBLBURGERNUGGETAYAMTANPASAYUR[NAMA BAHAN],[2]!TBLREKAPBAHAN[[NAMA BAHAN]:[MODAL SATUAN]],4,FALSE) -> 85 | AR7: =VLOOKUP(TBLBURGERNUGGETAYAMTANPASAYUR[NAMA BAHAN],[2]!TBLREKAPBAHAN[[NAMA BAHAN]:[MODAL SATUAN]],4,FALSE) -> 85 | AS7: 0 | AT7: =AR7*AS7 -> 0
B8: 7 | C8: NUGGET AYAM | D8: =VLOOKUP(TBLBURGERNUGGETAYAM[NAMA BAHAN],[2]!TBLREKAPBAHAN[[NAMA BAHAN]:[MODAL SATUAN]],2,FALSE) -> 22000 | E8: =VLOOKUP(TBLBURGERNUGGETAYAM[NAMA BAHAN],[2]!TBLREKAPBAHAN[[NAMA BAHAN]:[MODAL SATUAN]],3,FALSE) -> 6 | F8: BIJI | G8: =VLOOKUP(TBLBURGERNUGGETAYAM[NAMA BAHAN],[2]!TBLREKAPBAHAN[[NAMA BAHAN]:[MODAL SATUAN]],4,FALSE) -> 3666.6667 | H8: =VLOOKUP(TBLBURGERNUGGETAYAM[NAMA BAHAN],[2]!TBLREKAPBAHAN[[NAMA BAHAN]:[MODAL SATUAN]],4,FALSE) -> 3666.6667 | I8: 1 | J8: =H8*I8 -> 3666.6667 | M8: 7 | N8: NUGGET AYAM | O8: =VLOOKUP(TBLBURGERDAGINGSAPI[NAMA BAHAN],[2]!TBLREKAPBAHAN[[NAMA BAHAN]:[MODAL SATUAN]],2,FALSE) -> 22000 | P8: =VLOOKUP(TBLBURGERDAGINGSAPI[NAMA BAHAN],[2]!TBLREKAPBAHAN[[NAMA BAHAN]:[MODAL SATUAN]],3,FALSE) -> 6 | Q8: BIJI | R8: =VLOOKUP(TBLBURGERDAGINGSAPI[NAMA BAHAN],[2]!TBLREKAPBAHAN[[NAMA BAHAN]:[MODAL SATUAN]],4,FALSE) -> 3666.6667 | S8: =VLOOKUP(TBLBURGERDAGINGSAPI[NAMA BAHAN],[2]!TBLREKAPBAHAN[[NAMA BAHAN]:[MODAL SATUAN]],4,FALSE) -> 3666.6667 | T8: 0 | U8: =S8*T8 -> 0 | V8: 0 | W8: =TBLBURGERDAGINGSAPI[[#This Row],[MODAL SATUAN]]*TBLBURGERDAGINGSAPI[[#This Row],[DOUBLE]] -> 0 | AA8: 7 | AB8: NUGGET AYAM | AC8: =VLOOKUP(TBLBURGERDAGINGSAPITANPASAYUR[NAMA BAHAN],[2]!TBLREKAPBAHAN[[NAMA BAHAN]:[MODAL SATUAN]],2,FALSE) -> 22000 | AD8: =VLOOKUP(TBLBURGERDAGINGSAPITANPASAYUR[NAMA BAHAN],[2]!TBLREKAPBAHAN[[NAMA BAHAN]:[MODAL SATUAN]],3,FALSE) -> 6 | AE8: BIJI | AF8: =VLOOKUP(TBLBURGERDAGINGSAPITANPASAYUR[NAMA BAHAN],[2]!TBLREKAPBAHAN[[NAMA BAHAN]:[MODAL SATUAN]],4,FALSE) -> 3666.6667 | AG8: =VLOOKUP(TBLBURGERDAGINGSAPITANPASAYUR[NAMA BAHAN],[2]!TBLREKAPBAHAN[[NAMA BAHAN]:[MODAL SATUAN]],4,FALSE) -> 3666.6667 | AH8: 0 | AI8: =AG8*AH8 -> 0 | AL8: 7 | AM8: NUGGET AYAM | AN8: =VLOOKUP(TBLBURGERNUGGETAYAMTANPASAYUR[NAMA BAHAN],[2]!TBLREKAPBAHAN[[NAMA BAHAN]:[MODAL SATUAN]],2,FALSE) -> 22000 | AO8: =VLOOKUP(TBLBURGERNUGGETAYAMTANPASAYUR[NAMA BAHAN],[2]!TBLREKAPBAHAN[[NAMA BAHAN]:[MODAL SATUAN]],3,FALSE) -> 6 | AP8: BIJI | AQ8: =VLOOKUP(TBLBURGERNUGGETAYAMTANPASAYUR[NAMA BAHAN],[2]!TBLREKAPBAHAN[[NAMA BAHAN]:[MODAL SATUAN]],4,FALSE) -> 3666.6667 | AR8: =VLOOKUP(TBLBURGERNUGGETAYAMTANPASAYUR[NAMA BAHAN],[2]!TBLREKAPBAHAN[[NAMA BAHAN]:[MODAL SATUAN]],4,FALSE) -> 3666.6667 | AS8: 1 | AT8: =AR8*AS8 -> 3666.6667
B9: 8 | C9: ROTI BURGER MEDIUM | D9: =VLOOKUP(TBLBURGERNUGGETAYAM[NAMA BAHAN],[2]!TBLREKAPBAHAN[[NAMA BAHAN]:[MODAL SATUAN]],2,FALSE) -> 15000 | E9: =VLOOKUP(TBLBURGERNUGGETAYAM[NAMA BAHAN],[2]!TBLREKAPBAHAN[[NAMA BAHAN]:[MODAL SATUAN]],3,FALSE) -> 6 | F9: BIJI | G9: =VLOOKUP(TBLBURGERNUGGETAYAM[NAMA BAHAN],[2]!TBLREKAPBAHAN[[NAMA BAHAN]:[MODAL SATUAN]],4,FALSE) -> 2500 | H9: =VLOOKUP(TBLBURGERNUGGETAYAM[NAMA BAHAN],[2]!TBLREKAPBAHAN[[NAMA BAHAN]:[MODAL SATUAN]],4,FALSE) -> 2500 | I9: 1 | J9: =H9*I9 -> 2500 | M9: 8 | N9: ROTI BURGER MEDIUM | O9: =VLOOKUP(TBLBURGERDAGINGSAPI[NAMA BAHAN],[2]!TBLREKAPBAHAN[[NAMA BAHAN]:[MODAL SATUAN]],2,FALSE) -> 15000 | P9: =VLOOKUP(TBLBURGERDAGINGSAPI[NAMA BAHAN],[2]!TBLREKAPBAHAN[[NAMA BAHAN]:[MODAL SATUAN]],3,FALSE) -> 6 | Q9: BIJI | R9: =VLOOKUP(TBLBURGERDAGINGSAPI[NAMA BAHAN],[2]!TBLREKAPBAHAN[[NAMA BAHAN]:[MODAL SATUAN]],4,FALSE) -> 2500 | S9: =VLOOKUP(TBLBURGERDAGINGSAPI[NAMA BAHAN],[2]!TBLREKAPBAHAN[[NAMA BAHAN]:[MODAL SATUAN]],4,FALSE) -> 2500 | T9: 1 | U9: =S9*T9 -> 2500 | V9: 1 | W9: =TBLBURGERDAGINGSAPI[[#This Row],[MODAL SATUAN]]*TBLBURGERDAGINGSAPI[[#This Row],[DOUBLE]] -> 2500 | AA9: 8 | AB9: ROTI BURGER MEDIUM | AC9: =VLOOKUP(TBLBURGERDAGINGSAPITANPASAYUR[NAMA BAHAN],[2]!TBLREKAPBAHAN[[NAMA BAHAN]:[MODAL SATUAN]],2,FALSE) -> 15000 | AD9: =VLOOKUP(TBLBURGERDAGINGSAPITANPASAYUR[NAMA BAHAN],[2]!TBLREKAPBAHAN[[NAMA BAHAN]:[MODAL SATUAN]],3,FALSE) -> 6 | AE9: BIJI | AF9: =VLOOKUP(TBLBURGERDAGINGSAPITANPASAYUR[NAMA BAHAN],[2]!TBLREKAPBAHAN[[NAMA BAHAN]:[MODAL SATUAN]],4,FALSE) -> 2500 | AG9: =VLOOKUP(TBLBURGERDAGINGSAPITANPASAYUR[NAMA BAHAN],[2]!TBLREKAPBAHAN[[NAMA BAHAN]:[MODAL SATUAN]],4,FALSE) -> 2500 | AH9: 1 | AI9: =AG9*AH9 -> 2500 | AL9: 8 | AM9: ROTI BURGER MEDIUM | AN9: =VLOOKUP(TBLBURGERNUGGETAYAMTANPASAYUR[NAMA BAHAN],[2]!TBLREKAPBAHAN[[NAMA BAHAN]:[MODAL SATUAN]],2,FALSE) -> 15000 | AO9: =VLOOKUP(TBLBURGERNUGGETAYAMTANPASAYUR[NAMA BAHAN],[2]!TBLREKAPBAHAN[[NAMA BAHAN]:[MODAL SATUAN]],3,FALSE) -> 6 | AP9: BIJI | AQ9: =VLOOKUP(TBLBURGERNUGGETAYAMTANPASAYUR[NAMA BAHAN],[2]!TBLREKAPBAHAN[[NAMA BAHAN]:[MODAL SATUAN]],4,FALSE) -> 2500 | AR9: =VLOOKUP(TBLBURGERNUGGETAYAMTANPASAYUR[NAMA BAHAN],[2]!TBLREKAPBAHAN[[NAMA BAHAN]:[MODAL SATUAN]],4,FALSE) -> 2500 | AS9: 1 | AT9: =AR9*AS9 -> 2500
B10: 9 | C10: TIMUN IRIS | D10: =VLOOKUP(TBLBURGERNUGGETAYAM[NAMA BAHAN],[2]!TBLREKAPBAHAN[[NAMA BAHAN]:[MODAL SATUAN]],2,FALSE) -> 2000 | E10: =VLOOKUP(TBLBURGERNUGGETAYAM[NAMA BAHAN],[2]!TBLREKAPBAHAN[[NAMA BAHAN]:[MODAL SATUAN]],3,FALSE) -> 60 | F10: IRIS | G10: =VLOOKUP(TBLBURGERNUGGETAYAM[NAMA BAHAN],[2]!TBLREKAPBAHAN[[NAMA BAHAN]:[MODAL SATUAN]],4,FALSE) -> 33.333333 | H10: =VLOOKUP(TBLBURGERNUGGETAYAM[NAMA BAHAN],[2]!TBLREKAPBAHAN[[NAMA BAHAN]:[MODAL SATUAN]],4,FALSE) -> 33.333333 | I10: 3 | J10: =H10*I10 -> 100 | M10: 9 | N10: TIMUN IRIS | O10: =VLOOKUP(TBLBURGERDAGINGSAPI[NAMA BAHAN],[2]!TBLREKAPBAHAN[[NAMA BAHAN]:[MODAL SATUAN]],2,FALSE) -> 2000 | P10: =VLOOKUP(TBLBURGERDAGINGSAPI[NAMA BAHAN],[2]!TBLREKAPBAHAN[[NAMA BAHAN]:[MODAL SATUAN]],3,FALSE) -> 60 | Q10: IRIS | R10: =VLOOKUP(TBLBURGERDAGINGSAPI[NAMA BAHAN],[2]!TBLREKAPBAHAN[[NAMA BAHAN]:[MODAL SATUAN]],4,FALSE) -> 33.333333 | S10: =VLOOKUP(TBLBURGERDAGINGSAPI[NAMA BAHAN],[2]!TBLREKAPBAHAN[[NAMA BAHAN]:[MODAL SATUAN]],4,FALSE) -> 33.333333 | T10: 3 | U10: =S10*T10 -> 100 | V10: 3 | W10: =TBLBURGERDAGINGSAPI[[#This Row],[MODAL SATUAN]]*TBLBURGERDAGINGSAPI[[#This Row],[DOUBLE]] -> 100 | AA10: 9 | AB10: TIMUN IRIS | AC10: =VLOOKUP(TBLBURGERDAGINGSAPITANPASAYUR[NAMA BAHAN],[2]!TBLREKAPBAHAN[[NAMA BAHAN]:[MODAL SATUAN]],2,FALSE) -> 2000 | AD10: =VLOOKUP(TBLBURGERDAGINGSAPITANPASAYUR[NAMA BAHAN],[2]!TBLREKAPBAHAN[[NAMA BAHAN]:[MODAL SATUAN]],3,FALSE) -> 60 | AE10: IRIS | AF10: =VLOOKUP(TBLBURGERDAGINGSAPITANPASAYUR[NAMA BAHAN],[2]!TBLREKAPBAHAN[[NAMA BAHAN]:[MODAL SATUAN]],4,FALSE) -> 33.333333 | AG10: =VLOOKUP(TBLBURGERDAGINGSAPITANPASAYUR[NAMA BAHAN],[2]!TBLREKAPBAHAN[[NAMA BAHAN]:[MODAL SATUAN]],4,FALSE) -> 33.333333 | AH10: 0 | AI10: =AG10*AH10 -> 0 | AL10: 9 | AM10: TIMUN IRIS | AN10: =VLOOKUP(TBLBURGERNUGGETAYAMTANPASAYUR[NAMA BAHAN],[2]!TBLREKAPBAHAN[[NAMA BAHAN]:[MODAL SATUAN]],2,FALSE) -> 2000 | AO10: =VLOOKUP(TBLBURGERNUGGETAYAMTANPASAYUR[NAMA BAHAN],[2]!TBLREKAPBAHAN[[NAMA BAHAN]:[MODAL SATUAN]],3,FALSE) -> 60 | AP10: IRIS | AQ10: =VLOOKUP(TBLBURGERNUGGETAYAMTANPASAYUR[NAMA BAHAN],[2]!TBLREKAPBAHAN[[NAMA BAHAN]:[MODAL SATUAN]],4,FALSE) -> 33.333333 | AR10: =VLOOKUP(TBLBURGERNUGGETAYAMTANPASAYUR[NAMA BAHAN],[2]!TBLREKAPBAHAN[[NAMA BAHAN]:[MODAL SATUAN]],4,FALSE) -> 33.333333 | AS10: 0 | AT10: =AR10*AS10 -> 0
B11: 10 | C11: TOMAT IRIS | D11: =VLOOKUP(TBLBURGERNUGGETAYAM[NAMA BAHAN],[2]!TBLREKAPBAHAN[[NAMA BAHAN]:[MODAL SATUAN]],2,FALSE) -> 2000 | E11: =VLOOKUP(TBLBURGERNUGGETAYAM[NAMA BAHAN],[2]!TBLREKAPBAHAN[[NAMA BAHAN]:[MODAL SATUAN]],3,FALSE) -> 45 | F11: IRIS | G11: =VLOOKUP(TBLBURGERNUGGETAYAM[NAMA BAHAN],[2]!TBLREKAPBAHAN[[NAMA BAHAN]:[MODAL SATUAN]],4,FALSE) -> 44.444444 | H11: =VLOOKUP(TBLBURGERNUGGETAYAM[NAMA BAHAN],[2]!TBLREKAPBAHAN[[NAMA BAHAN]:[MODAL SATUAN]],4,FALSE) -> 44.444444 | I11: 2 | J11: =H11*I11 -> 88.888889 | M11: 10 | N11: TOMAT IRIS | O11: =VLOOKUP(TBLBURGERDAGINGSAPI[NAMA BAHAN],[2]!TBLREKAPBAHAN[[NAMA BAHAN]:[MODAL SATUAN]],2,FALSE) -> 2000 | P11: =VLOOKUP(TBLBURGERDAGINGSAPI[NAMA BAHAN],[2]!TBLREKAPBAHAN[[NAMA BAHAN]:[MODAL SATUAN]],3,FALSE) -> 45 | Q11: IRIS | R11: =VLOOKUP(TBLBURGERDAGINGSAPI[NAMA BAHAN],[2]!TBLREKAPBAHAN[[NAMA BAHAN]:[MODAL SATUAN]],4,FALSE) -> 44.444444 | S11: =VLOOKUP(TBLBURGERDAGINGSAPI[NAMA BAHAN],[2]!TBLREKAPBAHAN[[NAMA BAHAN]:[MODAL SATUAN]],4,FALSE) -> 44.444444 | T11: 2 | U11: =S11*T11 -> 88.888889 | V11: 2 | W11: =TBLBURGERDAGINGSAPI[[#This Row],[MODAL SATUAN]]*TBLBURGERDAGINGSAPI[[#This Row],[DOUBLE]] -> 88.888889 | AA11: 10 | AB11: TOMAT IRIS | AC11: =VLOOKUP(TBLBURGERDAGINGSAPITANPASAYUR[NAMA BAHAN],[2]!TBLREKAPBAHAN[[NAMA BAHAN]:[MODAL SATUAN]],2,FALSE) -> 2000 | AD11: =VLOOKUP(TBLBURGERDAGINGSAPITANPASAYUR[NAMA BAHAN],[2]!TBLREKAPBAHAN[[NAMA BAHAN]:[MODAL SATUAN]],3,FALSE) -> 45 | AE11: IRIS | AF11: =VLOOKUP(TBLBURGERDAGINGSAPITANPASAYUR[NAMA BAHAN],[2]!TBLREKAPBAHAN[[NAMA BAHAN]:[MODAL SATUAN]],4,FALSE) -> 44.444444 | AG11: =VLOOKUP(TBLBURGERDAGINGSAPITANPASAYUR[NAMA BAHAN],[2]!TBLREKAPBAHAN[[NAMA BAHAN]:[MODAL SATUAN]],4,FALSE) -> 44.444444 | AH11: 0 | AI11: =AG11*AH11 -> 0 | AL11: 10 | AM11: TOMAT IRIS | AN11: =VLOOKUP(TBLBURGERNUGGETAYAMTANPASAYUR[NAMA BAHAN],[2]!TBLREKAPBAHAN[[NAMA BAHAN]:[MODAL SATUAN]],2,FALSE) -> 2000 | AO11: =VLOOKUP(TBLBURGERNUGGETAYAMTANPASAYUR[NAMA BAHAN],[2]!TBLREKAPBAHAN[[NAMA BAHAN]:[MODAL SATUAN]],3,FALSE) -> 45 | AP11: IRIS | AQ11: =VLOOKUP(TBLBURGERNUGGETAYAMTANPASAYUR[NAMA BAHAN],[2]!TBLREKAPBAHAN[[NAMA BAHAN]:[MODAL SATUAN]],4,FALSE) -> 44.444444 | AR11: =VLOOKUP(TBLBURGERNUGGETAYAMTANPASAYUR[NAMA BAHAN],[2]!TBLREKAPBAHAN[[NAMA BAHAN]:[MODAL SATUAN]],4,FALSE) -> 44.444444 | AS11: 0 | AT11: =AR11*AS11 -> 0
B12: 11 | C12: SLADA | D12: =VLOOKUP(TBLBURGERNUGGETAYAM[NAMA BAHAN],[2]!TBLREKAPBAHAN[[NAMA BAHAN]:[MODAL SATUAN]],2,FALSE) -> 60000 | E12: =VLOOKUP(TBLBURGERNUGGETAYAM[NAMA BAHAN],[2]!TBLREKAPBAHAN[[NAMA BAHAN]:[MODAL SATUAN]],3,FALSE) -> 50 | F12: PORSI | G12: =VLOOKUP(TBLBURGERNUGGETAYAM[NAMA BAHAN],[2]!TBLREKAPBAHAN[[NAMA BAHAN]:[MODAL SATUAN]],4,FALSE) -> 1200 | H12: =VLOOKUP(TBLBURGERNUGGETAYAM[NAMA BAHAN],[2]!TBLREKAPBAHAN[[NAMA BAHAN]:[MODAL SATUAN]],4,FALSE) -> 1200 | I12: 0.5 | J12: =H12*I12 -> 600 | M12: 11 | N12: SLADA | O12: =VLOOKUP(TBLBURGERDAGINGSAPI[NAMA BAHAN],[2]!TBLREKAPBAHAN[[NAMA BAHAN]:[MODAL SATUAN]],2,FALSE) -> 60000 | P12: =VLOOKUP(TBLBURGERDAGINGSAPI[NAMA BAHAN],[2]!TBLREKAPBAHAN[[NAMA BAHAN]:[MODAL SATUAN]],3,FALSE) -> 50 | Q12: PORSI | R12: =VLOOKUP(TBLBURGERDAGINGSAPI[NAMA BAHAN],[2]!TBLREKAPBAHAN[[NAMA BAHAN]:[MODAL SATUAN]],4,FALSE) -> 1200 | S12: =VLOOKUP(TBLBURGERDAGINGSAPI[NAMA BAHAN],[2]!TBLREKAPBAHAN[[NAMA BAHAN]:[MODAL SATUAN]],4,FALSE) -> 1200 | T12: 0.5 | U12: =S12*T12 -> 600 | V12: 0.5 | W12: =TBLBURGERDAGINGSAPI[[#This Row],[MODAL SATUAN]]*TBLBURGERDAGINGSAPI[[#This Row],[DOUBLE]] -> 600 | AA12: 11 | AB12: SLADA | AC12: =VLOOKUP(TBLBURGERDAGINGSAPITANPASAYUR[NAMA BAHAN],[2]!TBLREKAPBAHAN[[NAMA BAHAN]:[MODAL SATUAN]],2,FALSE) -> 60000 | AD12: =VLOOKUP(TBLBURGERDAGINGSAPITANPASAYUR[NAMA BAHAN],[2]!TBLREKAPBAHAN[[NAMA BAHAN]:[MODAL SATUAN]],3,FALSE) -> 50 | AE12: PORSI | AF12: =VLOOKUP(TBLBURGERDAGINGSAPITANPASAYUR[NAMA BAHAN],[2]!TBLREKAPBAHAN[[NAMA BAHAN]:[MODAL SATUAN]],4,FALSE) -> 1200 | AG12: =VLOOKUP(TBLBURGERDAGINGSAPITANPASAYUR[NAMA BAHAN],[2]!TBLREKAPBAHAN[[NAMA BAHAN]:[MODAL SATUAN]],4,FALSE) -> 1200 | AH12: 0 | AI12: =AG12*AH12 -> 0 | AL12: 11 | AM12: SLADA | AN12: =VLOOKUP(TBLBURGERNUGGETAYAMTANPASAYUR[NAMA BAHAN],[2]!TBLREKAPBAHAN[[NAMA BAHAN]:[MODAL SATUAN]],2,FALSE) -> 60000 | AO12: =VLOOKUP(TBLBURGERNUGGETAYAMTANPASAYUR[NAMA BAHAN],[2]!TBLREKAPBAHAN[[NAMA BAHAN]:[MODAL SATUAN]],3,FALSE) -> 50 | AP12: PORSI | AQ12: =VLOOKUP(TBLBURGERNUGGETAYAMTANPASAYUR[NAMA BAHAN],[2]!TBLREKAPBAHAN[[NAMA BAHAN]:[MODAL SATUAN]],4,FALSE) -> 1200 | AR12: =VLOOKUP(TBLBURGERNUGGETAYAMTANPASAYUR[NAMA BAHAN],[2]!TBLREKAPBAHAN[[NAMA BAHAN]:[MODAL SATUAN]],4,FALSE) -> 1200 | AS12: 0 | AT12: =AR12*AS12 -> 0
B13: 12 | C13: MENTEGA | D13: =VLOOKUP(TBLBURGERNUGGETAYAM[NAMA BAHAN],[2]!TBLREKAPBAHAN[[NAMA BAHAN]:[MODAL SATUAN]],2,FALSE) -> 35000 | E13: =VLOOKUP(TBLBURGERNUGGETAYAM[NAMA BAHAN],[2]!TBLREKAPBAHAN[[NAMA BAHAN]:[MODAL SATUAN]],3,FALSE) -> 1000 | F13: GRAM | G13: =VLOOKUP(TBLBURGERNUGGETAYAM[NAMA BAHAN],[2]!TBLREKAPBAHAN[[NAMA BAHAN]:[MODAL SATUAN]],4,FALSE) -> 35 | H13: =VLOOKUP(TBLBURGERNUGGETAYAM[NAMA BAHAN],[2]!TBLREKAPBAHAN[[NAMA BAHAN]:[MODAL SATUAN]],4,FALSE) -> 35 | I13: 5 | J13: =H13*I13 -> 175 | M13: 12 | N13: MENTEGA | O13: =VLOOKUP(TBLBURGERDAGINGSAPI[NAMA BAHAN],[2]!TBLREKAPBAHAN[[NAMA BAHAN]:[MODAL SATUAN]],2,FALSE) -> 35000 | P13: =VLOOKUP(TBLBURGERDAGINGSAPI[NAMA BAHAN],[2]!TBLREKAPBAHAN[[NAMA BAHAN]:[MODAL SATUAN]],3,FALSE) -> 1000 | Q13: GRAM | R13: =VLOOKUP(TBLBURGERDAGINGSAPI[NAMA BAHAN],[2]!TBLREKAPBAHAN[[NAMA BAHAN]:[MODAL SATUAN]],4,FALSE) -> 35 | S13: =VLOOKUP(TBLBURGERDAGINGSAPI[NAMA BAHAN],[2]!TBLREKAPBAHAN[[NAMA BAHAN]:[MODAL SATUAN]],4,FALSE) -> 35 | T13: 5 | U13: =S13*T13 -> 175 | V13: 5 | W13: =TBLBURGERDAGINGSAPI[[#This Row],[MODAL SATUAN]]*TBLBURGERDAGINGSAPI[[#This Row],[DOUBLE]] -> 175 | AA13: 12 | AB13: MENTEGA | AC13: =VLOOKUP(TBLBURGERDAGINGSAPITANPASAYUR[NAMA BAHAN],[2]!TBLREKAPBAHAN[[NAMA BAHAN]:[MODAL SATUAN]],2,FALSE) -> 35000 | AD13: =VLOOKUP(TBLBURGERDAGINGSAPITANPASAYUR[NAMA BAHAN],[2]!TBLREKAPBAHAN[[NAMA BAHAN]:[MODAL SATUAN]],3,FALSE) -> 1000 | AE13: GRAM | AF13: =VLOOKUP(TBLBURGERDAGINGSAPITANPASAYUR[NAMA BAHAN],[2]!TBLREKAPBAHAN[[NAMA BAHAN]:[MODAL SATUAN]],4,FALSE) -> 35 | AG13: =VLOOKUP(TBLBURGERDAGINGSAPITANPASAYUR[NAMA BAHAN],[2]!TBLREKAPBAHAN[[NAMA BAHAN]:[MODAL SATUAN]],4,FALSE) -> 35 | AH13: 5 | AI13: =AG13*AH13 -> 175 | AL13: 12 | AM13: MENTEGA | AN13: =VLOOKUP(TBLBURGERNUGGETAYAMTANPASAYUR[NAMA BAHAN],[2]!TBLREKAPBAHAN[[NAMA BAHAN]:[MODAL SATUAN]],2,FALSE) -> 35000 | AO13: =VLOOKUP(TBLBURGERNUGGETAYAMTANPASAYUR[NAMA BAHAN],[2]!TBLREKAPBAHAN[[NAMA BAHAN]:[MODAL SATUAN]],3,FALSE) -> 1000 | AP13: GRAM | AQ13: =VLOOKUP(TBLBURGERNUGGETAYAMTANPASAYUR[NAMA BAHAN],[2]!TBLREKAPBAHAN[[NAMA BAHAN]:[MODAL SATUAN]],4,FALSE) -> 35 | AR13: =VLOOKUP(TBLBURGERNUGGETAYAMTANPASAYUR[NAMA BAHAN],[2]!TBLREKAPBAHAN[[NAMA BAHAN]:[MODAL SATUAN]],4,FALSE) -> 35 | AS13: 5 | AT13: =AR13*AS13 -> 175
B14: 13 | C14: GAS ELPIJI | D14: =VLOOKUP(TBLBURGERNUGGETAYAM[NAMA BAHAN],[2]!TBLREKAPBAHAN[[NAMA BAHAN]:[MODAL SATUAN]],2,FALSE) -> 23000 | E14: =VLOOKUP(TBLBURGERNUGGETAYAM[NAMA BAHAN],[2]!TBLREKAPBAHAN[[NAMA BAHAN]:[MODAL SATUAN]],3,FALSE) -> 3000 | F14: GRAM | G14: =VLOOKUP(TBLBURGERNUGGETAYAM[NAMA BAHAN],[2]!TBLREKAPBAHAN[[NAMA BAHAN]:[MODAL SATUAN]],4,FALSE) -> 7.6666667 | H14: =VLOOKUP(TBLBURGERNUGGETAYAM[NAMA BAHAN],[2]!TBLREKAPBAHAN[[NAMA BAHAN]:[MODAL SATUAN]],4,FALSE) -> 7.6666667 | I14: 5 | J14: =H14*I14 -> 38.333333 | M14: 13 | N14: GAS ELPIJI | O14: =VLOOKUP(TBLBURGERDAGINGSAPI[NAMA BAHAN],[2]!TBLREKAPBAHAN[[NAMA BAHAN]:[MODAL SATUAN]],2,FALSE) -> 23000 | P14: =VLOOKUP(TBLBURGERDAGINGSAPI[NAMA BAHAN],[2]!TBLREKAPBAHAN[[NAMA BAHAN]:[MODAL SATUAN]],3,FALSE) -> 3000 | Q14: GRAM | R14: =VLOOKUP(TBLBURGERDAGINGSAPI[NAMA BAHAN],[2]!TBLREKAPBAHAN[[NAMA BAHAN]:[MODAL SATUAN]],4,FALSE) -> 7.6666667 | S14: =VLOOKUP(TBLBURGERDAGINGSAPI[NAMA BAHAN],[2]!TBLREKAPBAHAN[[NAMA BAHAN]:[MODAL SATUAN]],4,FALSE) -> 7.6666667 | T14: 5 | U14: =S14*T14 -> 38.333333 | V14: 5 | W14: =TBLBURGERDAGINGSAPI[[#This Row],[MODAL SATUAN]]*TBLBURGERDAGINGSAPI[[#This Row],[DOUBLE]] -> 38.333333 | AA14: 13 | AB14: GAS ELPIJI | AC14: =VLOOKUP(TBLBURGERDAGINGSAPITANPASAYUR[NAMA BAHAN],[2]!TBLREKAPBAHAN[[NAMA BAHAN]:[MODAL SATUAN]],2,FALSE) -> 23000 | AD14: =VLOOKUP(TBLBURGERDAGINGSAPITANPASAYUR[NAMA BAHAN],[2]!TBLREKAPBAHAN[[NAMA BAHAN]:[MODAL SATUAN]],3,FALSE) -> 3000 | AE14: GRAM | AF14: =VLOOKUP(TBLBURGERDAGINGSAPITANPASAYUR[NAMA BAHAN],[2]!TBLREKAPBAHAN[[NAMA BAHAN]:[MODAL SATUAN]],4,FALSE) -> 7.6666667 | AG14: =VLOOKUP(TBLBURGERDAGINGSAPITANPASAYUR[NAMA BAHAN],[2]!TBLREKAPBAHAN[[NAMA BAHAN]:[MODAL SATUAN]],4,FALSE) -> 7.6666667 | AH14: 5 | AI14: =AG14*AH14 -> 38.333333 | AL14: 13 | AM14: GAS ELPIJI | AN14: =VLOOKUP(TBLBURGERNUGGETAYAMTANPASAYUR[NAMA BAHAN],[2]!TBLREKAPBAHAN[[NAMA BAHAN]:[MODAL SATUAN]],2,FALSE) -> 23000 | AO14: =VLOOKUP(TBLBURGERNUGGETAYAMTANPASAYUR[NAMA BAHAN],[2]!TBLREKAPBAHAN[[NAMA BAHAN]:[MODAL SATUAN]],3,FALSE) -> 3000 | AP14: GRAM | AQ14: =VLOOKUP(TBLBURGERNUGGETAYAMTANPASAYUR[NAMA BAHAN],[2]!TBLREKAPBAHAN[[NAMA BAHAN]:[MODAL SATUAN]],4,FALSE) -> 7.6666667 | AR14: =VLOOKUP(TBLBURGERNUGGETAYAMTANPASAYUR[NAMA BAHAN],[2]!TBLREKAPBAHAN[[NAMA BAHAN]:[MODAL SATUAN]],4,FALSE) -> 7.6666667 | AS14: 5 | AT14: =AR14*AS14 -> 38.333333
... B17: 16 | C17: KRESEK 15 CM | D17: =VLOOKUP(TBLBURGERNUGGETAYAM[NAMA BAHAN],[2]!TBLREKAPBAHAN[[NAMA BAHAN]:[MODAL SATUAN]],2,FALSE) -> 7000 | E17: =VLOOKUP(TBLBURGERNUGGETAYAM[NAMA BAHAN],[2]!TBLREKAPBAHAN[[NAMA BAHAN]:[MODAL SATUAN]],3,FALSE) -> 50 | F17: BIJI | G17: =VLOOKUP(TBLBURGERNUGGETAYAM[NAMA BAHAN],[2]!TBLREKAPBAHAN[[NAMA BAHAN]:[MODAL SATUAN]],4,FALSE) -> 140 | H17: =VLOOKUP(TBLBURGERNUGGETAYAM[NAMA BAHAN],[2]!TBLREKAPBAHAN[[NAMA BAHAN]:[MODAL SATUAN]],4,FALSE) -> 140 | I17: 1 | J17: =H17*I17 -> 140 | M17: 16 | N17: KRESEK 15 CM | O17: =VLOOKUP(TBLBURGERDAGINGSAPI[NAMA BAHAN],[2]!TBLREKAPBAHAN[[NAMA BAHAN]:[MODAL SATUAN]],2,FALSE) -> 7000 | P17: =VLOOKUP(TBLBURGERDAGINGSAPI[NAMA BAHAN],[2]!TBLREKAPBAHAN[[NAMA BAHAN]:[MODAL SATUAN]],3,FALSE) -> 50 | Q17: BIJI | R17: =VLOOKUP(TBLBURGERDAGINGSAPI[NAMA BAHAN],[2]!TBLREKAPBAHAN[[NAMA BAHAN]:[MODAL SATUAN]],4,FALSE) -> 140 | S17: =VLOOKUP(TBLBURGERDAGINGSAPI[NAMA BAHAN],[2]!TBLREKAPBAHAN[[NAMA BAHAN]:[MODAL SATUAN]],4,FALSE) -> 140 | T17: 1 | U17: =S17*T17 -> 140 | V17: 1 | W17: =TBLBURGERDAGINGSAPI[[#This Row],[MODAL SATUAN]]*TBLBURGERDAGINGSAPI[[#This Row],[DOUBLE]] -> 140 | AA17: 16 | AB17: KRESEK 15 CM | AC17: =VLOOKUP(TBLBURGERDAGINGSAPITANPASAYUR[NAMA BAHAN],[2]!TBLREKAPBAHAN[[NAMA BAHAN]:[MODAL SATUAN]],2,FALSE) -> 7000 | AD17: =VLOOKUP(TBLBURGERDAGINGSAPITANPASAYUR[NAMA BAHAN],[2]!TBLREKAPBAHAN[[NAMA BAHAN]:[MODAL SATUAN]],3,FALSE) -> 50 | AE17: BIJI | AF17: =VLOOKUP(TBLBURGERDAGINGSAPITANPASAYUR[NAMA BAHAN],[2]!TBLREKAPBAHAN[[NAMA BAHAN]:[MODAL SATUAN]],4,FALSE) -> 140 | AG17: =VLOOKUP(TBLBURGERDAGINGSAPITANPASAYUR[NAMA BAHAN],[2]!TBLREKAPBAHAN[[NAMA BAHAN]:[MODAL SATUAN]],4,FALSE) -> 140 | AH17: 1 | AI17: =AG17*AH17 -> 140 | AL17: 16 | AM17: KRESEK 15 CM | AN17: =VLOOKUP(TBLBURGERNUGGETAYAMTANPASAYUR[NAMA BAHAN],[2]!TBLREKAPBAHAN[[NAMA BAHAN]:[MODAL SATUAN]],2,FALSE) -> 7000 | AO17: =VLOOKUP(TBLBURGERNUGGETAYAMTANPASAYUR[NAMA BAHAN],[2]!TBLREKAPBAHAN[[NAMA BAHAN]:[MODAL SATUAN]],3,FALSE) -> 50 | AP17: BIJI | AQ17: =VLOOKUP(TBLBURGERNUGGETAYAMTANPASAYUR[NAMA BAHAN],[2]!TBLREKAPBAHAN[[NAMA BAHAN]:[MODAL SATUAN]],4,FALSE) -> 140 | AR17: =VLOOKUP(TBLBURGERNUGGETAYAMTANPASAYUR[NAMA BAHAN],[2]!TBLREKAPBAHAN[[NAMA BAHAN]:[MODAL SATUAN]],4,FALSE) -> 140 | AS17: 1 | AT17: =AR17*AS17 -> 140
C18: MODAL | J18: =SUM(J2:J17) -> 11679.556 | L18: MODAL | U18: =SUM(U2:U17) -> 11837.889 | W18: =SUM(W2:W17) -> 15662.889 | Z18: MODAL | AI18: =SUM(AI2:AI17) -> 11049 | AK18: MODAL | AT18: =SUM(AT2:AT17) -> 12224

Sheet ROCAS
A1: NAMA PRODUK | B1: KODE BAHAN | C1: NAMA BAHAN | D1: HARGA KULAK | E1: ISI | F1: SATUAN | G1: HARGA KULAK SATUAN | H1: MODAL SATUAN | I1: KEB | J1: JUMLAH MODAL
A2: ROCAS MEDIUM | B2: 1 | C2: SAOS TOMAT GRAM | D2: =VLOOKUP(TBLROCASMEDIUM[NAMA BAHAN],[2]!TBLREKAPBAHAN[[NAMA BAHAN]:[MODAL SATUAN]],2,FALSE) -> 20000 | E2: =VLOOKUP(TBLROCASMEDIUM[NAMA BAHAN],[2]!TBLREKAPBAHAN[[NAMA BAHAN]:[MODAL SATUAN]],3,FALSE) -> 1000 | F2: GRAM | G2: =VLOOKUP(TBLROCASMEDIUM[NAMA BAHAN],[2]!TBLREKAPBAHAN[[NAMA BAHAN]:[MODAL SATUAN]],4,FALSE) -> 20 | H2: =VLOOKUP(TBLROCASMEDIUM[NAMA BAHAN],[2]!TBLREKAPBAHAN[[NAMA BAHAN]:[MODAL SATUAN]],4,FALSE) -> 20 | I2: 10 | J2: =H2*I2 -> 200
B3: 2 | C3: SAOS SAMBAL GRAM | D3: =VLOOKUP(TBLROCASMEDIUM[NAMA BAHAN],[2]!TBLREKAPBAHAN[[NAMA BAHAN]:[MODAL SATUAN]],2,FALSE) -> 18000 | E3: =VLOOKUP(TBLROCASMEDIUM[NAMA BAHAN],[2]!TBLREKAPBAHAN[[NAMA BAHAN]:[MODAL SATUAN]],3,FALSE) -> 1000 | F3: GRAM | G3: =VLOOKUP(TBLROCASMEDIUM[NAMA BAHAN],[2]!TBLREKAPBAHAN[[NAMA BAHAN]:[MODAL SATUAN]],4,FALSE) -> 18 | H3: =VLOOKUP(TBLROCASMEDIUM[NAMA BAHAN],[2]!TBLREKAPBAHAN[[NAMA BAHAN]:[MODAL SATUAN]],4,FALSE) -> 18 | I3: 0 | J3: =H3*I3 -> 0
B4: 3 | C4: SAOS BBQ GRAM | D4: =VLOOKUP(TBLROCASMEDIUM[NAMA BAHAN],[2]!TBLREKAPBAHAN[[NAMA BAHAN]:[MODAL SATUAN]],2,FALSE) -> 12000 | E4: =VLOOKUP(TBLROCASMEDIUM[NAMA BAHAN],[2]!TBLREKAPBAHAN[[NAMA BAHAN]:[MODAL SATUAN]],3,FALSE) -> 250 | F4: GRAM | G4: =VLOOKUP(TBLROCASMEDIUM[NAMA BAHAN],[2]!TBLREKAPBAHAN[[NAMA BAHAN]:[MODAL SATUAN]],4,FALSE) -> 48 | H4: =VLOOKUP(TBLROCASMEDIUM[NAMA BAHAN],[2]!TBLREKAPBAHAN[[NAMA BAHAN]:[MODAL SATUAN]],4,FALSE) -> 48 | I4: 5 | J4: =H4*I4 -> 240
B5: 4 | C5: MAYONAIS GRAM | D5: =VLOOKUP(TBLROCASMEDIUM[NAMA BAHAN],[2]!TBLREKAPBAHAN[[NAMA BAHAN]:[MODAL SATUAN]],2,FALSE) -> 50000 | E5: =VLOOKUP(TBLROCASMEDIUM[NAMA BAHAN],[2]!TBLREKAPBAHAN[[NAMA BAHAN]:[MODAL SATUAN]],3,FALSE) -> 1000 | F5: GRAM | G5: =VLOOKUP(TBLROCASMEDIUM[NAMA BAHAN],[2]!TBLREKAPBAHAN[[NAMA BAHAN]:[MODAL SATUAN]],4,FALSE) -> 50 | H5: =VLOOKUP(TBLROCASMEDIUM[NAMA BAHAN],[2]!TBLREKAPBAHAN[[NAMA BAHAN]:[MODAL SATUAN]],4,FALSE) -> 50 | I5: 10 | J5: =H5*I5 -> 500
B6: 5 | C6: SAOS SAMBAL SACHET | D6: =VLOOKUP(TBLROCASMEDIUM[NAMA BAHAN],[2]!TBLREKAPBAHAN[[NAMA BAHAN]:[MODAL SATUAN]],2,FALSE) -> 8000 | E6: =VLOOKUP(TBLROCASMEDIUM[NAMA BAHAN],[2]!TBLREKAPBAHAN[[NAMA BAHAN]:[MODAL SATUAN]],3,FALSE) -> 24 | F6: SACHET | G6: =VLOOKUP(TBLROCASMEDIUM[NAMA BAHAN],[2]!TBLREKAPBAHAN[[NAMA BAHAN]:[MODAL SATUAN]],4,FALSE) -> 333.33333 | H6: =VLOOKUP(TBLROCASMEDIUM[NAMA BAHAN],[2]!TBLREKAPBAHAN[[NAMA BAHAN]:[MODAL SATUAN]],4,FALSE) -> 333.33333 | I6: 1 | J6: =H6*I6 -> 333.33333
B7: 6 | C7: SOSIZ BATANG | D7: =VLOOKUP(TBLROCASMEDIUM[NAMA BAHAN],[2]!TBLREKAPBAHAN[[NAMA BAHAN]:[MODAL SATUAN]],2,FALSE) -> 35000 | E7: =VLOOKUP(TBLROCASMEDIUM[NAMA BAHAN],[2]!TBLREKAPBAHAN[[NAMA BAHAN]:[MODAL SATUAN]],3,FALSE) -> 38 | F7: BATANG | G7: =VLOOKUP(TBLROCASMEDIUM[NAMA BAHAN],[2]!TBLREKAPBAHAN[[NAMA BAHAN]:[MODAL SATUAN]],4,FALSE) -> 921.05263 | H7: =VLOOKUP(TBLROCASMEDIUM[NAMA BAHAN],[2]!TBLREKAPBAHAN[[NAMA BAHAN]:[MODAL SATUAN]],4,FALSE) -> 921.05263 | I7: 1 | J7: =H7*I7 -> 921.05263
B8: 7 | C8: AYAM SUWIR | D8: =VLOOKUP(TBLROCASMEDIUM[NAMA BAHAN],[2]!TBLREKAPBAHAN[[NAMA BAHAN]:[MODAL SATUAN]],2,FALSE) -> 45000 | E8: =VLOOKUP(TBLROCASMEDIUM[NAMA BAHAN],[2]!TBLREKAPBAHAN[[NAMA BAHAN]:[MODAL SATUAN]],3,FALSE) -> 400 | F8: GRAM | G8: =VLOOKUP(TBLROCASMEDIUM[NAMA BAHAN],[2]!TBLREKAPBAHAN[[NAMA BAHAN]:[MODAL SATUAN]],4,FALSE) -> 112.5 | H8: =VLOOKUP(TBLROCASMEDIUM[NAMA BAHAN],[2]!TBLREKAPBAHAN[[NAMA BAHAN]:[MODAL SATUAN]],4,FALSE) -> 112.5 | I8: 12 | J8: =H8*I8 -> 1350
B9: 8 | C9: ROTI ROCAS MEDIUM | D9: =VLOOKUP(TBLROCASMEDIUM[NAMA BAHAN],[2]!TBLREKAPBAHAN[[NAMA BAHAN]:[MODAL SATUAN]],2,FALSE) -> 15000 | E9: =VLOOKUP(TBLROCASMEDIUM[NAMA BAHAN],[2]!TBLREKAPBAHAN[[NAMA BAHAN]:[MODAL SATUAN]],3,FALSE) -> 6 | F9: BIJI | G9: =VLOOKUP(TBLROCASMEDIUM[NAMA BAHAN],[2]!TBLREKAPBAHAN[[NAMA BAHAN]:[MODAL SATUAN]],4,FALSE) -> 2500 | H9: =VLOOKUP(TBLROCASMEDIUM[NAMA BAHAN],[2]!TBLREKAPBAHAN[[NAMA BAHAN]:[MODAL SATUAN]],4,FALSE) -> 2500 | I9: 1 | J9: =H9*I9 -> 2500
B10: 9 | C10: SLADA | D10: =VLOOKUP(TBLROCASMEDIUM[NAMA BAHAN],[2]!TBLREKAPBAHAN[[NAMA BAHAN]:[MODAL SATUAN]],2,FALSE) -> 60000 | E10: =VLOOKUP(TBLROCASMEDIUM[NAMA BAHAN],[2]!TBLREKAPBAHAN[[NAMA BAHAN]:[MODAL SATUAN]],3,FALSE) -> 50 | F10: PORSI | G10: =VLOOKUP(TBLROCASMEDIUM[NAMA BAHAN],[2]!TBLREKAPBAHAN[[NAMA BAHAN]:[MODAL SATUAN]],4,FALSE) -> 1200 | H10: =VLOOKUP(TBLROCASMEDIUM[NAMA BAHAN],[2]!TBLREKAPBAHAN[[NAMA BAHAN]:[MODAL SATUAN]],4,FALSE) -> 1200 | I10: 0.5 | J10: =H10*I10 -> 600
B11: 10 | C11: MENTEGA | D11: =VLOOKUP(TBLROCASMEDIUM[NAMA BAHAN],[2]!TBLREKAPBAHAN[[NAMA BAHAN]:[MODAL SATUAN]],2,FALSE) -> 35000 | E11: =VLOOKUP(TBLROCASMEDIUM[NAMA BAHAN],[2]!TBLREKAPBAHAN[[NAMA BAHAN]:[MODAL SATUAN]],3,FALSE) -> 1000 | F11: GRAM | G11: =VLOOKUP(TBLROCASMEDIUM[NAMA BAHAN],[2]!TBLREKAPBAHAN[[NAMA BAHAN]:[MODAL SATUAN]],4,FALSE) -> 35 | H11: =VLOOKUP(TBLROCASMEDIUM[NAMA BAHAN],[2]!TBLREKAPBAHAN[[NAMA BAHAN]:[MODAL SATUAN]],4,FALSE) -> 35 | I11: 3 | J11: =H11*I11 -> 105
B12: 11 | C12: GAS ELPIJI | D12: =VLOOKUP(TBLROCASMEDIUM[NAMA BAHAN],[2]!TBLREKAPBAHAN[[NAMA BAHAN]:[MODAL SATUAN]],2,FALSE) -> 23000 | E12: =VLOOKUP(TBLROCASMEDIUM[NAMA BAHAN],[2]!TBLREKAPBAHAN[[NAMA BAHAN]:[MODAL SATUAN]],3,FALSE) -> 3000 | F12: GRAM | G12: =VLOOKUP(TBLROCASMEDIUM[NAMA BAHAN],[2]!TBLREKAPBAHAN[[NAMA BAHAN]:[MODAL SATUAN]],4,FALSE) -> 7.6666667 | H12: =VLOOKUP(TBLROCASMEDIUM[NAMA BAHAN],[2]!TBLREKAPBAHAN[[NAMA BAHAN]:[MODAL SATUAN]],4,FALSE) -> 7.6666667 | I12: 5 | J12: =H12*I12 -> 38.333333
B13: 12 | C13: MIKA ROCAS MEDIUM | D13: =VLOOKUP(TBLROCASMEDIUM[NAMA BAHAN],[2]!TBLREKAPBAHAN[[NAMA BAHAN]:[MODAL SATUAN]],2,FALSE) -> 40000 | E13: =VLOOKUP(TBLROCASMEDIUM[NAMA BAHAN],[2]!TBLREKAPBAHAN[[NAMA BAHAN]:[MODAL SATUAN]],3,FALSE) -> 100 | F13: LEMBAR | G13: =VLOOKUP(TBLROCASMEDIUM[NAMA BAHAN],[2]!TBLREKAPBAHAN[[NAMA BAHAN]:[MODAL SATUAN]],4,FALSE) -> 400 | H13: =VLOOKUP(TBLROCASMEDIUM[NAMA BAHAN],[2]!TBLREKAPBAHAN[[NAMA BAHAN]:[MODAL SATUAN]],4,FALSE) -> 400 | I13: 0 | J13: =H13*I13 -> 0
B14: 13 | C14: KRESEK 20 CM | D14: =VLOOKUP(TBLROCASMEDIUM[NAMA BAHAN],[2]!TBLREKAPBAHAN[[NAMA BAHAN]:[MODAL SATUAN]],2,FALSE) -> 8500 | E14: =VLOOKUP(TBLROCASMEDIUM[NAMA BAHAN],[2]!TBLREKAPBAHAN[[NAMA BAHAN]:[MODAL SATUAN]],3,FALSE) -> 50 | F14: BIJI | G14: =VLOOKUP(TBLROCASMEDIUM[NAMA BAHAN],[2]!TBLREKAPBAHAN[[NAMA BAHAN]:[MODAL SATUAN]],4,FALSE) -> 170 | H14: =VLOOKUP(TBLROCASMEDIUM[NAMA BAHAN],[2]!TBLREKAPBAHAN[[NAMA BAHAN]:[MODAL SATUAN]],4,FALSE) -> 170 | I14: 0 | J14: =H14*I14 -> 0
A15: MODAL | J15: =SUM(J2:J14) -> 6787.7193
A20: NAMA PRODUK | B20: KODE BAHAN | C20: NAMA BAHAN | D20: HARGA KULAK | E20: ISI | F20: SATUAN | G20: HARGA KULAK SATUAN | H20: MODAL SATUAN | I20: KEB | J20: JUMLAH MODAL
A21: ROCAS SAPI | B21: 1 | C21: SAOS TOMAT GRAM | D21: =VLOOKUP(TBLROCASMEDIUMSAPI[NAMA BAHAN],[2]!TBLREKAPBAHAN[[NAMA BAHAN]:[MODAL SATUAN]],2,FALSE) -> 20000 | E21: =VLOOKUP(TBLROCASMEDIUMSAPI[NAMA BAHAN],[2]!TBLREKAPBAHAN[[NAMA BAHAN]:[MODAL SATUAN]],3,FALSE) -> 1000 | F21: GRAM | G21: =VLOOKUP(TBLROCASMEDIUMSAPI[NAMA BAHAN],[2]!TBLREKAPBAHAN[[NAMA BAHAN]:[MODAL SATUAN]],4,FALSE) -> 20 | H21: =VLOOKUP(TBLROCASMEDIUMSAPI[NAMA BAHAN],[2]!TBLREKAPBAHAN[[NAMA BAHAN]:[MODAL SATUAN]],4,FALSE) -> 20 | I21: 10 | J21: =H21*I21 -> 200
B22: 2 | C22: SAOS SAMBAL GRAM | D22: =VLOOKUP(TBLROCASMEDIUMSAPI[NAMA BAHAN],[2]!TBLREKAPBAHAN[[NAMA BAHAN]:[MODAL SATUAN]],2,FALSE) -> 18000 | E22: =VLOOKUP(TBLROCASMEDIUMSAPI[NAMA BAHAN],[2]!TBLREKAPBAHAN[[NAMA BAHAN]:[MODAL SATUAN]],3,FALSE) -> 1000 | F22: GRAM | G22: =VLOOKUP(TBLROCASMEDIUMSAPI[NAMA BAHAN],[2]!TBLREKAPBAHAN[[NAMA BAHAN]:[MODAL SATUAN]],4,FALSE) -> 18 | H22: =VLOOKUP(TBLROCASMEDIUMSAPI[NAMA BAHAN],[2]!TBLREKAPBAHAN[[NAMA BAHAN]:[MODAL SATUAN]],4,FALSE) -> 18 | I22: 0 | J22: =H22*I22 -> 0
B23: 3 | C23: SAOS BBQ GRAM | D23: =VLOOKUP(TBLROCASMEDIUMSAPI[NAMA BAHAN],[2]!TBLREKAPBAHAN[[NAMA BAHAN]:[MODAL SATUAN]],2,FALSE) -> 12000 | E23: =VLOOKUP(TBLROCASMEDIUMSAPI[NAMA BAHAN],[2]!TBLREKAPBAHAN[[NAMA BAHAN]:[MODAL SATUAN]],3,FALSE) -> 250 | F23: GRAM | G23: =VLOOKUP(TBLROCASMEDIUMSAPI[NAMA BAHAN],[2]!TBLREKAPBAHAN[[NAMA BAHAN]:[MODAL SATUAN]],4,FALSE) -> 48 | H23: =VLOOKUP(TBLROCASMEDIUMSAPI[NAMA BAHAN],[2]!TBLREKAPBAHAN[[NAMA BAHAN]:[MODAL SATUAN]],4,FALSE) -> 48 | I23: 5 | J23: =H23*I23 -> 240
B24: 4 | C24: MAYONAIS GRAM | D24: =VLOOKUP(TBLROCASMEDIUMSAPI[NAMA BAHAN],[2]!TBLREKAPBAHAN[[NAMA BAHAN]:[MODAL SATUAN]],2,FALSE) -> 50000 | E24: =VLOOKUP(TBLROCASMEDIUMSAPI[NAMA BAHAN],[2]!TBLREKAPBAHAN[[NAMA BAHAN]:[MODAL SATUAN]],3,FALSE) -> 1000 | F24: GRAM | G24: =VLOOKUP(TBLROCASMEDIUMSAPI[NAMA BAHAN],[2]!TBLREKAPBAHAN[[NAMA BAHAN]:[MODAL SATUAN]],4,FALSE) -> 50 | H24: =VLOOKUP(TBLROCASMEDIUMSAPI[NAMA BAHAN],[2]!TBLREKAPBAHAN[[NAMA BAHAN]:[MODAL SATUAN]],4,FALSE) -> 50 | I24: 10 | J24: =H24*I24 -> 500
B25: 5 | C25: SAOS SAMBAL SACHET | D25: =VLOOKUP(TBLROCASMEDIUMSAPI[NAMA BAHAN],[2]!TBLREKAPBAHAN[[NAMA BAHAN]:[MODAL SATUAN]],2,FALSE) -> 8000 | E25: =VLOOKUP(TBLROCASMEDIUMSAPI[NAMA BAHAN],[2]!TBLREKAPBAHAN[[NAMA BAHAN]:[MODAL SATUAN]],3,FALSE) -> 24 | F25: SACHET | G25: =VLOOKUP(TBLROCASMEDIUMSAPI[NAMA BAHAN],[2]!TBLREKAPBAHAN[[NAMA BAHAN]:[MODAL SATUAN]],4,FALSE) -> 333.33333 | H25: =VLOOKUP(TBLROCASMEDIUMSAPI[NAMA BAHAN],[2]!TBLREKAPBAHAN[[NAMA BAHAN]:[MODAL SATUAN]],4,FALSE) -> 333.33333 | I25: 1 | J25: =H25*I25 -> 333.33333
B26: 6 | C26: AYAM SUWIR | D26: =VLOOKUP(TBLROCASMEDIUMSAPI[NAMA BAHAN],[2]!TBLREKAPBAHAN[[NAMA BAHAN]:[MODAL SATUAN]],2,FALSE) -> 45000 | E26: =VLOOKUP(TBLROCASMEDIUMSAPI[NAMA BAHAN],[2]!TBLREKAPBAHAN[[NAMA BAHAN]:[MODAL SATUAN]],3,FALSE) -> 400 | F26: BATANG | G26: =VLOOKUP(TBLROCASMEDIUMSAPI[NAMA BAHAN],[2]!TBLREKAPBAHAN[[NAMA BAHAN]:[MODAL SATUAN]],4,FALSE) -> 112.5 | H26: =VLOOKUP(TBLROCASMEDIUMSAPI[NAMA BAHAN],[2]!TBLREKAPBAHAN[[NAMA BAHAN]:[MODAL SATUAN]],4,FALSE) -> 112.5 | I26: 8 | J26: =H26*I26 -> 900
B27: 7 | C27: DAGING SAPI | D27: =VLOOKUP(TBLROCASMEDIUMSAPI[NAMA BAHAN],[2]!TBLREKAPBAHAN[[NAMA BAHAN]:[MODAL SATUAN]],2,FALSE) -> 85000 | E27: =VLOOKUP(TBLROCASMEDIUMSAPI[NAMA BAHAN],[2]!TBLREKAPBAHAN[[NAMA BAHAN]:[MODAL SATUAN]],3,FALSE) -> 1000 | F27: GRAM | G27: =VLOOKUP(TBLROCASMEDIUMSAPI[NAMA BAHAN],[2]!TBLREKAPBAHAN[[NAMA BAHAN]:[MODAL SATUAN]],4,FALSE) -> 85 | H27: =VLOOKUP(TBLROCASMEDIUMSAPI[NAMA BAHAN],[2]!TBLREKAPBAHAN[[NAMA BAHAN]:[MODAL SATUAN]],4,FALSE) -> 85 | I27: 20 | J27: =H27*I27 -> 1700
B28: 8 | C28: ROTI ROCAS MEDIUM | D28: =VLOOKUP(TBLROCASMEDIUMSAPI[NAMA BAHAN],[2]!TBLREKAPBAHAN[[NAMA BAHAN]:[MODAL SATUAN]],2,FALSE) -> 15000 | E28: =VLOOKUP(TBLROCASMEDIUMSAPI[NAMA BAHAN],[2]!TBLREKAPBAHAN[[NAMA BAHAN]:[MODAL SATUAN]],3,FALSE) -> 6 | F28: BIJI | G28: =VLOOKUP(TBLROCASMEDIUMSAPI[NAMA BAHAN],[2]!TBLREKAPBAHAN[[NAMA BAHAN]:[MODAL SATUAN]],4,FALSE) -> 2500 | H28: =VLOOKUP(TBLROCASMEDIUMSAPI[NAMA BAHAN],[2]!TBLREKAPBAHAN[[NAMA BAHAN]:[MODAL SATUAN]],4,FALSE) -> 2500 | I28: 1 | J28: =H28*I28 -> 2500
B29: 9 | C29: SLADA | D29: =VLOOKUP(TBLROCASMEDIUMSAPI[NAMA BAHAN],[2]!TBLREKAPBAHAN[[NAMA BAHAN]:[MODAL SATUAN]],2,FALSE) -> 60000 | E29: =VLOOKUP(TBLROCASMEDIUMSAPI[NAMA BAHAN],[2]!TBLREKAPBAHAN[[NAMA BAHAN]:[MODAL SATUAN]],3,FALSE) -> 50 | F29: PORSI | G29: =VLOOKUP(TBLROCASMEDIUMSAPI[NAMA BAHAN],[2]!TBLREKAPBAHAN[[NAMA BAHAN]:[MODAL SATUAN]],4,FALSE) -> 1200 | H29: =VLOOKUP(TBLROCASMEDIUMSAPI[NAMA BAHAN],[2]!TBLREKAPBAHAN[[NAMA BAHAN]:[MODAL SATUAN]],4,FALSE) -> 1200 | I29: 0.5 | J29: =H29*I29 -> 600
B30: 10 | C30: MENTEGA | D30: =VLOOKUP(TBLROCASMEDIUMSAPI[NAMA BAHAN],[2]!TBLREKAPBAHAN[[NAMA BAHAN]:[MODAL SATUAN]],2,FALSE) -> 35000 | E30: =VLOOKUP(TBLROCASMEDIUMSAPI[NAMA BAHAN],[2]!TBLREKAPBAHAN[[NAMA BAHAN]:[MODAL SATUAN]],3,FALSE) -> 1000 | F30: GRAM | G30: =VLOOKUP(TBLROCASMEDIUMSAPI[NAMA BAHAN],[2]!TBLREKAPBAHAN[[NAMA BAHAN]:[MODAL SATUAN]],4,FALSE) -> 35 | H30: =VLOOKUP(TBLROCASMEDIUMSAPI[NAMA BAHAN],[2]!TBLREKAPBAHAN[[NAMA BAHAN]:[MODAL SATUAN]],4,FALSE) -> 35 | I30: 3 | J30: =H30*I30 -> 105
