Workbook
Name CUSTOMER: TBLDATACUSTOMER[NAMA CUSTOMER]
Name CUSTOMER: TBLDATACUSTOMER[NAMA CUSTOMER]
Name CUSTOMER: TBLDATACUSTOMER[NAMA CUSTOMER]
Name KODE: TBLBAHANKELUAR[TAHUN]
Name KODEPRODUK: [1]!TBLREKAPBAHAN[KODE PRODUK]
Name MITRA: TBLDATAMITRAEPC[NAMA MITRA]
Name MITRA: TBLDATAMITRAEPC[NAMA MITRA]
Name MITRA: TBLDATAMITRAEPC[NAMA MITRA]
Name NOMORPRODUK: TBLBAHANKELUAR[TAHUN]
Name ZAMBI_AYAM: [2]ZAMBI!#REF!

Sheet DATA MITRA
A1: DATA MITRA EPC
A4: KODE MITRA | B4: NAMA MITRA | C4: NAMA PEREKRUT | D4: NO HP/WA | E4: Column1
A5: =LEFT(TBLDATAMITRAEPC[[#This Row],[NAMA MITRA]],1)&IFERROR(MID(TBLDATAMITRAEPC[[#This Row],[NAMA MITRA]],FIND(" ",TBLDATAMITRAEPC[[#This Row],[NAMA MITRA]],1)+1,1),"")&IFERROR(MID(TBLDATAMITRAEPC[[#This Row],[NAMA MITRA]],FIND(" ",TBLDATAMITRAEPC[[#This Row],[NAMA MITRA]],FIND(" ",TBLDATAMITRAEPC[[#This Row],[NAMA MITRA]],1)+1)+1,1),"")&IFERROR(MID(TBLDATAMITRAEPC[[#This Row],[NAMA MITRA]],FIND(" ",TBLDATAMITRAEPC[[#This Row],[NAMA MITRA]],FIND(" ",TBLDATAMITRAEPC[[#This Row],[NAMA MITRA]],FIND(" ",TBLDATAMITRAEPC[[#This Row],[NAMA MITRA]],1)+1)+1)+1,1),"")&IFERROR(MID(TBLDATAMITRAEPC[[#This Row],[NAMA MITRA]],FIND(" ",TBLDATAMITRAEPC[[#This Row],[NAMA MITRA]],FIND(" ",TBLDATAMITRAEPC[[#This Row],[NAMA MITRA]],FIND(" ",TBLDATAMITRAEPC[[#This Row],[NAMA MITRA]],FIND(" ",TBLDATAMITRAEPC[[#This Row],[NAMA MITRA]],1)+1)+1)+1)+1,1),"") -> A | B5: ANGEL | C5: NURUL HIDAYATU SAMSIAH
A6: =LEFT(TBLDATAMITRAEPC[[#This Row],[NAMA MITRA]],1)&IFERROR(MID(TBLDATAMITRAEPC[[#This Row],[NAMA MITRA]],FIND(" ",TBLDATAMITRAEPC[[#This Row],[NAMA MITRA]],1)+1,1),"")&IFERROR(MID(TBLDATAMITRAEPC[[#This Row],[NAMA MITRA]],FIND(" ",TBLDATAMITRAEPC[[#This Row],[NAMA MITRA]],FIND(" ",TBLDATAMITRAEPC[[#This Row],[NAMA MITRA]],1)+1)+1,1),"")&IFERROR(MID(TBLDATAMITRAEPC[[#This Row],[NAMA MITRA]],FIND(" ",TBLDATAMITRAEPC[[#This Row],[NAMA MITRA]],FIND(" ",TBLDATAMITRAEPC[[#This Row],[NAMA MITRA]],FIND(" ",TBLDATAMITRAEPC[[#This Row],[NAMA MITRA]],1)+1)+1)+1,1),"")&IFERROR(MID(TBLDATAMITRAEPC[[#This Row],[NAMA MITRA]],FIND(" ",TBLDATAMITRAEPC[[#This Row],[NAMA MITRA]],FIND(" ",TBLDATAMITRAEPC[[#This Row],[NAMA MITRA]],FIND(" ",TBLDATAMITRAEPC[[#This Row],[NAMA MITRA]],FIND(" ",TBLDATAMITRAEPC[[#This Row],[NAMA MITRA]],1)+1)+1)+1)+1,1),"") -> A | B6: ANI | C6: NURUL HIDAYATU SAMSIAH
A7: =LEFT(TBLDATAMITRAEPC[[#This Row],[NAMA MITRA]],1)&IFERROR(MID(TBLDATAMITRAEPC[[#This Row],[NAMA MITRA]],FIND(" ",TBLDATAMITRAEPC[[#This Row],[NAMA MITRA]],1)+1,1),"")&IFERROR(MID(TBLDATAMITRAEPC[[#This Row],[NAMA MITRA]],FIND(" ",TBLDATAMITRAEPC[[#This Row],[NAMA MITRA]],FIND(" ",TBLDATAMITRAEPC[[#This Row],[NAMA MITRA]],1)+1)+1,1),"")&IFERROR(MID(TBLDATAMITRAEPC[[#This Row],[NAMA MITRA]],FIND(" ",TBLDATAMITRAEPC[[#This Row],[NAMA MITRA]],FIND(" ",TBLDATAMITRAEPC[[#This Row],[NAMA MITRA]],FIND(" ",TBLDATAMITRAEPC[[#This Row],[NAMA MITRA]],1)+1)+1)+1,1),"")&IFERROR(MID(TBLDATAMITRAEPC[[#This Row],[NAMA MITRA]],FIND(" ",TBLDATAMITRAEPC[[#This Row],[NAMA MITRA]],FIND(" ",TBLDATAMITRAEPC[[#This Row],[NAMA MITRA]],FIND(" ",TBLDATAMITRAEPC[[#This Row],[NAMA MITRA]],FIND(" ",TBLDATAMITRAEPC[[#This Row],[NAMA MITRA]],1)+1)+1)+1)+1,1),"") -> CG | B7: CAHYA GALLERY | C7: CAHYA GALLERY
A8: =LEFT(TBLDATAMITRAEPC[[#This Row],[NAMA MITRA]],1)&IFERROR(MID(TBLDATAMITRAEPC[[#This Row],[NAMA MITRA]],FIND(" ",TBLDATAMITRAEPC[[#This Row],[NAMA MITRA]],1)+1,1),"")&IFERROR(MID(TBLDATAMITRAEPC[[#This Row],[NAMA MITRA]],FIND(" ",TBLDATAMITRAEPC[[#This Row],[NAMA MITRA]],FIND(" ",TBLDATAMITRAEPC[[#This Row],[NAMA MITRA]],1)+1)+1,1),"")&IFERROR(MID(TBLDATAMITRAEPC[[#This Row],[NAMA MITRA]],FIND(" ",TBLDATAMITRAEPC[[#This Row],[NAMA MITRA]],FIND(" ",TBLDATAMITRAEPC[[#This Row],[NAMA MITRA]],FIND(" ",TBLDATAMITRAEPC[[#This Row],[NAMA MITRA]],1)+1)+1)+1,1),"")&IFERROR(MID(TBLDATAMITRAEPC[[#This Row],[NAMA MITRA]],FIND(" ",TBLDATAMITRAEPC[[#This Row],[NAMA MITRA]],FIND(" ",TBLDATAMITRAEPC[[#This Row],[NAMA MITRA]],FIND(" ",TBLDATAMITRAEPC[[#This Row],[NAMA MITRA]],FIND(" ",TBLDATAMITRAEPC[[#This Row],[NAMA MITRA]],1)+1)+1)+1)+1,1),"") -> D | B8: DANI | C8: NURUL HIDAYATU SAMSIAH
A9: =LEFT(TBLDATAMITRAEPC[[#This Row],[NAMA MITRA]],1)&IFERROR(MID(TBLDATAMITRAEPC[[#This Row],[NAMA MITRA]],FIND(" ",TBLDATAMITRAEPC[[#This Row],[NAMA MITRA]],1)+1,1),"")&IFERROR(MID(TBLDATAMITRAEPC[[#This Row],[NAMA MITRA]],FIND(" ",TBLDATAMITRAEPC[[#This Row],[NAMA MITRA]],FIND(" ",TBLDATAMITRAEPC[[#This Row],[NAMA MITRA]],1)+1)+1,1),"")&IFERROR(MID(TBLDATAMITRAEPC[[#This Row],[NAMA MITRA]],FIND(" ",TBLDATAMITRAEPC[[#This Row],[NAMA MITRA]],FIND(" ",TBLDATAMITRAEPC[[#This Row],[NAMA MITRA]],FIND(" ",TBLDATAMITRAEPC[[#This Row],[NAMA MITRA]],1)+1)+1)+1,1),"")&IFERROR(MID(TBLDATAMITRAEPC[[#This Row],[NAMA MITRA]],FIND(" ",TBLDATAMITRAEPC[[#This Row],[NAMA MITRA]],FIND(" ",TBLDATAMITRAEPC[[#This Row],[NAMA MITRA]],FIND(" ",TBLDATAMITRAEPC[[#This Row],[NAMA MITRA]],FIND(" ",TBLDATAMITRAEPC[[#This Row],[NAMA MITRA]],1)+1)+1)+1)+1,1),"") -> D | B9: DENI | C9: NURUL HIDAYATU SAMSIAH
A10: =LEFT(TBLDATAMITRAEPC[[#This Row],[NAMA MITRA]],1)&IFERROR(MID(TBLDATAMITRAEPC[[#This Row],[NAMA MITRA]],FIND(" ",TBLDATAMITRAEPC[[#This Row],[NAMA MITRA]],1)+1,1),"")&IFERROR(MID(TBLDATAMITRAEPC[[#This Row],[NAMA MITRA]],FIND(" ",TBLDATAMITRAEPC[[#This Row],[NAMA MITRA]],FIND(" ",TBLDATAMITRAEPC[[#This Row],[NAMA MITRA]],1)+1)+1,1),"")&IFERROR(MID(TBLDATAMITRAEPC[[#This Row],[NAMA MITRA]],FIND(" ",TBLDATAMITRAEPC[[#This Row],[NAMA MITRA]],FIND(" ",TBLDATAMITRAEPC[[#This Row],[NAMA MITRA]],FIND(" ",TBLDATAMITRAEPC[[#This Row],[NAMA MITRA]],1)+1)+1)+1,1),"")&IFERROR(MID(TBLDATAMITRAEPC[[#This Row],[NAMA MITRA]],FIND(" ",TBLDATAMITRAEPC[[#This Row],[NAMA MITRA]],FIND(" ",TBLDATAMITRAEPC[[#This Row],[NAMA MITRA]],FIND(" ",TBLDATAMITRAEPC[[#This Row],[NAMA MITRA]],FIND(" ",TBLDATAMITRAEPC[[#This Row],[NAMA MITRA]],1)+1)+1)+1)+1,1),"") -> DZ | B10: DEWI ZAKIYAH | C10: NURUL HIDAYATU SAMSIAH
A11: =LEFT(TBLDATAMITRAEPC[[#This Row],[NAMA MITRA]],1)&IFERROR(MID(TBLDATAMITRAEPC[[#This Row],[NAMA MITRA]],FIND(" ",TBLDATAMITRAEPC[[#This Row],[NAMA MITRA]],1)+1,1),"")&IFERROR(MID(TBLDATAMITRAEPC[[#This Row],[NAMA MITRA]],FIND(" ",TBLDATAMITRAEPC[[#This Row],[NAMA MITRA]],FIND(" ",TBLDATAMITRAEPC[[#This Row],[NAMA MITRA]],1)+1)+1,1),"")&IFERROR(MID(TBLDATAMITRAEPC[[#This Row],[NAMA MITRA]],FIND(" ",TBLDATAMITRAEPC[[#This Row],[NAMA MITRA]],FIND(" ",TBLDATAMITRAEPC[[#This Row],[NAMA MITRA]],FIND(" ",TBLDATAMITRAEPC[[#This Row],[NAMA MITRA]],1)+1)+1)+1,1),"")&IFERROR(MID(TBLDATAMITRAEPC[[#This Row],[NAMA MITRA]],FIND(" ",TBLDATAMITRAEPC[[#This Row],[NAMA MITRA]],FIND(" ",TBLDATAMITRAEPC[[#This Row],[NAMA MITRA]],FIND(" ",TBLDATAMITRAEPC[[#This Row],[NAMA MITRA]],FIND(" ",TBLDATAMITRAEPC[[#This Row],[NAMA MITRA]],1)+1)+1)+1)+1,1),"") -> G | B11: GALIH | C11: NURUL HIDAYATU SAMSIAH
A12: =LEFT(TBLDATAMITRAEPC[[#This Row],[NAMA MITRA]],1)&IFERROR(MID(TBLDATAMITRAEPC[[#This Row],[NAMA MITRA]],FIND(" ",TBLDATAMITRAEPC[[#This Row],[NAMA MITRA]],1)+1,1),"")&IFERROR(MID(TBLDATAMITRAEPC[[#This Row],[NAMA MITRA]],FIND(" ",TBLDATAMITRAEPC[[#This Row],[NAMA MITRA]],FIND(" ",TBLDATAMITRAEPC[[#This Row],[NAMA MITRA]],1)+1)+1,1),"")&IFERROR(MID(TBLDATAMITRAEPC[[#This Row],[NAMA MITRA]],FIND(" ",TBLDATAMITRAEPC[[#This Row],[NAMA MITRA]],FIND(" ",TBLDATAMITRAEPC[[#This Row],[NAMA MITRA]],FIND(" ",TBLDATAMITRAEPC[[#This Row],[NAMA MITRA]],1)+1)+1)+1,1),"")&IFERROR(MID(TBLDATAMITRAEPC[[#This Row],[NAMA MITRA]],FIND(" ",TBLDATAMITRAEPC[[#This Row],[NAMA MITRA]],FIND(" ",TBLDATAMITRAEPC[[#This Row],[NAMA MITRA]],FIND(" ",TBLDATAMITRAEPC[[#This Row],[NAMA MITRA]],FIND(" ",TBLDATAMITRAEPC[[#This Row],[NAMA MITRA]],1)+1)+1)+1)+1,1),"") -> H | B12: HANI | C12: NURUL HIDAYATU SAMSIAH
A13: =LEFT(TBLDATAMITRAEPC[[#This Row],[NAMA MITRA]],1)&IFERROR(MID(TBLDATAMITRAEPC[[#This Row],[NAMA MITRA]],FIND(" ",TBLDATAMITRAEPC[[#This Row],[NAMA MITRA]],1)+1,1),"")&IFERROR(MID(TBLDATAMITRAEPC[[#This Row],[NAMA MITRA]],FIND(" ",TBLDATAMITRAEPC[[#This Row],[NAMA MITRA]],FIND(" ",TBLDATAMITRAEPC[[#This Row],[NAMA MITRA]],1)+1)+1,1),"")&IFERROR(MID(TBLDATAMITRAEPC[[#This Row],[NAMA MITRA]],FIND(" ",TBLDATAMITRAEPC[[#This Row],[NAMA MITRA]],FIND(" ",TBLDATAMITRAEPC[[#This Row],[NAMA MITRA]],FIND(" ",TBLDATAMITRAEPC[[#This Row],[NAMA MITRA]],1)+1)+1)+1,1),"")&IFERROR(MID(TBLDATAMITRAEPC[[#This Row],[NAMA MITRA]],FIND(" ",TBLDATAMITRAEPC[[#This Row],[NAMA MITRA]],FIND(" ",TBLDATAMITRAEPC[[#This Row],[NAMA MITRA]],FIND(" ",TBLDATAMITRAEPC[[#This Row],[NAMA MITRA]],FIND(" ",TBLDATAMITRAEPC[[#This Row],[NAMA MITRA]],1)+1)+1)+1)+1,1),"") -> IS | B13: IIS SUGIARTI | C13: NURUL HIDAYATU SAMSIAH
A14: =LEFT(TBLDATAMITRAEPC[[#This Row],[NAMA MITRA]],1)&IFERROR(MID(TBLDATAMITRAEPC[[#This Row],[NAMA MITRA]],FIND(" ",TBLDATAMITRAEPC[[#This Row],[NAMA MITRA]],1)+1,1),"")&IFERROR(MID(TBLDATAMITRAEPC[[#This Row],[NAMA MITRA]],FIND(" ",TBLDATAMITRAEPC[[#This Row],[NAMA MITRA]],FIND(" ",TBLDATAMITRAEPC[[#This Row],[NAMA MITRA]],1)+1)+1,1),"")&IFERROR(MID(TBLDATAMITRAEPC[[#This Row],[NAMA MITRA]],FIND(" ",TBLDATAMITRAEPC[[#This Row],[NAMA MITRA]],FIND(" ",TBLDATAMITRAEPC[[#This Row],[NAMA MITRA]],FIND(" ",TBLDATAMITRAEPC[[#This Row],[NAMA MITRA]],1)+1)+1)+1,1),"")&IFERROR(MID(TBLDATAMITRAEPC[[#This Row],[NAMA MITRA]],FIND(" ",TBLDATAMITRAEPC[[#This Row],[NAMA MITRA]],FIND(" ",TBLDATAMITRAEPC[[#This Row],[NAMA MITRA]],FIND(" ",TBLDATAMITRAEPC[[#This Row],[NAMA MITRA]],FIND(" ",TBLDATAMITRAEPC[[#This Row],[NAMA MITRA]],1)+1)+1)+1)+1,1),"") -> I | B14: INTAN | C14: DENI
A15: =LEFT(TBLDATAMITRAEPC[[#This Row],[NAMA MITRA]],1)&IFERROR(MID(TBLDATAMITRAEPC[[#This Row],[NAMA MITRA]],FIND(" ",TBLDATAMITRAEPC[[#This Row],[NAMA MITRA]],1)+1,1),"")&IFERROR(MID(TBLDATAMITRAEPC[[#This Row],[NAMA MITRA]],FIND(" ",TBLDATAMITRAEPC[[#This Row],[NAMA MITRA]],FIND(" ",TBLDATAMITRAEPC[[#This Row],[NAMA MITRA]],1)+1)+1,1),"")&IFERROR(MID(TBLDATAMITRAEPC[[#This Row],[NAMA MITRA]],FIND(" ",TBLDATAMITRAEPC[[#This Row],[NAMA MITRA]],FIND(" ",TBLDATAMITRAEPC[[#This Row],[NAMA MITRA]],FIND(" ",TBLDATAMITRAEPC[[#This Row],[NAMA MITRA]],1)+1)+1)+1,1),"")&IFERROR(MID(TBLDATAMITRAEPC[[#This Row],[NAMA MITRA]],FIND(" ",TBLDATAMITRAEPC[[#This Row],[NAMA MITRA]],FIND(" ",TBLDATAMITRAEPC[[#This Row],[NAMA MITRA]],FIND(" ",TBLDATAMITRAEPC[[#This Row],[NAMA MITRA]],FIND(" ",TBLDATAMITRAEPC[[#This Row],[NAMA MITRA]],1)+1)+1)+1)+1,1),"") -> IF | B15: ISA FEFEN | C15: NURUL HIDAYATU SAMSIAH
A16: =LEFT(TBLDATAMITRAEPC[[#This Row],[NAMA MITRA]],1)&IFERROR(MID(TBLDATAMITRAEPC[[#This Row],[NAMA MITRA]],FIND(" ",TBLDATAMITRAEPC[[#This Row],[NAMA MITRA]],1)+1,1),"")&IFERROR(MID(TBLDATAMITRAEPC[[#This Row],[NAMA MITRA]],FIND(" ",TBLDATAMITRAEPC[[#This Row],[NAMA MITRA]],FIND(" ",TBLDATAMITRAEPC[[#This Row],[NAMA MITRA]],1)+1)+1,1),"")&IFERROR(MID(TBLDATAMITRAEPC[[#This Row],[NAMA MITRA]],FIND(" ",TBLDATAMITRAEPC[[#This Row],[NAMA MITRA]],FIND(" ",TBLDATAMITRAEPC[[#This Row],[NAMA MITRA]],FIND(" ",TBLDATAMITRAEPC[[#This Row],[NAMA MITRA]],1)+1)+1)+1,1),"")&IFERROR(MID(TBLDATAMITRAEPC[[#This Row],[NAMA MITRA]],FIND(" ",TBLDATAMITRAEPC[[#This Row],[NAMA MITRA]],FIND(" ",TBLDATAMITRAEPC[[#This Row],[NAMA MITRA]],FIND(" ",TBLDATAMITRAEPC[[#This Row],[NAMA MITRA]],FIND(" ",TBLDATAMITRAEPC[[#This Row],[NAMA MITRA]],1)+1)+1)+1)+1,1),"") -> KC | B16: KEDAI CERIA | C16: NURUL HIDAYATU SAMSIAH
... A19: =LEFT(TBLDATAMITRAEPC[[#This Row],[NAMA MITRA]],1)&IFERROR(MID(TBLDATAMITRAEPC[[#This Row],[NAMA MITRA]],FIND(" ",TBLDATAMITRAEPC[[#This Row],[NAMA MITRA]],1)+1,1),"")&IFERROR(MID(TBLDATAMITRAEPC[[#This Row],[NAMA MITRA]],FIND(" ",TBLDATAMITRAEPC[[#This Row],[NAMA MITRA]],FIND(" ",TBLDATAMITRAEPC[[#This Row],[NAMA MITRA]],1)+1)+1,1),"")&IFERROR(MID(TBLDATAMITRAEPC[[#This Row],[NAMA MITRA]],FIND(" ",TBLDATAMITRAEPC[[#This Row],[NAMA MITRA]],FIND(" ",TBLDATAMITRAEPC[[#This Row],[NAMA MITRA]],FIND(" ",TBLDATAMITRAEPC[[#This Row],[NAMA MITRA]],1)+1)+1)+1,1),"")&IFERROR(MID(TBLDATAMITRAEPC[[#This Row],[NAMA MITRA]],FIND(" ",TBLDATAMITRAEPC[[#This Row],[NAMA MITRA]],FIND(" ",TBLDATAMITRAEPC[[#This Row],[NAMA MITRA]],FIND(" ",TBLDATAMITRAEPC[[#This Row],[NAMA MITRA]],FIND(" ",TBLDATAMITRAEPC[[#This Row],[NAMA MITRA]],1)+1)+1)+1)+1,1),"") -> NP | B19: NUR PANTI | C19: NURUL HIDAYATU SAMSIAH
A20: =LEFT(TBLDATAMITRAEPC[[#This Row],[NAMA MITRA]],1)&IFERROR(MID(TBLDATAMITRAEPC[[#This Row],[NAMA MITRA]],FIND(" ",TBLDATAMITRAEPC[[#This Row],[NAMA MITRA]],1)+1,1),"")&IFERROR(MID(TBLDATAMITRAEPC[[#This Row],[NAMA MITRA]],FIND(" ",TBLDATAMITRAEPC[[#This Row],[NAMA MITRA]],FIND(" ",TBLDATAMITRAEPC[[#This Row],[NAMA MITRA]],1)+1)+1,1),"")&IFERROR(MID(TBLDATAMITRAEPC[[#This Row],[NAMA MITRA]],FIND(" ",TBLDATAMITRAEPC[[#This Row],[NAMA MITRA]],FIND(" ",TBLDATAMITRAEPC[[#This Row],[NAMA MITRA]],FIND(" ",TBLDATAMITRAEPC[[#This Row],[NAMA MITRA]],1)+1)+1)+1,1),"")&IFERROR(MID(TBLDATAMITRAEPC[[#This Row],[NAMA MITRA]],FIND(" ",TBLDATAMITRAEPC[[#This Row],[NAMA MITRA]],FIND(" ",TBLDATAMITRAEPC[[#This Row],[NAMA MITRA]],FIND(" ",TBLDATAMITRAEPC[[#This Row],[NAMA MITRA]],FIND(" ",TBLDATAMITRAEPC[[#This Row],[NAMA MITRA]],1)+1)+1)+1)+1,1),"") -> NHS | B20: NURUL HIDAYATU SAMSIAH | C20: NURUL HIDAYATU SAMSIAH | D20: 085746323192
A21: =LEFT(TBLDATAMITRAEPC[[#This Row],[NAMA MITRA]],1)&IFERROR(MID(TBLDATAMITRAEPC[[#This Row],[NAMA MITRA]],FIND(" ",TBLDATAMITRAEPC[[#This Row],[NAMA MITRA]],1)+1,1),"")&IFERROR(MID(TBLDATAMITRAEPC[[#This Row],[NAMA MITRA]],FIND(" ",TBLDATAMITRAEPC[[#This Row],[NAMA MITRA]],FIND(" ",TBLDATAMITRAEPC[[#This Row],[NAMA MITRA]],1)+1)+1,1),"")&IFERROR(MID(TBLDATAMITRAEPC[[#This Row],[NAMA MITRA]],FIND(" ",TBLDATAMITRAEPC[[#This Row],[NAMA MITRA]],FIND(" ",TBLDATAMITRAEPC[[#This Row],[NAMA MITRA]],FIND(" ",TBLDATAMITRAEPC[[#This Row],[NAMA MITRA]],1)+1)+1)+1,1),"")&IFERROR(MID(TBLDATAMITRAEPC[[#This Row],[NAMA MITRA]],FIND(" ",TBLDATAMITRAEPC[[#This Row],[NAMA MITRA]],FIND(" ",TBLDATAMITRAEPC[[#This Row],[NAMA MITRA]],FIND(" ",TBLDATAMITRAEPC[[#This Row],[NAMA MITRA]],FIND(" ",TBLDATAMITRAEPC[[#This Row],[NAMA MITRA]],1)+1)+1)+1)+1,1),"") -> Q | B21: QEQEL | C21: NURUL HIDAYATU SAMSIAH
A22: =LEFT(TBLDATAMITRAEPC[[#This Row],[NAMA MITRA]],1)&IFERROR(MID(TBLDATAMITRAEPC[[#This Row],[NAMA MITRA]],FIND(" ",TBLDATAMITRAEPC[[#This Row],[NAMA MITRA]],1)+1,1),"")&IFERROR(MID(TBLDATAMITRAEPC[[#This Row],[NAMA MITRA]],FIND(" ",TBLDATAMITRAEPC[[#This Row],[NAMA MITRA]],FIND(" ",TBLDATAMITRAEPC[[#This Row],[NAMA MITRA]],1)+1)+1,1),"")&IFERROR(MID(TBLDATAMITRAEPC[[#This Row],[NAMA MITRA]],FIND(" ",TBLDATAMITRAEPC[[#This Row],[NAMA MITRA]],FIND(" ",TBLDATAMITRAEPC[[#This Row],[NAMA MITRA]],FIND(" ",TBLDATAMITRAEPC[[#This Row],[NAMA MITRA]],1)+1)+1)+1,1),"")&IFERROR(MID(TBLDATAMITRAEPC[[#This Row],[NAMA MITRA]],FIND(" ",TBLDATAMITRAEPC[[#This Row],[NAMA MITRA]],FIND(" ",TBLDATAMITRAEPC[[#This Row],[NAMA MITRA]],FIND(" ",TBLDATAMITRAEPC[[#This Row],[NAMA MITRA]],FIND(" ",TBLDATAMITRAEPC[[#This Row],[NAMA MITRA]],1)+1)+1)+1)+1,1),"") -> RDA | B22: RENI DWI ANGGRAINI | C22: NURUL HIDAYATU SAMSIAH
A23: =LEFT(TBLDATAMITRAEPC[[#This Row],[NAMA MITRA]],1)&IFERROR(MID(TBLDATAMITRAEPC[[#This Row],[NAMA MITRA]],FIND(" ",TBLDATAMITRAEPC[[#This Row],[NAMA MITRA]],1)+1,1),"")&IFERROR(MID(TBLDATAMITRAEPC[[#This Row],[NAMA MITRA]],FIND(" ",TBLDATAMITRAEPC[[#This Row],[NAMA MITRA]],FIND(" ",TBLDATAMITRAEPC[[#This Row],[NAMA MITRA]],1)+1)+1,1),"")&IFERROR(MID(TBLDATAMITRAEPC[[#This Row],[NAMA MITRA]],FIND(" ",TBLDATAMITRAEPC[[#This Row],[NAMA MITRA]],FIND(" ",TBLDATAMITRAEPC[[#This Row],[NAMA MITRA]],FIND(" ",TBLDATAMITRAEPC[[#This Row],[NAMA MITRA]],1)+1)+1)+1,1),"")&IFERROR(MID(TBLDATAMITRAEPC[[#This Row],[NAMA MITRA]],FIND(" ",TBLDATAMITRAEPC[[#This Row],[NAMA MITRA]],FIND(" ",TBLDATAMITRAEPC[[#This Row],[NAMA MITRA]],FIND(" ",TBLDATAMITRAEPC[[#This Row],[NAMA MITRA]],FIND(" ",TBLDATAMITRAEPC[[#This Row],[NAMA MITRA]],1)+1)+1)+1)+1,1),"") -> R | B23: RIA | C23: NURUL HIDAYATU SAMSIAH
A24: =LEFT(TBLDATAMITRAEPC[[#This Row],[NAMA MITRA]],1)&IFERROR(MID(TBLDATAMITRAEPC[[#This Row],[NAMA MITRA]],FIND(" ",TBLDATAMITRAEPC[[#This Row],[NAMA MITRA]],1)+1,1),"")&IFERROR(MID(TBLDATAMITRAEPC[[#This Row],[NAMA MITRA]],FIND(" ",TBLDATAMITRAEPC[[#This Row],[NAMA MITRA]],FIND(" ",TBLDATAMITRAEPC[[#This Row],[NAMA MITRA]],1)+1)+1,1),"")&IFERROR(MID(TBLDATAMITRAEPC[[#This Row],[NAMA MITRA]],FIND(" ",TBLDATAMITRAEPC[[#This Row],[NAMA MITRA]],FIND(" ",TBLDATAMITRAEPC[[#This Row],[NAMA MITRA]],FIND(" ",TBLDATAMITRAEPC[[#This Row],[NAMA MITRA]],1)+1)+1)+1,1),"")&IFERROR(MID(TBLDATAMITRAEPC[[#This Row],[NAMA MITRA]],FIND(" ",TBLDATAMITRAEPC[[#This Row],[NAMA MITRA]],FIND(" ",TBLDATAMITRAEPC[[#This Row],[NAMA MITRA]],FIND(" ",TBLDATAMITRAEPC[[#This Row],[NAMA MITRA]],FIND(" ",TBLDATAMITRAEPC[[#This Row],[NAMA MITRA]],1)+1)+1)+1)+1,1),"") -> RD | B24: RINDA DWI | C24: NURUL HIDAYATU SAMSIAH
A25: =LEFT(TBLDATAMITRAEPC[[#This Row],[NAMA MITRA]],1)&IFERROR(MID(TBLDATAMITRAEPC[[#This Row],[NAMA MITRA]],FIND(" ",TBLDATAMITRAEPC[[#This Row],[NAMA MITRA]],1)+1,1),"")&IFERROR(MID(TBLDATAMITRAEPC[[#This Row],[NAMA MITRA]],FIND(" ",TBLDATAMITRAEPC[[#This Row],[NAMA MITRA]],FIND(" ",TBLDATAMITRAEPC[[#This Row],[NAMA MITRA]],1)+1)+1,1),"")&IFERROR(MID(TBLDATAMITRAEPC[[#This Row],[NAMA MITRA]],FIND(" ",TBLDATAMITRAEPC[[#This Row],[NAMA MITRA]],FIND(" ",TBLDATAMITRAEPC[[#This Row],[NAMA MITRA]],FIND(" ",TBLDATAMITRAEPC[[#This Row],[NAMA MITRA]],1)+1)+1)+1,1),"")&IFERROR(MID(TBLDATAMITRAEPC[[#This Row],[NAMA MITRA]],FIND(" ",TBLDATAMITRAEPC[[#This Row],[NAMA MITRA]],FIND(" ",TBLDATAMITRAEPC[[#This Row],[NAMA MITRA]],FIND(" ",TBLDATAMITRAEPC[[#This Row],[NAMA MITRA]],FIND(" ",TBLDATAMITRAEPC[[#This Row],[NAMA MITRA]],1)+1)+1)+1)+1,1),"") -> M | B25: MANDA | C25: NURUL HIDAYATU SAMSIAH
A26: =LEFT(TBLDATAMITRAEPC[[#This Row],[NAMA MITRA]],1)&IFERROR(MID(TBLDATAMITRAEPC[[#This Row],[NAMA MITRA]],FIND(" ",TBLDATAMITRAEPC[[#This Row],[NAMA MITRA]],1)+1,1),"")&IFERROR(MID(TBLDATAMITRAEPC[[#This Row],[NAMA MITRA]],FIND(" ",TBLDATAMITRAEPC[[#This Row],[NAMA MITRA]],FIND(" ",TBLDATAMITRAEPC[[#This Row],[NAMA MITRA]],1)+1)+1,1),"")&IFERROR(MID(TBLDATAMITRAEPC[[#This Row],[NAMA MITRA]],FIND(" ",TBLDATAMITRAEPC[[#This Row],[NAMA MITRA]],FIND(" ",TBLDATAMITRAEPC[[#This Row],[NAMA MITRA]],FIND(" ",TBLDATAMITRAEPC[[#This Row],[NAMA MITRA]],1)+1)+1)+1,1),"")&IFERROR(MID(TBLDATAMITRAEPC[[#This Row],[NAMA MITRA]],FIND(" ",TBLDATAMITRAEPC[[#This Row],[NAMA MITRA]],FIND(" ",TBLDATAMITRAEPC[[#This Row],[NAMA MITRA]],FIND(" ",TBLDATAMITRAEPC[[#This Row],[NAMA MITRA]],FIND(" ",TBLDATAMITRAEPC[[#This Row],[NAMA MITRA]],1)+1)+1)+1)+1,1),"") -> R | B26: RISTA | C26: NURUL HIDAYATU SAMSIAH
A27: =LEFT(TBLDATAMITRAEPC[[#This Row],[NAMA MITRA]],1)&IFERROR(MID(TBLDATAMITRAEPC[[#This Row],[NAMA MITRA]],FIND(" ",TBLDATAMITRAEPC[[#This Row],[NAMA MITRA]],1)+1,1),"")&IFERROR(MID(TBLDATAMITRAEPC[[#This Row],[NAMA MITRA]],FIND(" ",TBLDATAMITRAEPC[[#This Row],[NAMA MITRA]],FIND(" ",TBLDATAMITRAEPC[[#This Row],[NAMA MITRA]],1)+1)+1,1),"")&IFERROR(MID(TBLDATAMITRAEPC[[#This Row],[NAMA MITRA]],FIND(" ",TBLDATAMITRAEPC[[#This Row],[NAMA MITRA]],FIND(" ",TBLDATAMITRAEPC[[#This Row],[NAMA MITRA]],FIND(" ",TBLDATAMITRAEPC[[#This Row],[NAMA MITRA]],1)+1)+1)+1,1),"")&IFERROR(MID(TBLDATAMITRAEPC[[#This Row],[NAMA MITRA]],FIND(" ",TBLDATAMITRAEPC[[#This Row],[NAMA MITRA]],FIND(" ",TBLDATAMITRAEPC[[#This Row],[NAMA MITRA]],FIND(" ",TBLDATAMITRAEPC[[#This Row],[NAMA MITRA]],FIND(" ",TBLDATAMITRAEPC[[#This Row],[NAMA MITRA]],1)+1)+1)+1)+1,1),"") -> R | B27: ROIK | C27: NURUL HIDAYATU SAMSIAH
A28: =LEFT(TBLDATAMITRAEPC[[#This Row],[NAMA MITRA]],1)&IFERROR(MID(TBLDATAMITRAEPC[[#This Row],[NAMA MITRA]],FIND(" ",TBLDATAMITRAEPC[[#This Row],[NAMA MITRA]],1)+1,1),"")&IFERROR(MID(TBLDATAMITRAEPC[[#This Row],[NAMA MITRA]],FIND(" ",TBLDATAMITRAEPC[[#This Row],[NAMA MITRA]],FIND(" ",TBLDATAMITRAEPC[[#This Row],[NAMA MITRA]],1)+1)+1,1),"")&IFERROR(MID(TBLDATAMITRAEPC[[#This Row],[NAMA MITRA]],FIND(" ",TBLDATAMITRAEPC[[#This Row],[NAMA MITRA]],FIND(" ",TBLDATAMITRAEPC[[#This Row],[NAMA MITRA]],FIND(" ",TBLDATAMITRAEPC[[#This Row],[NAMA MITRA]],1)+1)+1)+1,1),"")&IFERROR(MID(TBLDATAMITRAEPC[[#This Row],[NAMA MITRA]],FIND(" ",TBLDATAMITRAEPC[[#This Row],[NAMA MITRA]],FIND(" ",TBLDATAMITRAEPC[[#This Row],[NAMA MITRA]],FIND(" ",TBLDATAMITRAEPC[[#This Row],[NAMA MITRA]],FIND(" ",TBLDATAMITRAEPC[[#This Row],[NAMA MITRA]],1)+1)+1)+1)+1,1),"") -> UDL | B28: ULFA DWI LESTARI | C28: NURUL HIDAYATU SAMSIAH
A29: =LEFT(TBLDATAMITRAEPC[[#This Row],[NAMA MITRA]],1)&IFERROR(MID(TBLDATAMITRAEPC[[#This Row],[NAMA MITRA]],FIND(" ",TBLDATAMITRAEPC[[#This Row],[NAMA MITRA]],1)+1,1),"")&IFERROR(MID(TBLDATAMITRAEPC[[#This Row],[NAMA MITRA]],FIND(" ",TBLDATAMITRAEPC[[#This Row],[NAMA MITRA]],FIND(" ",TBLDATAMITRAEPC[[#This Row],[NAMA MITRA]],1)+1)+1,1),"")&IFERROR(MID(TBLDATAMITRAEPC[[#This Row],[NAMA MITRA]],FIND(" ",TBLDATAMITRAEPC[[#This Row],[NAMA MITRA]],FIND(" ",TBLDATAMITRAEPC[[#This Row],[NAMA MITRA]],FIND(" ",TBLDATAMITRAEPC[[#This Row],[NAMA MITRA]],1)+1)+1)+1,1),"")&IFERROR(MID(TBLDATAMITRAEPC[[#This Row],[NAMA MITRA]],FIND(" ",TBLDATAMITRAEPC[[#This Row],[NAMA MITRA]],FIND(" ",TBLDATAMITRAEPC[[#This Row],[NAMA MITRA]],FIND(" ",TBLDATAMITRAEPC[[#This Row],[NAMA MITRA]],FIND(" ",TBLDATAMITRAEPC[[#This Row],[NAMA MITRA]],1)+1)+1)+1)+1,1),"") -> V | B29: VEBRI | C29: NURUL HIDAYATU SAMSIAH
A30: =LEFT(TBLDATAMITRAEPC[[#This Row],[NAMA MITRA]],1)&IFERROR(MID(TBLDATAMITRAEPC[[#This Row],[NAMA MITRA]],FIND(" ",TBLDATAMITRAEPC[[#This Row],[NAMA MITRA]],1)+1,1),"")&IFERROR(MID(TBLDATAMITRAEPC[[#This Row],[NAMA MITRA]],FIND(" ",TBLDATAMITRAEPC[[#This Row],[NAMA MITRA]],FIND(" ",TBLDATAMITRAEPC[[#This Row],[NAMA MITRA]],1)+1)+1,1),"")&IFERROR(MID(TBLDATAMITRAEPC[[#This Row],[NAMA MITRA]],FIND(" ",TBLDATAMITRAEPC[[#This Row],[NAMA MITRA]],FIND(" ",TBLDATAMITRAEPC[[#This Row],[NAMA MITRA]],FIND(" ",TBLDATAMITRAEPC[[#This Row],[NAMA MITRA]],1)+1)+1)+1,1),"")&IFERROR(MID(TBLDATAMITRAEPC[[#This Row],[NAMA MITRA]],FIND(" ",TBLDATAMITRAEPC[[#This Row],[NAMA MITRA]],FIND(" ",TBLDATAMITRAEPC[[#This Row],[NAMA MITRA]],FIND(" ",TBLDATAMITRAEPC[[#This Row],[NAMA MITRA]],FIND(" ",TBLDATAMITRAEPC[[#This Row],[NAMA MITRA]],1)+1)+1)+1)+1,1),"") -> V | B30: VITA | C30: NURUL HIDAYATU SAMSIAH
B32: LEFT([@[NAMA RESELLER]];1)
B33: IFERROR(MID([@[NAMA RESELLER]];FIND(" ";[@[NAMA RESELLER]];1)+1;1);"")
B34: IFERROR(MID([@[NAMA RESELLER]];FIND(" ";[@[NAMA RESELLER]];FIND(" ";[@[NAMA RESELLER]];1)+1)+1;1);"")
B35: IFERROR(MID([@[NAMA RESELLER]];FIND(" ";[@[NAMA RESELLER]];FIND(" ";[@[NAMA RESELLER]];FIND(" ";[@[NAMA RESELLER]];1)+1)+1)+1;1);"")
B36: IFERROR(MID([@[NAMA RESELLER]];FIND(" ";[@[NAMA RESELLER]];FIND(" ";[@[NAMA RESELLER]];FIND(" ";[@[NAMA RESELLER]];FIND(" ";[@[NAMA RESELLER]];1)+1)+1)+1)+1;1);"")

Sheet DATA CUSTOMER
A3: NAMA CUSTOMER | B3: NO HP | C3: ALAMAT KIRIM | D3: NAMA MITRA | E3: NAMA PEREKRUT
A4: ABIDZAR | C4: RAMBIPUJI | D4: CAHYA GALLERY | E4: NURUL HIDAYATU SAMSIAH
A5: ABIL | C5: LOJEJER | D5: DANI | E5: NURUL HIDAYATU SAMSIAH
A6: ADE | C6: AJUNG | D6: NURUL HIDAYATU SAMSIAH | E6: NURUL HIDAYATU SAMSIAH
A7: ADE CG | C7: AJUNG | D7: CAHYA GALLERY | E7: NURUL HIDAYATU SAMSIAH
A8: ADEL | C8: PANTI | D8: NURUL HIDAYATU SAMSIAH | E8: NURUL HIDAYATU SAMSIAH
A9: ADEL CG | C9: PANTI | D9: CAHYA GALLERY | E9: NURUL HIDAYATU SAMSIAH
A10: ADIF CG | C10: SATREAN | D10: CAHYA GALLERY | E10: NURUL HIDAYATU SAMSIAH
A11: ADMIN | C11: SEJATI | D11: NURUL HIDAYATU SAMSIAH | E11: NURUL HIDAYATU SAMSIAH
A12: ADMIN CG | C12: SEJATI | D12: CAHYA GALLERY | E12: NURUL HIDAYATU SAMSIAH
A13: AFFAN | C13: PANTI | D13: NURUL HIDAYATU SAMSIAH | E13: NURUL HIDAYATU SAMSIAH
A14: AFFAN CG | C14: PANTI | D14: CAHYA GALLERY | E14: NURUL HIDAYATU SAMSIAH
A15: AGUNG | C15: PANTI | D15: DENI | E15: NURUL HIDAYATU SAMSIAH
... A50: BU URIP ANI | C50: TALANGSARI | D50: ANI | E50: NURUL HIDAYATU SAMSIAH
A51: BU ZULIATI | D51: NURUL HIDAYATU SAMSIAH | E51: NURUL HIDAYATU SAMSIAH
A52: CAHYO CG | C52: AJUNG | D52: CAHYA GALLERY | E52: NURUL HIDAYATU SAMSIAH
A53: CG | C53: PANTI | D53: CAHYA GALLERY | E53: NURUL HIDAYATU SAMSIAH
A54: CICI CG | C54: PETUNG | D54: CAHYA GALLERY | E54: NURUL HIDAYATU SAMSIAH
A55: CIK EN WA | C55: SEJATI | D55: NURUL HIDAYATU SAMSIAH | E55: NURUL HIDAYATU SAMSIAH
A56: CIK EN WA CG | C56: SEJATI | D56: CAHYA GALLERY | E56: NURUL HIDAYATU SAMSIAH
A57: CINDY CG | C57: PANTI | D57: CAHYA GALLERY | E57: NURUL HIDAYATU SAMSIAH
A58: CINDY NUR | C58: PANTI | D58: NUR PANTI | E58: NURUL HIDAYATU SAMSIAH
A59: DENI | C59: PANTI | D59: DENI | E59: NURUL HIDAYATU SAMSIAH
A60: DEWI | C60: PANTI | D60: DENI | E60: NURUL HIDAYATU SAMSIAH
A61: DEWI ZAKIYAH | C61: BANGSAL | D61: DEWI ZAKIYAH | E61: NURUL HIDAYATU SAMSIAH
A62: DEWI ZAKIYAH NURUL | C62: BANGSAL | D62: NURUL HIDAYATU SAMSIAH | E62: NURUL HIDAYATU SAMSIAH
A63: DIDIN | C63: GELUNDENGAN | D63: NURUL HIDAYATU SAMSIAH | E63: NURUL HIDAYATU SAMSIAH
... A230: ZULAIKHA CG | C230: PERUMNAS PANTI | D230: CAHYA GALLERY | E230: NURUL HIDAYATU SAMSIAH

Sheet KATALOG
B3: NAMA PRODUK | C3: MODAL KEMBALI KE PERUSAHAAN PRODUK OFF LINE | D3: BUDGET KOMISI RESELLER | E3: MODAL SETELAH DITAMBAH BUDGET KOMISI | F3: HARGA JUAL | G3: SELISIH/LABA BERSIH TOKO | H3: LABA MITRA 5 % | I3: LABA KIRIM 5 % | J3: LABA BERSIH
B4: BURGER MEDIUM DAGING SAPI | C4: =VLOOKUP(TBLKATALOG[[#This Row],[NAMA PRODUK]],[4]!TBLMODAL[[NAMA MENU]:[MODAL KEMBALI KE PERUSAHAAN PRODUK OFF LINE]],2,FALSE) -> 11837.889 | D4: =SUM(TBLKATALOG[[#This Row],[LABA MITRA 5 %]:[LABA KIRIM 5 %]]) -> 1183.7889 | E4: =C4+D4 -> 13021.678 | F4: 15000 | G4: =F4-E4 -> 1978.3222 | H4: =0.05*C4 -> 591.89444 | I4: =0.05*C4 -> 591.89444 | J4: =TBLKATALOG[[#This Row],[HARGA JUAL]]-TBLKATALOG[[#This Row],[MODAL SETELAH DITAMBAH BUDGET KOMISI]] -> 1978.3222
B5: BURGER MEDIUM DAGING SAPI DOUBLE BEEF | C5: =VLOOKUP(TBLKATALOG[[#This Row],[NAMA PRODUK]],[4]!TBLMODAL[[NAMA MENU]:[MODAL KEMBALI KE PERUSAHAAN PRODUK OFF LINE]],2,FALSE) -> 15662.889 | D5: =SUM(TBLKATALOG[[#This Row],[LABA MITRA 5 %]:[LABA KIRIM 5 %]]) -> 1566.2889 | E5: =C5+D5 -> 17229.178 | F5: 20000 | G5: =F5-E5 -> 2770.8222 | H5: =0.05*C5 -> 783.14444 | I5: =0.05*C5 -> 783.14444 | J5: =TBLKATALOG[[#This Row],[HARGA JUAL]]-TBLKATALOG[[#This Row],[MODAL SETELAH DITAMBAH BUDGET KOMISI]] -> 2770.8222
B6: BURGER MEDIUM DAGING SAPI TANPA SAYUR | C6: =VLOOKUP(TBLKATALOG[[#This Row],[NAMA PRODUK]],[4]!TBLMODAL[[NAMA MENU]:[MODAL KEMBALI KE PERUSAHAAN PRODUK OFF LINE]],2,FALSE) -> 11049 | D6: =SUM(TBLKATALOG[[#This Row],[LABA MITRA 5 %]:[LABA KIRIM 5 %]]) -> 1104.9 | E6: =C6+D6 -> 12153.9 | F6: 15000 | G6: =F6-E6 -> 2846.1 | H6: =0.05*C6 -> 552.45 | I6: =0.05*C6 -> 552.45 | J6: =TBLKATALOG[[#This Row],[HARGA JUAL]]-TBLKATALOG[[#This Row],[MODAL SETELAH DITAMBAH BUDGET KOMISI]] -> 2846.1
B7: BURGER MEDIUM NUGGET AYAM | C7: =VLOOKUP(TBLKATALOG[[#This Row],[NAMA PRODUK]],[4]!TBLMODAL[[NAMA MENU]:[MODAL KEMBALI KE PERUSAHAAN PRODUK OFF LINE]],2,FALSE) -> 11679.556 | D7: =SUM(TBLKATALOG[[#This Row],[LABA MITRA 5 %]:[LABA KIRIM 5 %]]) -> 1167.9556 | E7: =C7+D7 -> 12847.511 | F7: 15000 | G7: =F7-E7 -> 2152.4889 | H7: =0.05*C7 -> 583.97778 | I7: =0.05*C7 -> 583.97778 | J7: =TBLKATALOG[[#This Row],[HARGA JUAL]]-TBLKATALOG[[#This Row],[MODAL SETELAH DITAMBAH BUDGET KOMISI]] -> 2152.4889
B8: BURGER MEDIUM NUGGET AYAM TANPA SAYUR | C8: =VLOOKUP(TBLKATALOG[[#This Row],[NAMA PRODUK]],[4]!TBLMODAL[[NAMA MENU]:[MODAL KEMBALI KE PERUSAHAAN PRODUK OFF LINE]],2,FALSE) -> 12224 | D8: =SUM(TBLKATALOG[[#This Row],[LABA MITRA 5 %]:[LABA KIRIM 5 %]]) -> 1222.4 | E8: =C8+D8 -> 13446.4 | F8: 15000 | G8: =F8-E8 -> 1553.6 | H8: =0.05*C8 -> 611.2 | I8: =0.05*C8 -> 611.2 | J8: =TBLKATALOG[[#This Row],[HARGA JUAL]]-TBLKATALOG[[#This Row],[MODAL SETELAH DITAMBAH BUDGET KOMISI]] -> 1553.6
B9: KEBAB AYAM (KECIL) | C9: =VLOOKUP(TBLKATALOG[[#This Row],[NAMA PRODUK]],[4]!TBLMODAL[[NAMA MENU]:[MODAL KEMBALI KE PERUSAHAAN PRODUK OFF LINE]],2,FALSE) -> 6711.6667 | D9: =SUM(TBLKATALOG[[#This Row],[LABA MITRA 5 %]:[LABA KIRIM 5 %]]) -> 671.16667 | E9: =C9+D9 -> 7382.8333 | F9: 9000 | G9: =F9-E9 -> 1617.1667 | H9: =0.05*C9 -> 335.58333 | I9: =0.05*C9 -> 335.58333 | J9: =TBLKATALOG[[#This Row],[HARGA JUAL]]-TBLKATALOG[[#This Row],[MODAL SETELAH DITAMBAH BUDGET KOMISI]] -> 1617.1667
B10: KEBAB AYAM (KECIL) PEDAS | C10: =VLOOKUP(TBLKATALOG[[#This Row],[NAMA PRODUK]],[4]!TBLMODAL[[NAMA MENU]:[MODAL KEMBALI KE PERUSAHAAN PRODUK OFF LINE]],2,FALSE) -> 7057.6667 | D10: =SUM(TBLKATALOG[[#This Row],[LABA MITRA 5 %]:[LABA KIRIM 5 %]]) -> 705.76667 | E10: =C10+D10 -> 7763.4333 | F10: 9000 | G10: =F10-E10 -> 1236.5667 | H10: =0.05*C10 -> 352.88333 | I10: =0.05*C10 -> 352.88333 | J10: =TBLKATALOG[[#This Row],[HARGA JUAL]]-TBLKATALOG[[#This Row],[MODAL SETELAH DITAMBAH BUDGET KOMISI]] -> 1236.5667
B11: KEBAB AYAM (KECIL) TANPA SAYUR | C11: =VLOOKUP(TBLKATALOG[[#This Row],[NAMA PRODUK]],[4]!TBLMODAL[[NAMA MENU]:[MODAL KEMBALI KE PERUSAHAAN PRODUK OFF LINE]],2,FALSE) -> 6074.1667 | D11: =SUM(TBLKATALOG[[#This Row],[LABA MITRA 5 %]:[LABA KIRIM 5 %]]) -> 607.41667 | E11: =C11+D11 -> 6681.5833 | F11: 9000 | G11: =F11-E11 -> 2318.4167 | H11: =0.05*C11 -> 303.70833 | I11: =0.05*C11 -> 303.70833 | J11: =TBLKATALOG[[#This Row],[HARGA JUAL]]-TBLKATALOG[[#This Row],[MODAL SETELAH DITAMBAH BUDGET KOMISI]] -> 2318.4167
B12: KEBAB AYAM (KECIL) TANPA SAYUR PEDAS | C12: =VLOOKUP(TBLKATALOG[[#This Row],[NAMA PRODUK]],[4]!TBLMODAL[[NAMA MENU]:[MODAL KEMBALI KE PERUSAHAAN PRODUK OFF LINE]],2,FALSE) -> 6420.1667 | D12: =SUM(TBLKATALOG[[#This Row],[LABA MITRA 5 %]:[LABA KIRIM 5 %]]) -> 642.01667 | E12: =C12+D12 -> 7062.1833 | F12: 9000 | G12: =F12-E12 -> 1937.8167 | H12: =0.05*C12 -> 321.00833 | I12: =0.05*C12 -> 321.00833 | J12: =TBLKATALOG[[#This Row],[HARGA JUAL]]-TBLKATALOG[[#This Row],[MODAL SETELAH DITAMBAH BUDGET KOMISI]] -> 1937.8167
B13: KEBAB AYAM + SOSIZ (KECIL) | C13: =VLOOKUP(TBLKATALOG[[#This Row],[NAMA PRODUK]],[4]!TBLMODAL[[NAMA MENU]:[MODAL KEMBALI KE PERUSAHAAN PRODUK OFF LINE]],2,FALSE) -> 6122.193 | D13: =SUM(TBLKATALOG[[#This Row],[LABA MITRA 5 %]:[LABA KIRIM 5 %]]) -> 612.2193 | E13: =C13+D13 -> 6734.4123 | F13: 9000 | G13: =F13-E13 -> 2265.5877 | H13: =0.05*C13 -> 306.10965 | I13: =0.05*C13 -> 306.10965 | J13: =TBLKATALOG[[#This Row],[HARGA JUAL]]-TBLKATALOG[[#This Row],[MODAL SETELAH DITAMBAH BUDGET KOMISI]] -> 2265.5877
B14: KEBAB AYAM + SOSIZ (KECIL) PEDAS | C14: =VLOOKUP(TBLKATALOG[[#This Row],[NAMA PRODUK]],[4]!TBLMODAL[[NAMA MENU]:[MODAL KEMBALI KE PERUSAHAAN PRODUK OFF LINE]],2,FALSE) -> 6192.193 | D14: =SUM(TBLKATALOG[[#This Row],[LABA MITRA 5 %]:[LABA KIRIM 5 %]]) -> 619.2193 | E14: =C14+D14 -> 6811.4123 | F14: 9000 | G14: =F14-E14 -> 2188.5877 | H14: =0.05*C14 -> 309.60965 | I14: =0.05*C14 -> 309.60965 | J14: =TBLKATALOG[[#This Row],[HARGA JUAL]]-TBLKATALOG[[#This Row],[MODAL SETELAH DITAMBAH BUDGET KOMISI]] -> 2188.5877
B15: KEBAB AYAM + SOSIZ (KECIL) TANPA SAYUR EKSTRA AYAM | C15: =VLOOKUP(TBLKATALOG[[#This Row],[NAMA PRODUK]],[4]!TBLMODAL[[NAMA MENU]:[MODAL KEMBALI KE PERUSAHAAN PRODUK OFF LINE]],2,FALSE) -> 5972.193 | D15: =SUM(TBLKATALOG[[#This Row],[LABA MITRA 5 %]:[LABA KIRIM 5 %]]) -> 597.2193 | E15: =C15+D15 -> 6569.4123 | F15: 9000 | G15: =F15-E15 -> 2430.5877 | H15: =0.05*C15 -> 298.60965 | I15: =0.05*C15 -> 298.60965 | J15: =TBLKATALOG[[#This Row],[HARGA JUAL]]-TBLKATALOG[[#This Row],[MODAL SETELAH DITAMBAH BUDGET KOMISI]] -> 2430.5877
... B68: ZAMBI 10 CM SOSIZ+AYAM | C68: =VLOOKUP(TBLKATALOG[[#This Row],[NAMA PRODUK]],[4]!TBLMODAL[[NAMA MENU]:[MODAL KEMBALI KE PERUSAHAAN PRODUK OFF LINE]],2,FALSE) -> 5951.9406 | D68: =SUM(TBLKATALOG[[#This Row],[LABA MITRA 5 %]:[LABA KIRIM 5 %]]) -> 595.19406 | E68: =C68+D68 -> 6547.1346 | F68: 8000 | G68: =F68-E68 -> 1452.8654 | H68: =0.05*C68 -> 297.59703 | I68: =0.05*C68 -> 297.59703 | J68: =TBLKATALOG[[#This Row],[HARGA JUAL]]-TBLKATALOG[[#This Row],[MODAL SETELAH DITAMBAH BUDGET KOMISI]] -> 1452.8654

Sheet REKAP BAHAN
A4: NAMA BAHAN | B4: MODAL | C4: ISI | D4: MODAL SATUAN | E4: STOK | F4: MASUK | G4: KELUAR | H4: SISA STOK | I4: NILAI SISA STOK
A5: SAOS TOMAT GRAM | B5: 20000 | C5: 1000 | D5: =TBLREKAPBAHAN[[#This Row],[MODAL]]/TBLREKAPBAHAN[[#This Row],[ISI]] -> 20 | E5: 1000 | F5: =SUMIF(TBLBAHANMASUK[NAMA BAHAN],TBLREKAPBAHAN[[#This Row],[NAMA BAHAN]],TBLBAHANMASUK[MASUK]) -> 2000 | G5: =SUMIF(TBLBAHANKELUAR[NAMA BAHAN],TBLREKAPBAHAN[[#This Row],[NAMA BAHAN]],TBLBAHANKELUAR[TOTAL BAHAN KELUAR]) -> 835 | H5: =TBLREKAPBAHAN[[#This Row],[STOK]]+TBLREKAPBAHAN[[#This Row],[MASUK]]-TBLREKAPBAHAN[[#This Row],[KELUAR]] -> 2165 | I5: =TBLREKAPBAHAN[[#This Row],[MODAL SATUAN]]*TBLREKAPBAHAN[[#This Row],[SISA STOK]] -> 43300
A6: SAOS SAMBAL GRAM | B6: 18000 | C6: 1000 | D6: =TBLREKAPBAHAN[[#This Row],[MODAL]]/TBLREKAPBAHAN[[#This Row],[ISI]] -> 18 | E6: 40 | F6: =SUMIF(TBLBAHANMASUK[NAMA BAHAN],TBLREKAPBAHAN[[#This Row],[NAMA BAHAN]],TBLBAHANMASUK[MASUK]) -> 3000 | G6: =SUMIF(TBLBAHANKELUAR[NAMA BAHAN],TBLREKAPBAHAN[[#This Row],[NAMA BAHAN]],TBLBAHANKELUAR[TOTAL BAHAN KELUAR]) -> 1380 | H6: =TBLREKAPBAHAN[[#This Row],[STOK]]+TBLREKAPBAHAN[[#This Row],[MASUK]]-TBLREKAPBAHAN[[#This Row],[KELUAR]] -> 1660 | I6: =TBLREKAPBAHAN[[#This Row],[MODAL SATUAN]]*TBLREKAPBAHAN[[#This Row],[SISA STOK]] -> 29880
A7: SAOS BBQ GRAM | B7: 12000 | C7: 250 | D7: =TBLREKAPBAHAN[[#This Row],[MODAL]]/TBLREKAPBAHAN[[#This Row],[ISI]] -> 48 | E7: 149 | F7: =SUMIF(TBLBAHANMASUK[NAMA BAHAN],TBLREKAPBAHAN[[#This Row],[NAMA BAHAN]],TBLBAHANMASUK[MASUK]) -> 1000 | G7: =SUMIF(TBLBAHANKELUAR[NAMA BAHAN],TBLREKAPBAHAN[[#This Row],[NAMA BAHAN]],TBLBAHANKELUAR[TOTAL BAHAN KELUAR]) -> 847 | H7: =TBLREKAPBAHAN[[#This Row],[STOK]]+TBLREKAPBAHAN[[#This Row],[MASUK]]-TBLREKAPBAHAN[[#This Row],[KELUAR]] -> 302 | I7: =TBLREKAPBAHAN[[#This Row],[MODAL SATUAN]]*TBLREKAPBAHAN[[#This Row],[SISA STOK]] -> 14496
A8: MAYONAIS GRAM | B8: 50000 | C8: 1000 | D8: =TBLREKAPBAHAN[[#This Row],[MODAL]]/TBLREKAPBAHAN[[#This Row],[ISI]] -> 50 | E8: 903 | F8: =SUMIF(TBLBAHANMASUK[NAMA BAHAN],TBLREKAPBAHAN[[#This Row],[NAMA BAHAN]],TBLBAHANMASUK[MASUK]) -> 2000 | G8: =SUMIF(TBLBAHANKELUAR[NAMA BAHAN],TBLREKAPBAHAN[[#This Row],[NAMA BAHAN]],TBLBAHANKELUAR[TOTAL BAHAN KELUAR]) -> 2270 | H8: =TBLREKAPBAHAN[[#This Row],[STOK]]+TBLREKAPBAHAN[[#This Row],[MASUK]]-TBLREKAPBAHAN[[#This Row],[KELUAR]] -> 633 | I8: =TBLREKAPBAHAN[[#This Row],[MODAL SATUAN]]*TBLREKAPBAHAN[[#This Row],[SISA STOK]] -> 31650
A9: SAOS SPAGHETI GRAM | B9: 12000 | C9: 250 | D9: =TBLREKAPBAHAN[[#This Row],[MODAL]]/TBLREKAPBAHAN[[#This Row],[ISI]] -> 48 | E9: 479 | F9: =SUMIF(TBLBAHANMASUK[NAMA BAHAN],TBLREKAPBAHAN[[#This Row],[NAMA BAHAN]],TBLBAHANMASUK[MASUK]) -> 2250 | G9: =SUMIF(TBLBAHANKELUAR[NAMA BAHAN],TBLREKAPBAHAN[[#This Row],[NAMA BAHAN]],TBLBAHANKELUAR[TOTAL BAHAN KELUAR]) -> 1387 | H9: =TBLREKAPBAHAN[[#This Row],[STOK]]+TBLREKAPBAHAN[[#This Row],[MASUK]]-TBLREKAPBAHAN[[#This Row],[KELUAR]] -> 1342 | I9: =TBLREKAPBAHAN[[#This Row],[MODAL SATUAN]]*TBLREKAPBAHAN[[#This Row],[SISA STOK]] -> 64416
A10: SAOS TOMAT SACHET | B10: 7000 | C10: 24 | D10: =TBLREKAPBAHAN[[#This Row],[MODAL]]/TBLREKAPBAHAN[[#This Row],[ISI]] -> 291.66667 | E10: 84 | F10: =SUMIF(TBLBAHANMASUK[NAMA BAHAN],TBLREKAPBAHAN[[#This Row],[NAMA BAHAN]],TBLBAHANMASUK[MASUK]) -> 48 | G10: =SUMIF(TBLBAHANKELUAR[NAMA BAHAN],TBLREKAPBAHAN[[#This Row],[NAMA BAHAN]],TBLBAHANKELUAR[TOTAL BAHAN KELUAR]) -> 114 | H10: =TBLREKAPBAHAN[[#This Row],[STOK]]+TBLREKAPBAHAN[[#This Row],[MASUK]]-TBLREKAPBAHAN[[#This Row],[KELUAR]] -> 18 | I10: =TBLREKAPBAHAN[[#This Row],[MODAL SATUAN]]*TBLREKAPBAHAN[[#This Row],[SISA STOK]] -> 5250
A11: SAOS SAMBAL SACHET | B11: 8000 | C11: 24 | D11: =TBLREKAPBAHAN[[#This Row],[MODAL]]/TBLREKAPBAHAN[[#This Row],[ISI]] -> 333.33333 | E11: 41 | F11: =SUMIF(TBLBAHANMASUK[NAMA BAHAN],TBLREKAPBAHAN[[#This Row],[NAMA BAHAN]],TBLBAHANMASUK[MASUK]) -> 72 | G11: =SUMIF(TBLBAHANKELUAR[NAMA BAHAN],TBLREKAPBAHAN[[#This Row],[NAMA BAHAN]],TBLBAHANKELUAR[TOTAL BAHAN KELUAR]) -> 74 | H11: =TBLREKAPBAHAN[[#This Row],[STOK]]+TBLREKAPBAHAN[[#This Row],[MASUK]]-TBLREKAPBAHAN[[#This Row],[KELUAR]] -> 39 | I11: =TBLREKAPBAHAN[[#This Row],[MODAL SATUAN]]*TBLREKAPBAHAN[[#This Row],[SISA STOK]] -> 13000
A12: KEJU SLICE MEDIUM SACHET | B12: 16000 | C12: 12 | D12: =TBLREKAPBAHAN[[#This Row],[MODAL]]/TBLREKAPBAHAN[[#This Row],[ISI]] -> 1333.3333 | E12: 27 | F12: =SUMIF(TBLBAHANMASUK[NAMA BAHAN],TBLREKAPBAHAN[[#This Row],[NAMA BAHAN]],TBLBAHANMASUK[MASUK]) -> 22 | G12: =SUMIF(TBLBAHANKELUAR[NAMA BAHAN],TBLREKAPBAHAN[[#This Row],[NAMA BAHAN]],TBLBAHANKELUAR[TOTAL BAHAN KELUAR]) -> 37 | H12: =TBLREKAPBAHAN[[#This Row],[STOK]]+TBLREKAPBAHAN[[#This Row],[MASUK]]-TBLREKAPBAHAN[[#This Row],[KELUAR]] -> 12 | I12: =TBLREKAPBAHAN[[#This Row],[MODAL SATUAN]]*TBLREKAPBAHAN[[#This Row],[SISA STOK]] -> 16000
A13: KEJU MOZZARELLA | B13: 90000 | C13: 500 | D13: =TBLREKAPBAHAN[[#This Row],[MODAL]]/TBLREKAPBAHAN[[#This Row],[ISI]] -> 180 | E13: 6 | F13: =SUMIF(TBLBAHANMASUK[NAMA BAHAN],TBLREKAPBAHAN[[#This Row],[NAMA BAHAN]],TBLBAHANMASUK[MASUK]) -> 1000 | G13: =SUMIF(TBLBAHANKELUAR[NAMA BAHAN],TBLREKAPBAHAN[[#This Row],[NAMA BAHAN]],TBLBAHANKELUAR[TOTAL BAHAN KELUAR]) -> 802 | H13: =TBLREKAPBAHAN[[#This Row],[STOK]]+TBLREKAPBAHAN[[#This Row],[MASUK]]-TBLREKAPBAHAN[[#This Row],[KELUAR]] -> 204 | I13: =TBLREKAPBAHAN[[#This Row],[MODAL SATUAN]]*TBLREKAPBAHAN[[#This Row],[SISA STOK]] -> 36720
A14: NUGGET AYAM | B14: 22000 | C14: 6 | D14: =TBLREKAPBAHAN[[#This Row],[MODAL]]/TBLREKAPBAHAN[[#This Row],[ISI]] -> 3666.6667 | E14: 0 | F14: =SUMIF(TBLBAHANMASUK[NAMA BAHAN],TBLREKAPBAHAN[[#This Row],[NAMA BAHAN]],TBLBAHANMASUK[MASUK]) -> 0 | G14: =SUMIF(TBLBAHANKELUAR[NAMA BAHAN],TBLREKAPBAHAN[[#This Row],[NAMA BAHAN]],TBLBAHANKELUAR[TOTAL BAHAN KELUAR]) -> 0 | H14: =TBLREKAPBAHAN[[#This Row],[STOK]]+TBLREKAPBAHAN[[#This Row],[MASUK]]-TBLREKAPBAHAN[[#This Row],[KELUAR]] -> 0 | I14: =TBLREKAPBAHAN[[#This Row],[MODAL SATUAN]]*TBLREKAPBAHAN[[#This Row],[SISA STOK]] -> 0
A15: SOSIZ BATANG | B15: 35000 | C15: 38 | D15: =TBLREKAPBAHAN[[#This Row],[MODAL]]/TBLREKAPBAHAN[[#This Row],[ISI]] -> 921.05263 | E15: 7 | F15: =SUMIF(TBLBAHANMASUK[NAMA BAHAN],TBLREKAPBAHAN[[#This Row],[NAMA BAHAN]],TBLBAHANMASUK[MASUK]) -> 192 | G15: =SUMIF(TBLBAHANKELUAR[NAMA BAHAN],TBLREKAPBAHAN[[#This Row],[NAMA BAHAN]],TBLBAHANKELUAR[TOTAL BAHAN KELUAR]) -> 141 | H15: =TBLREKAPBAHAN[[#This Row],[STOK]]+TBLREKAPBAHAN[[#This Row],[MASUK]]-TBLREKAPBAHAN[[#This Row],[KELUAR]] -> 58 | I15: =TBLREKAPBAHAN[[#This Row],[MODAL SATUAN]]*TBLREKAPBAHAN[[#This Row],[SISA STOK]] -> 53421.053
A16: AYAM SUWIR | B16: 45000 | C16: 400 | D16: =TBLREKAPBAHAN[[#This Row],[MODAL]]/TBLREKAPBAHAN[[#This Row],[ISI]] -> 112.5 | E16: 1593 | F16: =SUMIF(TBLBAHANMASUK[NAMA BAHAN],TBLREKAPBAHAN[[#This Row],[NAMA BAHAN]],TBLBAHANMASUK[MASUK]) -> 2800 | G16: =SUMIF(TBLBAHANKELUAR[NAMA BAHAN],TBLREKAPBAHAN[[#This Row],[NAMA BAHAN]],TBLBAHANKELUAR[TOTAL BAHAN KELUAR]) -> 3943 | H16: =TBLREKAPBAHAN[[#This Row],[STOK]]+TBLREKAPBAHAN[[#This Row],[MASUK]]-TBLREKAPBAHAN[[#This Row],[KELUAR]] -> 450 | I16: =TBLREKAPBAHAN[[#This Row],[MODAL SATUAN]]*TBLREKAPBAHAN[[#This Row],[SISA STOK]] -> 50625
... A71: PERASA JAGUNG MANIS | B71: 5500 | C71: 100 | D71: =TBLREKAPBAHAN[[#This Row],[MODAL]]/TBLREKAPBAHAN[[#This Row],[ISI]] -> 55 | E71: 0 | F71: =SUMIF(TBLBAHANMASUK[NAMA BAHAN],TBLREKAPBAHAN[[#This Row],[NAMA BAHAN]],TBLBAHANMASUK[MASUK]) -> 100 | G71: =SUMIF(TBLBAHANKELUAR[NAMA BAHAN],TBLREKAPBAHAN[[#This Row],[NAMA BAHAN]],TBLBAHANKELUAR[TOTAL BAHAN KELUAR]) -> 0 | H71: =TBLREKAPBAHAN[[#This Row],[STOK]]+TBLREKAPBAHAN[[#This Row],[MASUK]]-TBLREKAPBAHAN[[#This Row],[KELUAR]] -> 100 | I71: =TBLREKAPBAHAN[[#This Row],[MODAL SATUAN]]*TBLREKAPBAHAN[[#This Row],[SISA STOK]] -> 5500

Sheet DATA BAHAN MASUK
A1: CASH VALUE DAN LABA
A2: CAHYA GALLERY FOOD & BEVERAGE
A4: TAHUN | B4: BULAN | C4: TANGGAL | D4: NAMA BAHAN | E4: MODAL | F4: ISI | G4: MODAL SATUAN | H4: MASUK | I4: NILAI MASUK | J4: HARGA ASLI | K4: QTY | L4: MODAL ASLI | M4: QTY MASUK | N4: NILAI MASUK ASLI | O4: CASHBACK BELANJA
A5: 2026 | B5: JUNI | C5: 46190 | D5: SAOS SAMBAL GRAM | E5: =VLOOKUP(TBLBAHANMASUK[[#This Row],[NAMA BAHAN]],TBLREKAPBAHAN[[NAMA BAHAN]:[MODAL SATUAN]],2,FALSE) -> 18000 | F5: =VLOOKUP(TBLBAHANMASUK[[#This Row],[NAMA BAHAN]],TBLREKAPBAHAN[[NAMA BAHAN]:[MODAL SATUAN]],3,FALSE) -> 1000 | G5: =VLOOKUP(TBLBAHANMASUK[[#This Row],[NAMA BAHAN]],TBLREKAPBAHAN[[NAMA BAHAN]:[MODAL SATUAN]],4,FALSE) -> 18 | H5: 1000 | I5: =TBLBAHANMASUK[[#This Row],[MODAL SATUAN]]*TBLBAHANMASUK[[#This Row],[MASUK]] -> 18000 | J5: 17500 | K5: =TBLBAHANMASUK[[#This Row],[ISI]] -> 1000 | L5: =TBLBAHANMASUK[[#This Row],[HARGA ASLI]]/TBLBAHANMASUK[[#This Row],[QTY]] -> 17.5 | M5: =TBLBAHANMASUK[[#This Row],[MASUK]] -> 1000 | N5: =TBLBAHANMASUK[[#This Row],[MODAL ASLI]]*TBLBAHANMASUK[[#This Row],[QTY MASUK]] -> 17500 | O5: =TBLBAHANMASUK[[#This Row],[NILAI MASUK]]-TBLBAHANMASUK[[#This Row],[NILAI MASUK ASLI]] -> 500
A6: 2026 | B6: JUNI | C6: 46190 | D6: SAOS TOMAT SACHET | E6: =VLOOKUP(TBLBAHANMASUK[[#This Row],[NAMA BAHAN]],TBLREKAPBAHAN[[NAMA BAHAN]:[MODAL SATUAN]],2,FALSE) -> 7000 | F6: =VLOOKUP(TBLBAHANMASUK[[#This Row],[NAMA BAHAN]],TBLREKAPBAHAN[[NAMA BAHAN]:[MODAL SATUAN]],3,FALSE) -> 24 | G6: =VLOOKUP(TBLBAHANMASUK[[#This Row],[NAMA BAHAN]],TBLREKAPBAHAN[[NAMA BAHAN]:[MODAL SATUAN]],4,FALSE) -> 291.66667 | H6: 24 | I6: =TBLBAHANMASUK[[#This Row],[MODAL SATUAN]]*TBLBAHANMASUK[[#This Row],[MASUK]] -> 7000 | J6: 6900 | K6: =TBLBAHANMASUK[[#This Row],[ISI]] -> 24 | L6: =TBLBAHANMASUK[[#This Row],[HARGA ASLI]]/TBLBAHANMASUK[[#This Row],[QTY]] -> 287.5 | M6: =TBLBAHANMASUK[[#This Row],[MASUK]] -> 24 | N6: =TBLBAHANMASUK[[#This Row],[MODAL ASLI]]*TBLBAHANMASUK[[#This Row],[QTY MASUK]] -> 6900 | O6: =TBLBAHANMASUK[[#This Row],[NILAI MASUK]]-TBLBAHANMASUK[[#This Row],[NILAI MASUK ASLI]] -> 100
A7: 2026 | B7: JUNI | C7: 46190 | D7: SAOS SPAGHETI GRAM | E7: =VLOOKUP(TBLBAHANMASUK[[#This Row],[NAMA BAHAN]],TBLREKAPBAHAN[[NAMA BAHAN]:[MODAL SATUAN]],2,FALSE) -> 12000 | F7: =VLOOKUP(TBLBAHANMASUK[[#This Row],[NAMA BAHAN]],TBLREKAPBAHAN[[NAMA BAHAN]:[MODAL SATUAN]],3,FALSE) -> 250 | G7: =VLOOKUP(TBLBAHANMASUK[[#This Row],[NAMA BAHAN]],TBLREKAPBAHAN[[NAMA BAHAN]:[MODAL SATUAN]],4,FALSE) -> 48 | H7: 500 | I7: =TBLBAHANMASUK[[#This Row],[MODAL SATUAN]]*TBLBAHANMASUK[[#This Row],[MASUK]] -> 24000 | J7: 9800 | K7: =TBLBAHANMASUK[[#This Row],[ISI]] -> 250 | L7: =TBLBAHANMASUK[[#This Row],[HARGA ASLI]]/TBLBAHANMASUK[[#This Row],[QTY]] -> 39.2 | M7: =TBLBAHANMASUK[[#This Row],[MASUK]] -> 500 | N7: =TBLBAHANMASUK[[#This Row],[MODAL ASLI]]*TBLBAHANMASUK[[#This Row],[QTY MASUK]] -> 19600 | O7: =TBLBAHANMASUK[[#This Row],[NILAI MASUK]]-TBLBAHANMASUK[[#This Row],[NILAI MASUK ASLI]] -> 4400
A8: 2026 | B8: JUNI | C8: 46190 | D8: SAOS BBQ GRAM | E8: =VLOOKUP(TBLBAHANMASUK[[#This Row],[NAMA BAHAN]],TBLREKAPBAHAN[[NAMA BAHAN]:[MODAL SATUAN]],2,FALSE) -> 12000 | F8: =VLOOKUP(TBLBAHANMASUK[[#This Row],[NAMA BAHAN]],TBLREKAPBAHAN[[NAMA BAHAN]:[MODAL SATUAN]],3,FALSE) -> 250 | G8: =VLOOKUP(TBLBAHANMASUK[[#This Row],[NAMA BAHAN]],TBLREKAPBAHAN[[NAMA BAHAN]:[MODAL SATUAN]],4,FALSE) -> 48 | H8: 500 | I8: =TBLBAHANMASUK[[#This Row],[MODAL SATUAN]]*TBLBAHANMASUK[[#This Row],[MASUK]] -> 24000 | J8: 10950 | K8: =TBLBAHANMASUK[[#This Row],[ISI]] -> 250 | L8: =TBLBAHANMASUK[[#This Row],[HARGA ASLI]]/TBLBAHANMASUK[[#This Row],[QTY]] -> 43.8 | M8: =TBLBAHANMASUK[[#This Row],[MASUK]] -> 500 | N8: =TBLBAHANMASUK[[#This Row],[MODAL ASLI]]*TBLBAHANMASUK[[#This Row],[QTY MASUK]] -> 21900 | O8: =TBLBAHANMASUK[[#This Row],[NILAI MASUK]]-TBLBAHANMASUK[[#This Row],[NILAI MASUK ASLI]] -> 2100
A9: 2026 | B9: JUNI | C9: 46190 | D9: MAYONAIS GRAM | E9: =VLOOKUP(TBLBAHANMASUK[[#This Row],[NAMA BAHAN]],TBLREKAPBAHAN[[NAMA BAHAN]:[MODAL SATUAN]],2,FALSE) -> 50000 | F9: =VLOOKUP(TBLBAHANMASUK[[#This Row],[NAMA BAHAN]],TBLREKAPBAHAN[[NAMA BAHAN]:[MODAL SATUAN]],3,FALSE) -> 1000 | G9: =VLOOKUP(TBLBAHANMASUK[[#This Row],[NAMA BAHAN]],TBLREKAPBAHAN[[NAMA BAHAN]:[MODAL SATUAN]],4,FALSE) -> 50 | H9: 1000 | I9: =TBLBAHANMASUK[[#This Row],[MODAL SATUAN]]*TBLBAHANMASUK[[#This Row],[MASUK]] -> 50000 | J9: 32000 | K9: =TBLBAHANMASUK[[#This Row],[ISI]] -> 1000 | L9: =TBLBAHANMASUK[[#This Row],[HARGA ASLI]]/TBLBAHANMASUK[[#This Row],[QTY]] -> 32 | M9: =TBLBAHANMASUK[[#This Row],[MASUK]] -> 1000 | N9: =TBLBAHANMASUK[[#This Row],[MODAL ASLI]]*TBLBAHANMASUK[[#This Row],[QTY MASUK]] -> 32000 | O9: =TBLBAHANMASUK[[#This Row],[NILAI MASUK]]-TBLBAHANMASUK[[#This Row],[NILAI MASUK ASLI]] -> 18000
A10: 2026 | B10: JUNI | C10: 46190 | D10: KULIT KEBAB 17/18 CM | E10: =VLOOKUP(TBLBAHANMASUK[[#This Row],[NAMA BAHAN]],TBLREKAPBAHAN[[NAMA BAHAN]:[MODAL SATUAN]],2,FALSE) -> 27000 | F10: =VLOOKUP(TBLBAHANMASUK[[#This Row],[NAMA BAHAN]],TBLREKAPBAHAN[[NAMA BAHAN]:[MODAL SATUAN]],3,FALSE) -> 20 | G10: =VLOOKUP(TBLBAHANMASUK[[#This Row],[NAMA BAHAN]],TBLREKAPBAHAN[[NAMA BAHAN]:[MODAL SATUAN]],4,FALSE) -> 1350 | H10: 20 | I10: =TBLBAHANMASUK[[#This Row],[MODAL SATUAN]]*TBLBAHANMASUK[[#This Row],[MASUK]] -> 27000 | J10: 26000 | K10: =TBLBAHANMASUK[[#This Row],[ISI]] -> 20 | L10: =TBLBAHANMASUK[[#This Row],[HARGA ASLI]]/TBLBAHANMASUK[[#This Row],[QTY]] -> 1300 | M10: =TBLBAHANMASUK[[#This Row],[MASUK]] -> 20 | N10: =TBLBAHANMASUK[[#This Row],[MODAL ASLI]]*TBLBAHANMASUK[[#This Row],[QTY MASUK]] -> 26000 | O10: =TBLBAHANMASUK[[#This Row],[NILAI MASUK]]-TBLBAHANMASUK[[#This Row],[NILAI MASUK ASLI]] -> 1000
A11: 2026 | B11: JUNI | C11: 46190 | D11: KULIT KEBAB 19/20 CM | E11: =VLOOKUP(TBLBAHANMASUK[[#This Row],[NAMA BAHAN]],TBLREKAPBAHAN[[NAMA BAHAN]:[MODAL SATUAN]],2,FALSE) -> 29000 | F11: =VLOOKUP(TBLBAHANMASUK[[#This Row],[NAMA BAHAN]],TBLREKAPBAHAN[[NAMA BAHAN]:[MODAL SATUAN]],3,FALSE) -> 20 | G11: =VLOOKUP(TBLBAHANMASUK[[#This Row],[NAMA BAHAN]],TBLREKAPBAHAN[[NAMA BAHAN]:[MODAL SATUAN]],4,FALSE) -> 1450 | H11: 20 | I11: =TBLBAHANMASUK[[#This Row],[MODAL SATUAN]]*TBLBAHANMASUK[[#This Row],[MASUK]] -> 29000 | J11: 28500 | K11: =TBLBAHANMASUK[[#This Row],[ISI]] -> 20 | L11: =TBLBAHANMASUK[[#This Row],[HARGA ASLI]]/TBLBAHANMASUK[[#This Row],[QTY]] -> 1425 | M11: =TBLBAHANMASUK[[#This Row],[MASUK]] -> 20 | N11: =TBLBAHANMASUK[[#This Row],[MODAL ASLI]]*TBLBAHANMASUK[[#This Row],[QTY MASUK]] -> 28500 | O11: =TBLBAHANMASUK[[#This Row],[NILAI MASUK]]-TBLBAHANMASUK[[#This Row],[NILAI MASUK ASLI]] -> 500
A12: 2026 | B12: JUNI | C12: 46190 | D12: ROTI MARYAM | E12: =VLOOKUP(TBLBAHANMASUK[[#This Row],[NAMA BAHAN]],TBLREKAPBAHAN[[NAMA BAHAN]:[MODAL SATUAN]],2,FALSE) -> 20000 | F12: =VLOOKUP(TBLBAHANMASUK[[#This Row],[NAMA BAHAN]],TBLREKAPBAHAN[[NAMA BAHAN]:[MODAL SATUAN]],3,FALSE) -> 10 | G12: =VLOOKUP(TBLBAHANMASUK[[#This Row],[NAMA BAHAN]],TBLREKAPBAHAN[[NAMA BAHAN]:[MODAL SATUAN]],4,FALSE) -> 2000 | H12: 10 | I12: =TBLBAHANMASUK[[#This Row],[MODAL SATUAN]]*TBLBAHANMASUK[[#This Row],[MASUK]] -> 20000 | J12: 18500 | K12: =TBLBAHANMASUK[[#This Row],[ISI]] -> 10 | L12: =TBLBAHANMASUK[[#This Row],[HARGA ASLI]]/TBLBAHANMASUK[[#This Row],[QTY]] -> 1850 | M12: =TBLBAHANMASUK[[#This Row],[MASUK]] -> 10 | N12: =TBLBAHANMASUK[[#This Row],[MODAL ASLI]]*TBLBAHANMASUK[[#This Row],[QTY MASUK]] -> 18500 | O12: =TBLBAHANMASUK[[#This Row],[NILAI MASUK]]-TBLBAHANMASUK[[#This Row],[NILAI MASUK ASLI]] -> 1500
A13: 2026 | B13: JUNI | C13: 46190 | D13: ROTI BURGER MEDIUM | E13: =VLOOKUP(TBLBAHANMASUK[[#This Row],[NAMA BAHAN]],TBLREKAPBAHAN[[NAMA BAHAN]:[MODAL SATUAN]],2,FALSE) -> 15000 | F13: =VLOOKUP(TBLBAHANMASUK[[#This Row],[NAMA BAHAN]],TBLREKAPBAHAN[[NAMA BAHAN]:[MODAL SATUAN]],3,FALSE) -> 6 | G13: =VLOOKUP(TBLBAHANMASUK[[#This Row],[NAMA BAHAN]],TBLREKAPBAHAN[[NAMA BAHAN]:[MODAL SATUAN]],4,FALSE) -> 2500 | H13: 6 | I13: =TBLBAHANMASUK[[#This Row],[MODAL SATUAN]]*TBLBAHANMASUK[[#This Row],[MASUK]] -> 15000 | J13: 14500 | K13: =TBLBAHANMASUK[[#This Row],[ISI]] -> 6 | L13: =TBLBAHANMASUK[[#This Row],[HARGA ASLI]]/TBLBAHANMASUK[[#This Row],[QTY]] -> 2416.6667 | M13: =TBLBAHANMASUK[[#This Row],[MASUK]] -> 6 | N13: =TBLBAHANMASUK[[#This Row],[MODAL ASLI]]*TBLBAHANMASUK[[#This Row],[QTY MASUK]] -> 14500 | O13: =TBLBAHANMASUK[[#This Row],[NILAI MASUK]]-TBLBAHANMASUK[[#This Row],[NILAI MASUK ASLI]] -> 500
A14: 2026 | B14: JUNI | C14: 46190 | D14: DAGING SAPI | E14: =VLOOKUP(TBLBAHANMASUK[[#This Row],[NAMA BAHAN]],TBLREKAPBAHAN[[NAMA BAHAN]:[MODAL SATUAN]],2,FALSE) -> 85000 | F14: =VLOOKUP(TBLBAHANMASUK[[#This Row],[NAMA BAHAN]],TBLREKAPBAHAN[[NAMA BAHAN]:[MODAL SATUAN]],3,FALSE) -> 1000 | G14: =VLOOKUP(TBLBAHANMASUK[[#This Row],[NAMA BAHAN]],TBLREKAPBAHAN[[NAMA BAHAN]:[MODAL SATUAN]],4,FALSE) -> 85 | H14: 1000 | I14: =TBLBAHANMASUK[[#This Row],[MODAL SATUAN]]*TBLBAHANMASUK[[#This Row],[MASUK]] -> 85000 | J14: 79900 | K14: =TBLBAHANMASUK[[#This Row],[ISI]] -> 1000 | L14: =TBLBAHANMASUK[[#This Row],[HARGA ASLI]]/TBLBAHANMASUK[[#This Row],[QTY]] -> 79.9 | M14: =TBLBAHANMASUK[[#This Row],[MASUK]] -> 1000 | N14: =TBLBAHANMASUK[[#This Row],[MODAL ASLI]]*TBLBAHANMASUK[[#This Row],[QTY MASUK]] -> 79900 | O14: =TBLBAHANMASUK[[#This Row],[NILAI MASUK]]-TBLBAHANMASUK[[#This Row],[NILAI MASUK ASLI]] -> 5100
A15: 2026 | B15: JUNI | C15: 46190 | D15: SLADA | E15: =VLOOKUP(TBLBAHANMASUK[[#This Row],[NAMA BAHAN]],TBLREKAPBAHAN[[NAMA BAHAN]:[MODAL SATUAN]],2,FALSE) -> 60000 | F15: =VLOOKUP(TBLBAHANMASUK[[#This Row],[NAMA BAHAN]],TBLREKAPBAHAN[[NAMA BAHAN]:[MODAL SATUAN]],3,FALSE) -> 50 | G15: =VLOOKUP(TBLBAHANMASUK[[#This Row],[NAMA BAHAN]],TBLREKAPBAHAN[[NAMA BAHAN]:[MODAL SATUAN]],4,FALSE) -> 1200 | H15: 50 | I15: =TBLBAHANMASUK[[#This Row],[MODAL SATUAN]]*TBLBAHANMASUK[[#This Row],[MASUK]] -> 60000 | J15: 50000 | K15: =TBLBAHANMASUK[[#This Row],[ISI]] -> 50 | L15: =TBLBAHANMASUK[[#This Row],[HARGA ASLI]]/TBLBAHANMASUK[[#This Row],[QTY]] -> 1000 | M15: =TBLBAHANMASUK[[#This Row],[MASUK]] -> 50 | N15: =TBLBAHANMASUK[[#This Row],[MODAL ASLI]]*TBLBAHANMASUK[[#This Row],[QTY MASUK]] -> 50000 | O15: =TBLBAHANMASUK[[#This Row],[NILAI MASUK]]-TBLBAHANMASUK[[#This Row],[NILAI MASUK ASLI]] -> 10000
A16: 2026 | B16: JUNI | C16: 46190 | D16: KEJU MOZZARELLA | E16: =VLOOKUP(TBLBAHANMASUK[[#This Row],[NAMA BAHAN]],TBLREKAPBAHAN[[NAMA BAHAN]:[MODAL SATUAN]],2,FALSE) -> 90000 | F16: =VLOOKUP(TBLBAHANMASUK[[#This Row],[NAMA BAHAN]],TBLREKAPBAHAN[[NAMA BAHAN]:[MODAL SATUAN]],3,FALSE) -> 500 | G16: =VLOOKUP(TBLBAHANMASUK[[#This Row],[NAMA BAHAN]],TBLREKAPBAHAN[[NAMA BAHAN]:[MODAL SATUAN]],4,FALSE) -> 180 | H16: 500 | I16: =TBLBAHANMASUK[[#This Row],[MODAL SATUAN]]*TBLBAHANMASUK[[#This Row],[MASUK]] -> 90000 | J16: 88000 | K16: =TBLBAHANMASUK[[#This Row],[ISI]] -> 500 | L16: =TBLBAHANMASUK[[#This Row],[HARGA ASLI]]/TBLBAHANMASUK[[#This Row],[QTY]] -> 176 | M16: =TBLBAHANMASUK[[#This Row],[MASUK]] -> 500 | N16: =TBLBAHANMASUK[[#This Row],[MODAL ASLI]]*TBLBAHANMASUK[[#This Row],[QTY MASUK]] -> 88000 | O16: =TBLBAHANMASUK[[#This Row],[NILAI MASUK]]-TBLBAHANMASUK[[#This Row],[NILAI MASUK ASLI]] -> 2000
... A74: 2026 | B74: JULI | C74: 46228 | D74: JAGUNG | E74: =VLOOKUP(TBLBAHANMASUK[[#This Row],[NAMA BAHAN]],TBLREKAPBAHAN[[NAMA BAHAN]:[MODAL SATUAN]],2,FALSE) -> 3000 | F74: =VLOOKUP(TBLBAHANMASUK[[#This Row],[NAMA BAHAN]],TBLREKAPBAHAN[[NAMA BAHAN]:[MODAL SATUAN]],3,FALSE) -> 2 | G74: =VLOOKUP(TBLBAHANMASUK[[#This Row],[NAMA BAHAN]],TBLREKAPBAHAN[[NAMA BAHAN]:[MODAL SATUAN]],4,FALSE) -> 1500 | H74: 1 | I74: =TBLBAHANMASUK[[#This Row],[MODAL SATUAN]]*TBLBAHANMASUK[[#This Row],[MASUK]] -> 1500 | J74: 4000 | K74: =TBLBAHANMASUK[[#This Row],[ISI]] -> 2 | L74: =TBLBAHANMASUK[[#This Row],[HARGA ASLI]]/TBLBAHANMASUK[[#This Row],[QTY]] -> 2000 | M74: =TBLBAHANMASUK[[#This Row],[MASUK]] -> 1 | N74: =TBLBAHANMASUK[[#This Row],[MODAL ASLI]]*TBLBAHANMASUK[[#This Row],[QTY MASUK]] -> 2000 | O74: =TBLBAHANMASUK[[#This Row],[NILAI MASUK]]-TBLBAHANMASUK[[#This Row],[NILAI MASUK ASLI]] -> -500

Sheet DATA BAHAN KELUAR
G1: CASH VALUE DAN LABA
G2: CAHYA GALLERY FOOD & BEVERAGE
E5: WAJIB DIISI MANUAL BY DATA VALIDATION UNTUK MENAUTKAN JUMLAH PRODUK KELUAR | F5: KODE BAHAN WAJIB DIISI MANUAL UNTUK MENAMPILKAN NAMA BAHAN DAN KEBUTUHAN BAHAN | G5: INGAT! SETIAP GANTI MENU/PRODUK MAKA NAMA PRODUK YG ADA DI DALAM RUMUS HARUS DIEDIT/DIGANTI | K5: INGAT! SETIAP GANTI MENU/PRODUK MAKA NAMA PRODUK YG ADA DI DALAM RUMUS HARUS DIEDIT/DIGANTI | L5: INI AKAN TERISI OTOMATIS KETIKA JUMLAH PRODUK KELUAR PADA SHEET PRODUK KELUAR TELAH DIISI (PERHATIKAN BULAN KELUAR NYA)
A6: TAHUN | B6: BULAN | C6: PEKAN | D6: TANGGAL | E6: NAMA PRODUK | F6: KODE BAHAN | G6: NAMA BAHAN | H6: MODAL | I6: ISI | J6: MODAL SATUAN | K6: KEB. BAHAN | L6: JUMLAH KEB. BAHAN KELUAR | M6: TOTAL BAHAN KELUAR | N6: NILAI BAHAN KELUAR
A7: 2026 | B7: JUNI | E7: KEBAB AYAM + SOSIZ (KECIL) | F7: 1 | G7: =VLOOKUP(TBLBAHANKELUAR[[#This Row],[KODE BAHAN]],[4]!TBLKEBABSOSYAMKECIL[#Data],2,FALSE) -> SAOS TOMAT GRAM | H7: =VLOOKUP(TBLBAHANKELUAR[[#This Row],[NAMA BAHAN]],TBLREKAPBAHAN[[NAMA BAHAN]:[MODAL SATUAN]],2,FALSE) -> 20000 | I7: =VLOOKUP(TBLBAHANKELUAR[[#This Row],[NAMA BAHAN]],TBLREKAPBAHAN[[NAMA BAHAN]:[MODAL SATUAN]],3,FALSE) -> 1000 | J7: =VLOOKUP(TBLBAHANKELUAR[[#This Row],[NAMA BAHAN]],TBLREKAPBAHAN[[NAMA BAHAN]:[MODAL SATUAN]],4,FALSE) -> 20 | K7: =VLOOKUP(TBLBAHANKELUAR[[#This Row],[KODE BAHAN]],[4]!TBLKEBABSOSYAMKECIL[#Data],8,FALSE) -> 10 | L7: =SUMIF(TBLPRODUKKELUARJUNI[NAMA PRODUK],TBLBAHANKELUAR[[#This Row],[NAMA PRODUK]],TBLPRODUKKELUARJUNI[JUMLAH TERJUAL]) -> 2 | M7: =TBLBAHANKELUAR[[#This Row],[KEB. BAHAN]]*TBLBAHANKELUAR[[#This Row],[JUMLAH KEB. BAHAN KELUAR]] -> 20 | N7: =TBLBAHANKELUAR[[#This Row],[MODAL SATUAN]]*TBLBAHANKELUAR[[#This Row],[TOTAL BAHAN KELUAR]] -> 400
A8: 2026 | B8: JUNI | E8: KEBAB AYAM + SOSIZ (KECIL) | F8: 2 | G8: =VLOOKUP(TBLBAHANKELUAR[[#This Row],[KODE BAHAN]],[4]!TBLKEBABSOSYAMKECIL[#Data],2,FALSE) -> SAOS SAMBAL GRAM | H8: =VLOOKUP(TBLBAHANKELUAR[[#This Row],[NAMA BAHAN]],TBLREKAPBAHAN[[NAMA BAHAN]:[MODAL SATUAN]],2,FALSE) -> 18000 | I8: =VLOOKUP(TBLBAHANKELUAR[[#This Row],[NAMA BAHAN]],TBLREKAPBAHAN[[NAMA BAHAN]:[MODAL SATUAN]],3,FALSE) -> 1000 | J8: =VLOOKUP(TBLBAHANKELUAR[[#This Row],[NAMA BAHAN]],TBLREKAPBAHAN[[NAMA BAHAN]:[MODAL SATUAN]],4,FALSE) -> 18 | K8: =VLOOKUP(TBLBAHANKELUAR[[#This Row],[KODE BAHAN]],[4]!TBLKEBABSOSYAMKECIL[#Data],8,FALSE) -> 0 | L8: =SUMIF(TBLPRODUKKELUARJUNI[NAMA PRODUK],TBLBAHANKELUAR[[#This Row],[NAMA PRODUK]],TBLPRODUKKELUARJUNI[JUMLAH TERJUAL]) -> 2 | M8: =TBLBAHANKELUAR[[#This Row],[KEB. BAHAN]]*TBLBAHANKELUAR[[#This Row],[JUMLAH KEB. BAHAN KELUAR]] -> 0 | N8: =TBLBAHANKELUAR[[#This Row],[MODAL SATUAN]]*TBLBAHANKELUAR[[#This Row],[TOTAL BAHAN KELUAR]] -> 0
A9: 2026 | B9: JUNI | E9: KEBAB AYAM + SOSIZ (KECIL) | F9: 3 | G9: =VLOOKUP(TBLBAHANKELUAR[[#This Row],[KODE BAHAN]],[4]!TBLKEBABSOSYAMKECIL[#Data],2,FALSE) -> SAOS BBQ GRAM | H9: =VLOOKUP(TBLBAHANKELUAR[[#This Row],[NAMA BAHAN]],TBLREKAPBAHAN[[NAMA BAHAN]:[MODAL SATUAN]],2,FALSE) -> 12000 | I9: =VLOOKUP(TBLBAHANKELUAR[[#This Row],[NAMA BAHAN]],TBLREKAPBAHAN[[NAMA BAHAN]:[MODAL SATUAN]],3,FALSE) -> 250 | J9: =VLOOKUP(TBLBAHANKELUAR[[#This Row],[NAMA BAHAN]],TBLREKAPBAHAN[[NAMA BAHAN]:[MODAL SATUAN]],4,FALSE) -> 48 | K9: =VLOOKUP(TBLBAHANKELUAR[[#This Row],[KODE BAHAN]],[4]!TBLKEBABSOSYAMKECIL[#Data],8,FALSE) -> 5 | L9: =SUMIF(TBLPRODUKKELUARJUNI[NAMA PRODUK],TBLBAHANKELUAR[[#This Row],[NAMA PRODUK]],TBLPRODUKKELUARJUNI[JUMLAH TERJUAL]) -> 2 | M9: =TBLBAHANKELUAR[[#This Row],[KEB. BAHAN]]*TBLBAHANKELUAR[[#This Row],[JUMLAH KEB. BAHAN KELUAR]] -> 10 | N9: =TBLBAHANKELUAR[[#This Row],[MODAL SATUAN]]*TBLBAHANKELUAR[[#This Row],[TOTAL BAHAN KELUAR]] -> 480
A10: 2026 | B10: JUNI | E10: KEBAB AYAM + SOSIZ (KECIL) | F10: 4 | G10: =VLOOKUP(TBLBAHANKELUAR[[#This Row],[KODE BAHAN]],[4]!TBLKEBABSOSYAMKECIL[#Data],2,FALSE) -> MAYONAIS GRAM | H10: =VLOOKUP(TBLBAHANKELUAR[[#This Row],[NAMA BAHAN]],TBLREKAPBAHAN[[NAMA BAHAN]:[MODAL SATUAN]],2,FALSE) -> 50000 | I10: =VLOOKUP(TBLBAHANKELUAR[[#This Row],[NAMA BAHAN]],TBLREKAPBAHAN[[NAMA BAHAN]:[MODAL SATUAN]],3,FALSE) -> 1000 | J10: =VLOOKUP(TBLBAHANKELUAR[[#This Row],[NAMA BAHAN]],TBLREKAPBAHAN[[NAMA BAHAN]:[MODAL SATUAN]],4,FALSE) -> 50 | K10: =VLOOKUP(TBLBAHANKELUAR[[#This Row],[KODE BAHAN]],[4]!TBLKEBABSOSYAMKECIL[#Data],8,FALSE) -> 7 | L10: =SUMIF(TBLPRODUKKELUARJUNI[NAMA PRODUK],TBLBAHANKELUAR[[#This Row],[NAMA PRODUK]],TBLPRODUKKELUARJUNI[JUMLAH TERJUAL]) -> 2 | M10: =TBLBAHANKELUAR[[#This Row],[KEB. BAHAN]]*TBLBAHANKELUAR[[#This Row],[JUMLAH KEB. BAHAN KELUAR]] -> 14 | N10: =TBLBAHANKELUAR[[#This Row],[MODAL SATUAN]]*TBLBAHANKELUAR[[#This Row],[TOTAL BAHAN KELUAR]] -> 700
A11: 2026 | B11: JUNI | E11: KEBAB AYAM + SOSIZ (KECIL) | F11: 5 | G11: =VLOOKUP(TBLBAHANKELUAR[[#This Row],[KODE BAHAN]],[4]!TBLKEBABSOSYAMKECIL[#Data],2,FALSE) -> SAOS SPAGHETI GRAM | H11: =VLOOKUP(TBLBAHANKELUAR[[#This Row],[NAMA BAHAN]],TBLREKAPBAHAN[[NAMA BAHAN]:[MODAL SATUAN]],2,FALSE) -> 12000 | I11: =VLOOKUP(TBLBAHANKELUAR[[#This Row],[NAMA BAHAN]],TBLREKAPBAHAN[[NAMA BAHAN]:[MODAL SATUAN]],3,FALSE) -> 250 | J11: =VLOOKUP(TBLBAHANKELUAR[[#This Row],[NAMA BAHAN]],TBLREKAPBAHAN[[NAMA BAHAN]:[MODAL SATUAN]],4,FALSE) -> 48 | K11: =VLOOKUP(TBLBAHANKELUAR[[#This Row],[KODE BAHAN]],[4]!TBLKEBABSOSYAMKECIL[#Data],8,FALSE) -> 5 | L11: =SUMIF(TBLPRODUKKELUARJUNI[NAMA PRODUK],TBLBAHANKELUAR[[#This Row],[NAMA PRODUK]],TBLPRODUKKELUARJUNI[JUMLAH TERJUAL]) -> 2 | M11: =TBLBAHANKELUAR[[#This Row],[KEB. BAHAN]]*TBLBAHANKELUAR[[#This Row],[JUMLAH KEB. BAHAN KELUAR]] -> 10 | N11: =TBLBAHANKELUAR[[#This Row],[MODAL SATUAN]]*TBLBAHANKELUAR[[#This Row],[TOTAL BAHAN KELUAR]] -> 480
A12: 2026 | B12: JUNI | E12: KEBAB AYAM + SOSIZ (KECIL) | F12: 6 | G12: =VLOOKUP(TBLBAHANKELUAR[[#This Row],[KODE BAHAN]],[4]!TBLKEBABSOSYAMKECIL[#Data],2,FALSE) -> SOSIZ BATANG | H12: =VLOOKUP(TBLBAHANKELUAR[[#This Row],[NAMA BAHAN]],TBLREKAPBAHAN[[NAMA BAHAN]:[MODAL SATUAN]],2,FALSE) -> 35000 | I12: =VLOOKUP(TBLBAHANKELUAR[[#This Row],[NAMA BAHAN]],TBLREKAPBAHAN[[NAMA BAHAN]:[MODAL SATUAN]],3,FALSE) -> 38 | J12: =VLOOKUP(TBLBAHANKELUAR[[#This Row],[NAMA BAHAN]],TBLREKAPBAHAN[[NAMA BAHAN]:[MODAL SATUAN]],4,FALSE) -> 921.05263 | K12: =VLOOKUP(TBLBAHANKELUAR[[#This Row],[KODE BAHAN]],[4]!TBLKEBABSOSYAMKECIL[#Data],8,FALSE) -> 0.5 | L12: =SUMIF(TBLPRODUKKELUARJUNI[NAMA PRODUK],TBLBAHANKELUAR[[#This Row],[NAMA PRODUK]],TBLPRODUKKELUARJUNI[JUMLAH TERJUAL]) -> 2 | M12: =TBLBAHANKELUAR[[#This Row],[KEB. BAHAN]]*TBLBAHANKELUAR[[#This Row],[JUMLAH KEB. BAHAN KELUAR]] -> 1 | N12: =TBLBAHANKELUAR[[#This Row],[MODAL SATUAN]]*TBLBAHANKELUAR[[#This Row],[TOTAL BAHAN KELUAR]] -> 921.05263
A13: 2026 | B13: JUNI | E13: KEBAB AYAM + SOSIZ (KECIL) | F13: 7 | G13: =VLOOKUP(TBLBAHANKELUAR[[#This Row],[KODE BAHAN]],[4]!TBLKEBABSOSYAMKECIL[#Data],2,FALSE) -> AYAM SUWIR | H13: =VLOOKUP(TBLBAHANKELUAR[[#This Row],[NAMA BAHAN]],TBLREKAPBAHAN[[NAMA BAHAN]:[MODAL SATUAN]],2,FALSE) -> 45000 | I13: =VLOOKUP(TBLBAHANKELUAR[[#This Row],[NAMA BAHAN]],TBLREKAPBAHAN[[NAMA BAHAN]:[MODAL SATUAN]],3,FALSE) -> 400 | J13: =VLOOKUP(TBLBAHANKELUAR[[#This Row],[NAMA BAHAN]],TBLREKAPBAHAN[[NAMA BAHAN]:[MODAL SATUAN]],4,FALSE) -> 112.5 | K13: =VLOOKUP(TBLBAHANKELUAR[[#This Row],[KODE BAHAN]],[4]!TBLKEBABSOSYAMKECIL[#Data],8,FALSE) -> 12 | L13: =SUMIF(TBLPRODUKKELUARJUNI[NAMA PRODUK],TBLBAHANKELUAR[[#This Row],[NAMA PRODUK]],TBLPRODUKKELUARJUNI[JUMLAH TERJUAL]) -> 2 | M13: =TBLBAHANKELUAR[[#This Row],[KEB. BAHAN]]*TBLBAHANKELUAR[[#This Row],[JUMLAH KEB. BAHAN KELUAR]] -> 24 | N13: =TBLBAHANKELUAR[[#This Row],[MODAL SATUAN]]*TBLBAHANKELUAR[[#This Row],[TOTAL BAHAN KELUAR]] -> 2700
